File: squid/SIO1/MdeT_1000G_ZFC.rso.dat
[Header]
TITLE,MPMS RSO Measurement
BYAPP,MPMS Measurement,1.1,Summary
FILEOPENTIME, 1717101380.959000 5/30/2024, 5:36:20 PM

INFO, APPNAME, MPMS MultiVu Application, Revision 1.61,  Build 082

INFO, NAME, SIO1
INFO, WEIGHT, 0.000
INFO, AREA, 1.000
INFO, LENGTH, 1.000
INFO, SHAPE, 0
INFO, COMMENT,
INFO, SEQUENCE FILE: MdeT1000GZFC_FCC_SIO.seq


INFO, BACKGROUND DATA FILE:, None


STARTUPAXIS,X,4,LINEAR,AUTO,0.000000,0.000000
STARTUPAXIS,Y1,5,LINEAR,AUTO,0.000000,0.000000


STARTUPGROUP,Longitudinal
FIELDGROUP,Longitudinal,1,2,3,4,5,6,7,8,9,10,11,19,20,21,22,23,35
FIELDGROUP,Transverse,1,2,3,4,12,13,14,15,16,17,18,24,25,26,27,28,35

PLOT_APPEARANCE,ALL,HORZ_GRID_ON,VERT_GRID_ON,MARKERS_AND_LINES

[Data]
Time,Comment,Field (Oe),Temperature (K),Long Moment (emu),Long Scan Std Dev,Long Offset (cm),Long Offset Std Dev,Long Algorithm,Long Reg Fit,Long Reg Factor,Trans Moment (emu),Trans Scan Std Dev,Trans Offset (cm),Trans Offset Std Dev,Trans Algorithm,Trans Reg Fit,Trans Reg Factor,Long Moment [w/o ABS] (emu),Long Scan Std Dev [w/o ABS],Long Offset [w/o ABS] (cm),Long Offset Std Dev [w/o ABS],Long Reg Fit [w/o ABS],Trans Moment [w/o ABS] (emu),Trans Scan Std Dev [w/o ABS],Trans Offset [w/o ABS] (cm),Trans Offset Std Dev [w/o ABS],Trans Reg Fit [w/o ABS],RSO Position (deg),Amplitude (cm),Frequency,Cycles to Average,Scans per Measurement,Delta Temp (K),Error,EC Comp. Running,Using ABS,
1717101380.959,,1.000000e+003,1.000191e+001,1.549708e-004,8.705135e-009,-1.596461e-001,3.450457e-004,3,9.900000e-001,1.799000e+000,,,,,,,,,,,,,,,,,,0,4.000000e+000,1.000000e+000,1,2,3.400803e-003,0,,0,
1717101452.089,,1.000000e+003,1.135162e+001,1.562593e-004,1.836825e-007,-1.596786e-001,2.176779e-004,3,9.901837e-001,1.799000e+000,,,,,,,,,,,,,,,,,,0,4.000000e+000,1.000000e+000,1,2,2.161398e-001,0,,0,
1717101503.229,,1.000000e+003,1.257826e+001,1.580209e-004,1.192892e-007,-1.605235e-001,4.587895e-004,3,9.899683e-001,1.799000e+000,,,,,,,,,,,,,,,,,,0,4.000000e+000,1.000000e+000,1,2,1.869106e-001,0,,0,
1717101544.144,,1.000000e+003,1.378560e+001,1.592341e-004,6.686285e-008,-1.608389e-001,3.730944e-004,3,9.900684e-001,1.799000e+000,,,,,,,,,,,,,,,,,,0,4.000000e+000,1.000000e+000,1,2,2.965603e-001,0,,0,
1717101582.854,,1.000000e+003,1.508472e+001,1.602086e-004,1.300625e-007,-1.609915e-001,2.774106e-004,3,9.901290e-001,1.799000e+000,,,,,,,,,,,,,,,,,,0,4.000000e+000,1.000000e+000,1,2,3.272505e-001,0,,0,
1717101617.994,,1.000000e+003,1.625714e+001,1.607944e-004,1.052436e-007,-1.612268e-001,8.120644e-005,3,9.904177e-001,1.799000e+000,,,,,,,,,,,,,,,,,,0,4.000000e+000,1.000000e+000,1,2,3.201199e-001,0,,0,
1717101652.634,,1.000000e+003,1.737502e+001,1.613461e-004,9.764980e-008,-1.613009e-001,1.532459e-004,3,9.899787e-001,1.799000e+000,,,,,,,,,,,,,,,,,,0,4.000000e+000,1.000000e+000,1,2,3.145199e-001,0,,0,
1717101692.049,,1.000000e+003,1.865183e+001,1.617286e-004,6.212956e-008,-1.616586e-001,2.525650e-004,3,9.904497e-001,1.799000e+000,,,,,,,,,,,,,,,,,,0,4.000000e+000,1.000000e+000,1,2,3.095913e-001,0,,0,
1717101729.064,,1.000000e+003,1.984068e+001,1.620078e-004,7.079354e-009,-1.614445e-001,4.720447e-005,3,9.901977e-001,1.799000e+000,,,,,,,,,,,,,,,,,,0,4.000000e+000,1.000000e+000,1,2,3.379307e-001,0,,0,
1717101765.949,,1.000000e+003,2.103756e+001,1.621895e-004,4.486334e-009,-1.614531e-001,4.437115e-004,3,9.901218e-001,1.799000e+000,,,,,,,,,,,,,,,,,,0,4.000000e+000,1.000000e+000,1,2,3.331108e-001,0,,0,
1717101803.744,,1.000000e+003,2.225562e+001,1.623700e-004,8.281197e-008,-1.617919e-001,4.263154e-004,3,9.903473e-001,1.799000e+000,,,,,,,,,,,,,,,,,,0,4.000000e+000,1.000000e+000,1,2,3.634586e-001,0,,0,
1717101841.229,,1.000000e+003,2.345149e+001,1.625668e-004,1.375741e-008,-1.621339e-001,4.009219e-005,3,9.901170e-001,1.799000e+000,,,,,,,,,,,,,,,,,,0,4.000000e+000,1.000000e+000,1,2,3.563404e-001,0,,0,
1717101876.179,,1.000000e+003,2.459259e+001,1.625993e-004,1.358248e-008,-1.618168e-001,9.618964e-005,3,9.904312e-001,1.799000e+000,,,,,,,,,,,,,,,,,,0,4.000000e+000,1.000000e+000,1,2,2.804813e-001,0,,0,
1717101915.894,,1.000000e+003,2.583957e+001,1.626779e-004,7.100678e-010,-1.617479e-001,2.969246e-005,3,9.902776e-001,1.799000e+000,,,,,,,,,,,,,,,,,,0,4.000000e+000,1.000000e+000,1,2,3.407211e-001,0,,0,
1717101951.424,,1.000000e+003,2.701978e+001,1.627580e-004,2.261689e-008,-1.617545e-001,6.090325e-004,3,9.899364e-001,1.799000e+000,,,,,,,,,,,,,,,,,,0,4.000000e+000,1.000000e+000,1,2,2.792301e-001,0,,0,
1717101990.684,,1.000000e+003,2.822643e+001,1.627939e-004,1.051099e-007,-1.616263e-001,1.143339e-004,3,9.900126e-001,1.799000e+000,,,,,,,,,,,,,,,,,,0,4.000000e+000,1.000000e+000,1,2,2.722797e-001,0,,0,
1717102028.634,,1.000000e+003,2.943500e+001,1.628305e-004,3.525271e-008,-1.615295e-001,2.757458e-005,3,9.900038e-001,1.799000e+000,,,,,,,,,,,,,,,,,,0,4.000000e+000,1.000000e+000,1,2,2.469902e-001,0,,0,
1717102064.954,,1.000000e+003,3.064921e+001,1.627968e-004,3.097234e-009,-1.612695e-001,3.478711e-007,3,9.901721e-001,1.799000e+000,,,,,,,,,,,,,,,,,,0,4.000000e+000,1.000000e+000,1,2,3.101101e-001,0,,0,
1717102101.944,,1.000000e+003,3.187135e+001,1.629197e-004,7.079353e-008,-1.616834e-001,3.277234e-004,3,9.903638e-001,1.799000e+000,,,,,,,,,,,,,,,,,,0,4.000000e+000,1.000000e+000,1,2,3.052101e-001,0,,0,
1717102138.924,,1.000000e+003,3.309046e+001,1.628779e-004,3.718718e-008,-1.613066e-001,4.044728e-004,3,9.897640e-001,1.799000e+000,,,,,,,,,,,,,,,,,,0,4.000000e+000,1.000000e+000,1,2,3.034706e-001,0,,0,
1717102175.179,,1.000000e+003,3.420624e+001,1.629270e-004,4.499711e-008,-1.615443e-001,3.840632e-005,3,9.900389e-001,1.799000e+000,,,,,,,,,,,,,,,,,,0,4.000000e+000,1.000000e+000,1,2,2.945023e-001,0,,0,
1717102235.869,,1.000000e+003,3.613520e+001,1.628559e-004,2.613598e-009,-1.611890e-001,1.126269e-004,3,9.899763e-001,1.799000e+000,,,,,,,,,,,,,,,,,,0,4.000000e+000,1.000000e+000,1,2,3.284607e-001,0,,0,
1717102273.174,,1.000000e+003,3.739036e+001,1.628882e-004,1.152453e-008,-1.610417e-001,3.535699e-004,3,9.903419e-001,1.799000e+000,,,,,,,,,,,,,,,,,,0,4.000000e+000,1.000000e+000,1,2,2.946625e-001,0,,0,
1717102308.654,,1.000000e+003,3.853683e+001,1.628525e-004,4.100469e-008,-1.610549e-001,2.060243e-004,3,9.904334e-001,1.799000e+000,,,,,,,,,,,,,,,,,,0,4.000000e+000,1.000000e+000,1,2,2.853813e-001,0,,0,
1717102346.584,,1.000000e+003,3.980458e+001,1.629403e-004,1.061903e-007,-1.603535e-001,9.989857e-005,3,9.899228e-001,1.799000e+000,,,,,,,,,,,,,,,,,,0,4.000000e+000,1.000000e+000,1,2,3.556786e-001,0,,0,
1717102390.934,,1.000000e+003,4.120995e+001,1.627586e-004,4.469871e-008,-1.606412e-001,1.993441e-004,3,9.901321e-001,1.799000e+000,,,,,,,,,,,,,,,,,,0,4.000000e+000,1.000000e+000,1,2,2.828369e-001,0,,0,
1717102428.139,,1.000000e+003,4.240380e+001,1.628693e-004,4.950403e-008,-1.606385e-001,2.399210e-005,3,9.901323e-001,1.799000e+000,,,,,,,,,,,,,,,,,,0,4.000000e+000,1.000000e+000,1,2,3.559990e-001,0,,0,
1717102465.389,,1.000000e+003,4.364598e+001,1.629735e-004,2.230819e-008,-1.600351e-001,2.107342e-008,3,9.904071e-001,1.799000e+000,,,,,,,,,,,,,,,,,,0,4.000000e+000,1.000000e+000,1,2,3.173790e-001,0,,0,
1717102503.044,,1.000000e+003,4.487582e+001,1.630214e-004,9.910066e-008,-1.596689e-001,2.358116e-004,3,9.899970e-001,1.799000e+000,,,,,,,,,,,,,,,,,,0,4.000000e+000,1.000000e+000,1,2,3.149490e-001,0,,0,
1717102539.759,,1.000000e+003,4.609413e+001,1.630744e-004,2.263747e-009,-1.595109e-001,3.211590e-005,3,9.898770e-001,1.799000e+000,,,,,,,,,,,,,,,,,,0,4.000000e+000,1.000000e+000,1,2,3.458290e-001,0,,0,
1717102576.029,,1.000000e+003,4.725743e+001,1.631665e-004,3.504692e-008,-1.595230e-001,1.127217e-004,3,9.900597e-001,1.799000e+000,,,,,,,,,,,,,,,,,,0,4.000000e+000,1.000000e+000,1,2,3.304214e-001,0,,0,
1717102613.229,,1.000000e+003,4.847204e+001,1.631833e-004,3.818529e-008,-1.588088e-001,2.247059e-004,3,9.904847e-001,1.799000e+000,,,,,,,,,,,,,,,,,,0,4.000000e+000,1.000000e+000,1,2,3.416405e-001,0,,0,
1717102648.629,,1.000000e+003,4.955625e+001,1.632929e-004,3.797950e-008,-1.591968e-001,8.498912e-005,3,9.900496e-001,1.799000e+000,,,,,,,,,,,,,,,,,,0,4.000000e+000,1.000000e+000,1,2,2.813797e-001,0,,0,
1717102685.929,,1.000000e+003,5.075396e+001,1.633724e-004,8.588861e-008,-1.593260e-001,4.347869e-004,3,9.901391e-001,1.799000e+000,,,,,,,,,,,,,,,,,,0,4.000000e+000,1.000000e+000,1,2,3.356018e-001,0,,0,
1717102721.039,,1.000000e+003,5.187408e+001,1.633907e-004,4.353597e-008,-1.589392e-001,4.080131e-004,3,9.901127e-001,1.799000e+000,,,,,,,,,,,,,,,,,,0,4.000000e+000,1.000000e+000,1,2,3.356018e-001,0,,0,
1717102756.674,,1.000000e+003,5.304017e+001,1.635294e-004,1.366480e-008,-1.589134e-001,2.281409e-004,3,9.897903e-001,1.799000e+000,,,,,,,,,,,,,,,,,,0,4.000000e+000,1.000000e+000,1,2,3.482704e-001,0,,0,
1717102792.114,,1.000000e+003,5.420501e+001,1.636281e-004,2.587874e-008,-1.587223e-001,6.817253e-005,3,9.902093e-001,1.799000e+000,,,,,,,,,,,,,,,,,,0,4.000000e+000,1.000000e+000,1,2,2.940598e-001,0,,0,
1717102828.904,,1.000000e+003,5.538576e+001,1.413742e-004,3.169069e-005,-5.951115e-002,1.408256e-001,3,6.770832e-001,1.799000e+000,,,,,,,,,,,,,,,,,,0,4.000000e+000,1.000000e+000,1,2,3.022423e-001,0,,0,
1717102863.329,,1.000000e+003,5.648289e+001,1.639129e-004,4.360799e-008,-1.588612e-001,4.549752e-005,3,9.899490e-001,1.799000e+000,,,,,,,,,,,,,,,,,,0,4.000000e+000,1.000000e+000,1,2,2.955017e-001,0,,0,
1717102899.199,,1.000000e+003,5.768213e+001,1.641642e-004,6.564866e-008,-1.585125e-001,3.454883e-004,3,9.902382e-001,1.799000e+000,,,,,,,,,,,,,,,,,,0,4.000000e+000,1.000000e+000,1,2,3.018723e-001,0,,0,
1717102935.394,,1.000000e+003,5.887564e+001,1.643438e-004,3.880268e-008,-1.582308e-001,3.302627e-004,3,9.899853e-001,1.799000e+000,,,,,,,,,,,,,,,,,,0,4.000000e+000,1.000000e+000,1,2,3.231506e-001,0,,0,
1717102972.354,,1.000000e+003,6.010171e+001,1.645725e-004,1.090714e-008,-1.582596e-001,1.710846e-004,3,9.900830e-001,1.799000e+000,,,,,,,,,,,,,,,,,,0,4.000000e+000,1.000000e+000,1,2,3.341179e-001,0,,0,
1717103009.069,,1.000000e+003,6.127923e+001,1.648036e-004,7.079354e-009,-1.580508e-001,8.154361e-005,3,9.902031e-001,1.799000e+000,,,,,,,,,,,,,,,,,,0,4.000000e+000,1.000000e+000,1,2,2.946625e-001,0,,0,
1717103043.959,,1.000000e+003,6.243233e+001,1.650573e-004,2.039430e-008,-1.577592e-001,3.858544e-005,3,9.901721e-001,1.799000e+000,,,,,,,,,,,,,,,,,,0,4.000000e+000,1.000000e+000,1,2,2.960091e-001,0,,0,
1717103080.374,,1.000000e+003,6.363924e+001,1.653544e-004,1.304741e-008,-1.576136e-001,2.381297e-006,3,9.899573e-001,1.799000e+000,,,,,,,,,,,,,,,,,,0,4.000000e+000,1.000000e+000,1,2,3.372803e-001,0,,0,
1717103115.319,,1.000000e+003,6.478484e+001,1.656420e-004,4.146773e-008,-1.569325e-001,6.995323e-005,3,9.898986e-001,1.799000e+000,,,,,,,,,,,,,,,,,,0,4.000000e+000,1.000000e+000,1,2,2.706299e-001,0,,0,
1717103151.819,,1.000000e+003,6.591526e+001,1.658735e-004,3.147637e-008,-1.568108e-001,6.967928e-005,3,9.903936e-001,1.799000e+000,,,,,,,,,,,,,,,,,,0,4.000000e+000,1.000000e+000,1,2,2.737503e-001,0,,0,
1717103185.029,,1.000000e+003,6.699774e+001,1.662014e-004,6.256173e-008,-1.567962e-001,6.785853e-004,3,9.900458e-001,1.799000e+000,,,,,,,,,,,,,,,,,,0,4.000000e+000,1.000000e+000,1,2,3.208313e-001,0,,0,
1717103221.724,,1.000000e+003,6.822631e+001,1.665080e-004,3.123970e-008,-1.564116e-001,1.767112e-004,3,9.900607e-001,1.799000e+000,,,,,,,,,,,,,,,,,,0,4.000000e+000,1.000000e+000,1,2,2.847061e-001,0,,0,
1717103257.114,,1.000000e+003,6.936993e+001,1.668826e-004,1.921098e-008,-1.563068e-001,1.930326e-004,3,9.901056e-001,1.799000e+000,,,,,,,,,,,,,,,,,,0,4.000000e+000,1.000000e+000,1,2,3.227539e-001,0,,0,
1717103292.984,,1.000000e+003,7.054242e+001,1.671790e-004,6.441388e-009,-1.560534e-001,1.489259e-004,3,9.903725e-001,1.799000e+000,,,,,,,,,,,,,,,,,,0,4.000000e+000,1.000000e+000,1,2,3.188553e-001,0,,0,
1717103329.689,,1.000000e+003,7.174277e+001,1.675215e-004,2.565237e-008,-1.556237e-001,3.298729e-004,3,9.900522e-001,1.799000e+000,,,,,,,,,,,,,,,,,,0,4.000000e+000,1.000000e+000,1,2,3.106003e-001,0,,0,
1717103366.754,,1.000000e+003,7.294739e+001,1.678852e-004,6.071829e-010,-1.552723e-001,5.275100e-004,3,9.897624e-001,1.799000e+000,,,,,,,,,,,,,,,,,,0,4.000000e+000,1.000000e+000,1,2,3.053513e-001,0,,0,
1717103402.904,,1.000000e+003,7.409306e+001,1.681160e-004,2.140270e-009,-1.553171e-001,2.529232e-004,3,9.900273e-001,1.799000e+000,,,,,,,,,,,,,,,,,,0,4.000000e+000,1.000000e+000,1,2,3.371506e-001,0,,0,
1717103440.104,,1.000000e+003,7.528253e+001,1.685571e-004,6.619401e-008,-1.547353e-001,1.339005e-004,3,9.902090e-001,1.799000e+000,,,,,,,,,,,,,,,,,,0,4.000000e+000,1.000000e+000,1,2,2.979126e-001,0,,0,
1717103485.869,,1.000000e+003,7.670009e+001,1.690486e-004,2.217443e-008,-1.545172e-001,2.193111e-004,3,9.901739e-001,1.799000e+000,,,,,,,,,,,,,,,,,,0,4.000000e+000,1.000000e+000,1,2,3.003998e-001,0,,0,
1717103521.599,,1.000000e+003,7.784948e+001,1.694532e-004,2.162907e-008,-1.542755e-001,4.108791e-004,3,9.898762e-001,1.799000e+000,,,,,,,,,,,,,,,,,,0,4.000000e+000,1.000000e+000,1,2,2.916718e-001,0,,0,
1717103559.264,,1.000000e+003,7.904036e+001,1.699009e-004,1.381915e-008,-1.536244e-001,1.190122e-004,3,9.899710e-001,1.799000e+000,,,,,,,,,,,,,,,,,,0,4.000000e+000,1.000000e+000,1,2,3.487015e-001,0,,0,
1717103593.924,,1.000000e+003,8.017999e+001,1.703438e-004,7.881955e-009,-1.534517e-001,2.909924e-004,3,9.900675e-001,1.799000e+000,,,,,,,,,,,,,,,,,,0,4.000000e+000,1.000000e+000,1,2,3.140411e-001,0,,0,
1717103630.384,,1.000000e+003,8.142027e+001,1.708062e-004,9.904921e-008,-1.532757e-001,1.431834e-004,3,9.902289e-001,1.799000e+000,,,,,,,,,,,,,,,,,,0,4.000000e+000,1.000000e+000,1,2,3.140106e-001,0,,0,
1717103666.834,,1.000000e+003,8.264603e+001,1.951383e-004,3.366945e-005,-1.997563e-001,6.594619e-002,3,7.937123e-001,1.799000e+000,,,,,,,,,,,,,,,,,,0,4.000000e+000,1.000000e+000,1,2,3.535233e-001,0,,0,
1717103702.109,,1.000000e+003,8.379865e+001,1.717663e-004,4.993620e-008,-1.527475e-001,1.271782e-005,3,9.900688e-001,1.799000e+000,,,,,,,,,,,,,,,,,,0,4.000000e+000,1.000000e+000,1,2,3.247147e-001,0,,0,
1717103738.069,,1.000000e+003,8.498574e+001,1.722684e-004,5.099604e-008,-1.523084e-001,1.844557e-004,3,9.899636e-001,1.799000e+000,,,,,,,,,,,,,,,,,,0,4.000000e+000,1.000000e+000,1,2,3.523941e-001,0,,0,
1717103775.514,,1.000000e+003,8.619579e+001,1.542426e-004,2.646339e-005,-1.930784e-001,5.440661e-002,3,6.952250e-001,1.799000e+000,,,,,,,,,,,,,,,,,,0,4.000000e+000,1.000000e+000,1,2,3.270569e-001,0,,0,
1717103811.404,,1.000000e+003,8.740067e+001,1.732228e-004,5.144879e-009,-1.516092e-001,2.503839e-004,3,9.898766e-001,1.799000e+000,,,,,,,,,,,,,,,,,,0,4.000000e+000,1.000000e+000,1,2,3.082657e-001,0,,0,
1717103848.799,,1.000000e+003,8.862808e+001,1.737730e-004,2.509672e-008,-1.512772e-001,1.390214e-004,3,9.904876e-001,1.799000e+000,,,,,,,,,,,,,,,,,,0,4.000000e+000,1.000000e+000,1,2,3.023148e-001,0,,0,
1717103885.939,,1.000000e+003,8.985838e+001,1.741494e-004,8.880067e-009,-1.507730e-001,1.189700e-004,3,9.900730e-001,1.799000e+000,,,,,,,,,,,,,,,,,,0,4.000000e+000,1.000000e+000,1,2,3.343964e-001,0,,0,
1717103921.579,,1.000000e+003,9.105248e+001,1.745841e-004,9.601373e-008,-1.504794e-001,1.148502e-005,3,9.901052e-001,1.799000e+000,,,,,,,,,,,,,,,,,,0,4.000000e+000,1.000000e+000,1,2,3.004990e-001,0,,0,
1717103965.509,,1.000000e+003,9.232293e+001,1.749989e-004,1.071987e-007,-1.502925e-001,3.478063e-004,3,9.899926e-001,1.799000e+000,,,,,,,,,,,,,,,,,,0,4.000000e+000,1.000000e+000,1,2,6.392899e-001,0,,0,
1717104003.159,,1.000000e+003,9.367139e+001,1.753404e-004,8.125821e-008,-1.495330e-001,1.187171e-004,3,9.901701e-001,1.799000e+000,,,,,,,,,,,,,,,,,,0,4.000000e+000,1.000000e+000,1,2,3.527908e-001,0,,0,
1717104038.349,,1.000000e+003,9.478031e+001,1.755461e-004,4.973040e-008,-1.497162e-001,1.503484e-004,3,9.900607e-001,1.799000e+000,,,,,,,,,,,,,,,,,,0,4.000000e+000,1.000000e+000,1,2,2.856140e-001,0,,0,
1717104076.094,,1.000000e+003,9.600016e+001,1.756233e-004,4.878374e-008,-1.493524e-001,1.447217e-004,3,9.900640e-001,1.799000e+000,,,,,,,,,,,,,,,,,,0,4.000000e+000,1.000000e+000,1,2,3.264236e-001,0,,0,
1717104110.799,,1.000000e+003,9.715355e+001,1.756850e-004,2.812191e-008,-1.489833e-001,2.642924e-004,3,9.901059e-001,1.799000e+000,,,,,,,,,,,,,,,,,,0,4.000000e+000,1.000000e+000,1,2,2.824860e-001,0,,0,
1717104147.449,,1.000000e+003,9.834230e+001,1.755399e-004,7.641174e-008,-1.487075e-001,1.261034e-004,3,9.898851e-001,1.799000e+000,,,,,,,,,,,,,,,,,,0,4.000000e+000,1.000000e+000,1,2,3.103790e-001,0,,0,
1717104182.144,,1.000000e+003,9.946048e+001,1.752900e-004,1.280046e-008,-1.484032e-001,5.397010e-004,3,9.900160e-001,1.799000e+000,,,,,,,,,,,,,,,,,,0,4.000000e+000,1.000000e+000,1,2,2.777481e-001,0,,0,
1717104224.804,,1.000000e+003,1.008468e+002,1.749722e-004,1.977691e-008,-1.481654e-001,9.591569e-005,3,9.901206e-001,1.799000e+000,,,,,,,,,,,,,,,,,,0,4.000000e+000,1.000000e+000,1,2,3.115005e-001,0,,0,
1717104266.729,,1.000000e+003,1.021533e+002,1.746087e-004,7.241932e-008,-1.478108e-001,1.074850e-004,3,9.898152e-001,1.799000e+000,,,,,,,,,,,,,,,,,,0,4.000000e+000,1.000000e+000,1,2,2.550964e-001,0,,0,
1717104302.639,,1.000000e+003,1.033267e+002,1.742589e-004,9.142450e-008,-1.473437e-001,6.155547e-005,3,9.903861e-001,1.799000e+000,,,,,,,,,,,,,,,,,,0,4.000000e+000,1.000000e+000,1,2,3.193054e-001,0,,0,
1717104340.614,,1.000000e+003,1.045713e+002,1.738775e-004,5.462833e-008,-1.470494e-001,5.972209e-005,3,9.896744e-001,1.799000e+000,,,,,,,,,,,,,,,,,,0,4.000000e+000,1.000000e+000,1,2,2.911987e-001,0,,0,
1717104376.574,,1.000000e+003,1.057903e+002,1.735998e-004,1.536261e-008,-1.467770e-001,1.711373e-004,3,9.900873e-001,1.799000e+000,,,,,,,,,,,,,,,,,,0,4.000000e+000,1.000000e+000,1,2,3.389969e-001,0,,0,
1717104413.659,,1.000000e+003,1.070162e+002,1.733781e-004,2.673279e-008,-1.461344e-001,5.198814e-005,3,9.903015e-001,1.799000e+000,,,,,,,,,,,,,,,,,,0,4.000000e+000,1.000000e+000,1,2,3.092957e-001,0,,0,
1717104450.334,,1.000000e+003,1.082454e+002,1.732351e-004,6.281897e-008,-1.447464e-001,1.630556e-004,3,9.901152e-001,1.799000e+000,,,,,,,,,,,,,,,,,,0,4.000000e+000,1.000000e+000,1,2,3.121033e-001,0,,0,
1717104488.029,,1.000000e+003,1.094749e+002,1.730906e-004,4.862940e-008,-1.444219e-001,1.009312e-004,3,9.899009e-001,1.799000e+000,,,,,,,,,,,,,,,,,,0,4.000000e+000,1.000000e+000,1,2,2.712021e-001,0,,0,
1717104525.449,,1.000000e+003,1.107015e+002,1.728043e-004,1.440566e-008,-1.436631e-001,1.318248e-004,3,9.900341e-001,1.799000e+000,,,,,,,,,,,,,,,,,,0,4.000000e+000,1.000000e+000,1,2,3.041992e-001,0,,0,
1717104560.799,,1.000000e+003,1.118611e+002,1.726219e-004,4.297003e-008,-1.432326e-001,6.654355e-004,3,9.899979e-001,1.799000e+000,,,,,,,,,,,,,,,,,,0,4.000000e+000,1.000000e+000,1,2,3.152008e-001,0,,0,
1717104597.209,,1.000000e+003,1.130917e+002,1.724046e-004,2.645497e-008,-1.429568e-001,7.208165e-005,3,9.901961e-001,1.799000e+000,,,,,,,,,,,,,,,,,,0,4.000000e+000,1.000000e+000,1,2,2.985992e-001,0,,0,
1717104632.619,,1.000000e+003,1.141701e+002,1.721688e-004,1.091538e-007,-1.426308e-001,1.778070e-004,3,9.900331e-001,1.799000e+000,,,,,,,,,,,,,,,,,,0,4.000000e+000,1.000000e+000,1,2,3.232040e-001,0,,0,
1717104670.259,,1.000000e+003,1.153543e+002,1.719234e-004,6.341578e-008,-1.421846e-001,1.496951e-004,3,9.900464e-001,1.799000e+000,,,,,,,,,,,,,,,,,,0,4.000000e+000,1.000000e+000,1,2,3.150940e-001,0,,0,
1717104704.694,,1.000000e+003,1.164672e+002,1.717351e-004,9.260782e-010,-1.419379e-001,3.536120e-004,3,9.898778e-001,1.799000e+000,,,,,,,,,,,,,,,,,,0,4.000000e+000,1.000000e+000,1,2,3.010941e-001,0,,0,
1717104740.334,,1.000000e+003,1.176184e+002,1.715729e-004,5.597628e-009,-1.417175e-001,1.377464e-004,3,9.900670e-001,1.799000e+000,,,,,,,,,,,,,,,,,,0,4.000000e+000,1.000000e+000,1,2,3.118973e-001,0,,0,
1717104777.254,,1.000000e+003,1.188097e+002,1.714196e-004,6.471229e-008,-1.410564e-001,3.537069e-004,3,9.900086e-001,1.799000e+000,,,,,,,,,,,,,,,,,,0,4.000000e+000,1.000000e+000,1,2,3.434982e-001,0,,0,
1717104814.489,,1.000000e+003,1.200243e+002,1.714347e-004,5.052271e-008,-1.409895e-001,1.444056e-004,3,9.899000e-001,1.799000e+000,,,,,,,,,,,,,,,,,,0,4.000000e+000,1.000000e+000,1,2,2.562943e-001,0,,0,
1717104849.509,,1.000000e+003,1.211511e+002,1.715023e-004,5.556469e-008,-1.403428e-001,3.029410e-004,3,9.902620e-001,1.799000e+000,,,,,,,,,,,,,,,,,,0,4.000000e+000,1.000000e+000,1,2,3.035049e-001,0,,0,
1717104885.684,,1.000000e+003,1.223418e+002,1.718378e-004,5.387717e-008,-1.402517e-001,4.375897e-005,3,9.903755e-001,1.799000e+000,,,,,,,,,,,,,,,,,,0,4.000000e+000,1.000000e+000,1,2,2.767944e-001,0,,0,
1717104921.469,,1.000000e+003,1.235054e+002,1.721257e-004,6.563837e-008,-1.397570e-001,2.705406e-004,3,9.900147e-001,1.799000e+000,,,,,,,,,,,,,,,,,,0,4.000000e+000,1.000000e+000,1,2,3.040009e-001,0,,0,
1717104958.024,,1.000000e+003,1.246920e+002,1.726393e-004,2.541570e-008,-1.393736e-001,4.967006e-005,3,9.901612e-001,1.799000e+000,,,,,,,,,,,,,,,,,,0,4.000000e+000,1.000000e+000,1,2,3.152008e-001,0,,0,
1717104993.744,,1.000000e+003,1.258533e+002,1.733289e-004,6.669821e-008,-1.391239e-001,5.235693e-005,3,9.896019e-001,1.799000e+000,,,,,,,,,,,,,,,,,,0,4.000000e+000,1.000000e+000,1,2,3.094025e-001,0,,0,
1717105029.684,,1.000000e+003,1.270111e+002,1.738769e-004,1.359380e-007,-1.386482e-001,5.019690e-005,3,9.901965e-001,1.799000e+000,,,,,,,,,,,,,,,,,,0,4.000000e+000,1.000000e+000,1,2,2.667007e-001,0,,0,
1717105064.134,,1.000000e+003,1.280842e+002,1.745057e-004,1.162743e-007,-1.385292e-001,1.951294e-004,3,9.900944e-001,1.799000e+000,,,,,,,,,,,,,,,,,,0,4.000000e+000,1.000000e+000,1,2,2.966080e-001,0,,0,
1717105099.884,,1.000000e+003,1.291772e+002,1.752061e-004,3.530416e-008,-1.381042e-001,1.671122e-005,3,9.900740e-001,1.799000e+000,,,,,,,,,,,,,,,,,,0,4.000000e+000,1.000000e+000,1,2,2.351990e-001,0,,0,
1717105134.814,,1.000000e+003,1.302660e+002,1.759576e-004,7.487857e-008,-1.375582e-001,1.273151e-004,3,9.899491e-001,1.799000e+000,,,,,,,,,,,,,,,,,,0,4.000000e+000,1.000000e+000,1,2,3.249969e-001,0,,0,
1717105180.494,,1.000000e+003,1.317263e+002,1.770403e-004,3.594213e-008,-1.368005e-001,2.589397e-004,3,9.898961e-001,1.799000e+000,,,,,,,,,,,,,,,,,,0,4.000000e+000,1.000000e+000,1,2,3.322906e-001,0,,0,
1717105215.939,,1.000000e+003,1.328253e+002,1.777875e-004,3.602885e-010,-1.367439e-001,4.931181e-006,3,9.902099e-001,1.799000e+000,,,,,,,,,,,,,,,,,,0,4.000000e+000,1.000000e+000,1,2,2.556000e-001,0,,0,
1717105263.329,,1.000000e+003,1.343947e+002,1.788152e-004,2.986088e-008,-1.357423e-001,1.828436e-004,3,9.900967e-001,1.799000e+000,,,,,,,,,,,,,,,,,,0,4.000000e+000,1.000000e+000,1,2,2.902985e-001,0,,0,
1717105299.549,,1.000000e+003,1.355784e+002,1.795969e-004,9.711474e-008,-1.355466e-001,2.582548e-004,3,9.898177e-001,1.799000e+000,,,,,,,,,,,,,,,,,,0,4.000000e+000,1.000000e+000,1,2,2.854004e-001,0,,0,
1717105338.089,,1.000000e+003,1.367551e+002,1.804222e-004,1.036076e-007,-1.350900e-001,4.134500e-004,3,9.899924e-001,1.799000e+000,,,,,,,,,,,,,,,,,,0,4.000000e+000,1.000000e+000,1,2,2.700958e-001,0,,0,
1717105373.174,,1.000000e+003,1.378578e+002,1.811777e-004,7.744072e-008,-1.347921e-001,5.923634e-004,3,9.899403e-001,1.799000e+000,,,,,,,,,,,,,,,,,,0,4.000000e+000,1.000000e+000,1,2,3.498993e-001,0,,0,
1717105408.779,,1.000000e+003,1.389730e+002,1.818818e-004,5.947480e-009,-1.341298e-001,1.619598e-004,3,9.899945e-001,1.799000e+000,,,,,,,,,,,,,,,,,,0,4.000000e+000,1.000000e+000,1,2,2.962036e-001,0,,0,
1717105445.879,,1.000000e+003,1.401010e+002,1.827235e-004,5.822974e-008,-1.340936e-001,3.164069e-004,3,9.898649e-001,1.799000e+000,,,,,,,,,,,,,,,,,,0,4.000000e+000,1.000000e+000,1,2,3.046112e-001,0,,0,
1717105481.304,,1.000000e+003,1.411941e+002,1.834693e-004,3.517039e-008,-1.336550e-001,4.164425e-004,3,9.901273e-001,1.799000e+000,,,,,,,,,,,,,,,,,,0,4.000000e+000,1.000000e+000,1,2,2.913971e-001,0,,0,
1717105516.659,,1.000000e+003,1.422907e+002,1.840425e-004,1.445711e-008,-1.329536e-001,2.583707e-004,3,9.900781e-001,1.799000e+000,,,,,,,,,,,,,,,,,,0,4.000000e+000,1.000000e+000,1,2,3.104858e-001,0,,0,
1717105574.989,,1.000000e+003,1.441596e+002,1.851057e-004,2.109400e-008,-1.323482e-001,3.678366e-004,3,9.900298e-001,1.799000e+000,,,,,,,,,,,,,,,,,,0,4.000000e+000,1.000000e+000,1,2,3.148041e-001,0,,0,
1717105611.129,,1.000000e+003,1.453474e+002,1.857727e-004,5.272472e-008,-1.319031e-001,1.172420e-004,3,9.901217e-001,1.799000e+000,,,,,,,,,,,,,,,,,,0,4.000000e+000,1.000000e+000,1,2,3.238983e-001,0,,0,
1717105648.774,,1.000000e+003,1.465935e+002,1.863210e-004,6.970282e-008,-1.312579e-001,2.435245e-004,3,9.899094e-001,1.799000e+000,,,,,,,,,,,,,,,,,,0,4.000000e+000,1.000000e+000,1,2,3.255005e-001,0,,0,
1717105682.884,,1.000000e+003,1.477439e+002,1.868894e-004,4.730202e-008,-1.309226e-001,1.329944e-004,3,9.902009e-001,1.799000e+000,,,,,,,,,,,,,,,,,,0,4.000000e+000,1.000000e+000,1,2,2.913971e-001,0,,0,
1717105720.464,,1.000000e+003,1.490036e+002,1.875197e-004,9.752632e-008,-1.305571e-001,1.124162e-004,3,9.899724e-001,1.799000e+000,,,,,,,,,,,,,,,,,,0,4.000000e+000,1.000000e+000,1,2,3.244019e-001,0,,0,
1717105756.609,,1.000000e+003,1.502258e+002,1.881334e-004,8.168010e-008,-1.299738e-001,3.344036e-004,3,9.902695e-001,1.799000e+000,,,,,,,,,,,,,,,,,,0,4.000000e+000,1.000000e+000,1,2,3.255005e-001,0,,0,
1717105791.499,,1.000000e+003,1.513802e+002,1.886860e-004,5.818858e-008,-1.295734e-001,1.335002e-005,3,9.901519e-001,1.799000e+000,,,,,,,,,,,,,,,,,,0,4.000000e+000,1.000000e+000,1,2,3.222961e-001,0,,0,
1717105829.824,,1.000000e+003,1.526281e+002,1.892395e-004,9.895660e-008,-1.289934e-001,5.041817e-005,3,9.898677e-001,1.799000e+000,,,,,,,,,,,,,,,,,,0,4.000000e+000,1.000000e+000,1,2,3.529053e-001,0,,0,
1717105865.504,,1.000000e+003,1.538037e+002,1.897590e-004,2.329601e-008,-1.286301e-001,1.943391e-004,3,9.900078e-001,1.799000e+000,,,,,,,,,,,,,,,,,,0,4.000000e+000,1.000000e+000,1,2,3.113098e-001,0,,0,
1717105901.844,,1.000000e+003,1.549814e+002,1.902720e-004,5.986581e-008,-1.281789e-001,3.101797e-004,3,9.899087e-001,1.799000e+000,,,,,,,,,,,,,,,,,,0,4.000000e+000,1.000000e+000,1,2,3.074036e-001,0,,0,
1717105936.504,,1.000000e+003,1.561200e+002,1.907673e-004,6.675995e-008,-1.278213e-001,6.050180e-005,3,9.900107e-001,1.799000e+000,,,,,,,,,,,,,,,,,,0,4.000000e+000,1.000000e+000,1,2,3.208008e-001,0,,0,
1717105974.509,,1.000000e+003,1.573758e+002,1.912955e-004,9.434679e-008,-1.272099e-001,6.072834e-004,3,9.898456e-001,1.799000e+000,,,,,,,,,,,,,,,,,,0,4.000000e+000,1.000000e+000,1,2,3.170013e-001,0,,0,
1717106010.139,,1.000000e+003,1.584899e+002,1.916794e-004,8.178299e-008,-1.269712e-001,1.124373e-004,3,9.898684e-001,1.799000e+000,,,,,,,,,,,,,,,,,,0,4.000000e+000,1.000000e+000,1,2,3.260956e-001,0,,0,
1717106046.754,,1.000000e+003,1.596588e+002,1.920711e-004,8.396442e-008,-1.259809e-001,3.643595e-005,3,9.902149e-001,1.799000e+000,,,,,,,,,,,,,,,,,,0,4.000000e+000,1.000000e+000,1,2,3.354034e-001,0,,0,
1717106085.034,,1.000000e+003,1.608730e+002,1.923969e-004,7.337626e-008,-1.255665e-001,1.366295e-004,3,9.903110e-001,1.799000e+000,,,,,,,,,,,,,,,,,,0,4.000000e+000,1.000000e+000,1,2,3.312073e-001,0,,0,
1717106120.644,,1.000000e+003,1.619495e+002,1.927498e-004,8.504485e-008,-1.249982e-001,2.489614e-004,3,9.900953e-001,1.799000e+000,,,,,,,,,,,,,,,,,,0,4.000000e+000,1.000000e+000,1,2,3.134918e-001,0,,0,
1717106158.369,,1.000000e+003,1.630952e+002,1.930941e-004,4.836186e-008,-1.247778e-001,1.604214e-004,3,9.899793e-001,1.799000e+000,,,,,,,,,,,,,,,,,,0,4.000000e+000,1.000000e+000,1,2,2.973938e-001,0,,0,
1717106194.934,,1.000000e+003,1.642836e+002,1.932127e-004,2.500432e-009,-1.240875e-001,1.570550e-004,3,9.900694e-001,1.799000e+000,,,,,,,,,,,,,,,,,,0,4.000000e+000,1.000000e+000,1,2,3.018036e-001,0,,0,
1717106231.949,,1.000000e+003,1.654910e+002,1.935295e-004,3.776341e-008,-1.238049e-001,2.362331e-004,3,9.897583e-001,1.799000e+000,,,,,,,,,,,,,,,,,,0,4.000000e+000,1.000000e+000,1,2,3.457947e-001,0,,0,
1717106268.984,,1.000000e+003,1.667039e+002,1.935767e-004,2.401629e-008,-1.233152e-001,1.340691e-004,3,9.900695e-001,1.799000e+000,,,,,,,,,,,,,,,,,,0,4.000000e+000,1.000000e+000,1,2,3.106995e-001,0,,0,
1717106306.229,,1.000000e+003,1.679451e+002,1.937224e-004,4.494566e-008,-1.225695e-001,6.327296e-005,3,9.901329e-001,1.799000e+000,,,,,,,,,,,,,,,,,,0,4.000000e+000,1.000000e+000,1,2,3.103943e-001,0,,0,
1717106342.584,,1.000000e+003,1.691224e+002,1.936145e-004,1.831577e-008,-1.220149e-001,8.205465e-005,3,9.900899e-001,1.799000e+000,,,,,,,,,,,,,,,,,,0,4.000000e+000,1.000000e+000,1,2,3.045044e-001,0,,0,
1717106378.094,,1.000000e+003,1.702891e+002,1.934777e-004,3.135289e-008,-1.215247e-001,2.240948e-004,3,9.900960e-001,1.799000e+000,,,,,,,,,,,,,,,,,,0,4.000000e+000,1.000000e+000,1,2,3.087006e-001,0,,0,
1717106414.644,,1.000000e+003,1.714881e+002,1.933590e-004,1.404552e-008,-1.210169e-001,8.917219e-005,3,9.899036e-001,1.799000e+000,,,,,,,,,,,,,,,,,,0,4.000000e+000,1.000000e+000,1,2,3.025055e-001,0,,0,
1717106450.399,,1.000000e+003,1.726383e+002,1.931540e-004,6.596764e-008,-1.204723e-001,3.412841e-005,3,9.897759e-001,1.799000e+000,,,,,,,,,,,,,,,,,,0,4.000000e+000,1.000000e+000,1,2,3.067017e-001,0,,0,
1717106486.904,,1.000000e+003,1.738001e+002,1.928165e-004,1.218307e-008,-1.199969e-001,2.047178e-004,3,9.900364e-001,1.799000e+000,,,,,,,,,,,,,,,,,,0,4.000000e+000,1.000000e+000,1,2,3.325958e-001,0,,0,
1717106522.834,,1.000000e+003,1.749350e+002,1.923333e-004,1.340550e-007,-1.197874e-001,5.674546e-005,3,9.897660e-001,1.799000e+000,,,,,,,,,,,,,,,,,,0,4.000000e+000,1.000000e+000,1,2,3.314972e-001,0,,0,
1717106560.364,,1.000000e+003,1.761619e+002,1.919366e-004,2.058981e-008,-1.189642e-001,1.117892e-004,3,9.899867e-001,1.799000e+000,,,,,,,,,,,,,,,,,,0,4.000000e+000,1.000000e+000,1,2,3.697968e-001,0,,0,
1717106596.109,,1.000000e+003,1.773367e+002,1.912739e-004,2.203037e-008,-1.189126e-001,3.103062e-004,3,9.899254e-001,1.799000e+000,,,,,,,,,,,,,,,,,,0,4.000000e+000,1.000000e+000,1,2,3.123016e-001,0,,0,
1717106630.719,,1.000000e+003,1.784828e+002,1.904885e-004,9.528316e-008,-1.180050e-001,1.472874e-004,3,9.901512e-001,1.799000e+000,,,,,,,,,,,,,,,,,,0,4.000000e+000,1.000000e+000,1,2,3.049927e-001,0,,0,
1717106666.954,,1.000000e+003,1.796703e+002,1.897804e-004,7.127715e-008,-1.178631e-001,3.080197e-004,3,9.900711e-001,1.799000e+000,,,,,,,,,,,,,,,,,,0,4.000000e+000,1.000000e+000,1,2,2.915039e-001,0,,0,
1717106703.324,,1.000000e+003,1.808222e+002,1.886675e-004,3.636400e-008,-1.169576e-001,1.107935e-005,3,9.900529e-001,1.799000e+000,,,,,,,,,,,,,,,,,,0,4.000000e+000,1.000000e+000,1,2,3.307953e-001,0,,0,
1717106739.654,,1.000000e+003,1.820084e+002,1.874617e-004,1.869032e-007,-1.167249e-001,7.304575e-005,3,9.899880e-001,1.799000e+000,,,,,,,,,,,,,,,,,,0,4.000000e+000,1.000000e+000,1,2,3.232117e-001,0,,0,
1717106775.944,,1.000000e+003,1.831308e+002,1.861288e-004,1.307622e-007,-1.161255e-001,2.044228e-004,3,9.897553e-001,1.799000e+000,,,,,,,,,,,,,,,,,,0,4.000000e+000,1.000000e+000,1,2,2.969971e-001,0,,0,
1717106813.799,,1.000000e+003,1.843850e+002,1.846194e-004,9.083799e-008,-1.155538e-001,1.911202e-004,3,9.899945e-001,1.799000e+000,,,,,,,,,,,,,,,,,,0,4.000000e+000,1.000000e+000,1,2,3.379974e-001,0,,0,
1717106848.994,,1.000000e+003,1.855308e+002,1.828588e-004,1.458779e-007,-1.149355e-001,2.045386e-004,3,9.901497e-001,1.799000e+000,,,,,,,,,,,,,,,,,,0,4.000000e+000,1.000000e+000,1,2,2.988129e-001,0,,0,
1717106885.604,,1.000000e+003,1.867544e+002,1.808536e-004,2.122160e-007,-1.145094e-001,3.372275e-005,3,9.900254e-001,1.799000e+000,,,,,,,,,,,,,,,,,,0,4.000000e+000,1.000000e+000,1,2,3.405914e-001,0,,0,
1717106921.139,,1.000000e+003,1.879162e+002,1.785418e-004,2.689949e-007,-1.140960e-001,5.884595e-004,3,9.896216e-001,1.799000e+000,,,,,,,,,,,,,,,,,,0,4.000000e+000,1.000000e+000,1,2,3.193970e-001,0,,0,
1717106956.489,,1.000000e+003,1.890654e+002,1.759997e-004,2.226086e-007,-1.136176e-001,3.495291e-004,3,9.900419e-001,1.799000e+000,,,,,,,,,,,,,,,,,,0,4.000000e+000,1.000000e+000,1,2,3.363953e-001,0,,0,
1717106990.794,,1.000000e+003,1.901766e+002,1.732348e-004,3.009445e-007,-1.128979e-001,2.562159e-004,3,9.899648e-001,1.799000e+000,,,,,,,,,,,,,,,,,,0,4.000000e+000,1.000000e+000,1,2,2.946930e-001,0,,0,
1717107049.404,,1.000000e+003,1.920864e+002,1.678574e-004,3.860614e-007,-1.124091e-001,2.521435e-005,3,9.895965e-001,1.799000e+000,,,,,,,,,,,,,,,,,,0,4.000000e+000,1.000000e+000,1,2,2.940979e-001,0,,0,
1717107086.599,,1.000000e+003,1.932817e+002,1.640070e-004,3.437294e-007,-1.117544e-001,3.363424e-004,3,9.899732e-001,1.799000e+000,,,,,,,,,,,,,,,,,,0,4.000000e+000,1.000000e+000,1,2,3.181000e-001,0,,0,
1717107121.634,,1.000000e+003,1.944031e+002,1.601405e-004,4.102012e-007,-1.115956e-001,1.676496e-004,3,9.895668e-001,1.799000e+000,,,,,,,,,,,,,,,,,,0,4.000000e+000,1.000000e+000,1,2,3.150024e-001,0,,0,
1717107157.704,,1.000000e+003,1.955484e+002,1.559582e-004,4.310894e-007,-1.107722e-001,4.974066e-004,3,9.895946e-001,1.799000e+000,,,,,,,,,,,,,,,,,,0,4.000000e+000,1.000000e+000,1,2,3.256073e-001,0,,0,
1717107193.714,,1.000000e+003,1.967355e+002,1.511557e-004,5.549987e-007,-1.107002e-001,8.253934e-005,3,9.899059e-001,1.799000e+000,,,,,,,,,,,,,,,,,,0,4.000000e+000,1.000000e+000,1,2,2.946930e-001,0,,0,
1717107229.964,,1.000000e+003,1.979019e+002,1.459391e-004,4.976641e-007,-1.099955e-001,2.930470e-004,3,9.896986e-001,1.799000e+000,,,,,,,,,,,,,,,,,,0,4.000000e+000,1.000000e+000,1,2,3.337097e-001,0,,0,
1717107265.819,,1.000000e+003,1.990717e+002,1.403718e-004,5.234606e-007,-1.095466e-001,1.067790e-004,3,9.898908e-001,1.799000e+000,,,,,,,,,,,,,,,,,,0,4.000000e+000,1.000000e+000,1,2,2.875061e-001,0,,0,
1717107302.819,,1.000000e+003,2.002848e+002,1.341058e-004,6.812746e-007,-1.099535e-001,6.306749e-005,3,9.895940e-001,1.799000e+000,,,,,,,,,,,,,,,,,,0,4.000000e+000,1.000000e+000,1,2,2.983093e-001,0,,0,
1717107338.614,,1.000000e+003,2.014358e+002,1.272074e-004,7.847278e-007,-1.088786e-001,4.389120e-004,3,9.892012e-001,1.799000e+000,,,,,,,,,,,,,,,,,,0,4.000000e+000,1.000000e+000,1,2,2.944946e-001,0,,0,
1717107375.044,,1.000000e+003,2.026506e+002,1.194636e-004,8.297301e-007,-1.088194e-001,7.938780e-004,3,9.891999e-001,1.799000e+000,,,,,,,,,,,,,,,,,,0,4.000000e+000,1.000000e+000,1,2,3.428040e-001,0,,0,
1717107408.699,,1.000000e+003,2.037692e+002,1.113407e-004,7.690977e-007,-1.087280e-001,1.249285e-004,3,9.891744e-001,1.799000e+000,,,,,,,,,,,,,,,,,,0,4.000000e+000,1.000000e+000,1,2,3.240967e-001,0,,0,
1717107446.514,,1.000000e+003,2.050034e+002,1.011345e-004,9.065225e-007,-1.088841e-001,5.494421e-004,3,9.889054e-001,1.799000e+000,,,,,,,,,,,,,,,,,,0,4.000000e+000,1.000000e+000,1,2,3.585968e-001,0,,0,
1717107480.059,,1.000000e+003,2.060697e+002,9.130650e-005,1.103062e-006,-1.088481e-001,5.197233e-005,3,9.883655e-001,1.799000e+000,,,,,,,,,,,,,,,,,,0,4.000000e+000,1.000000e+000,1,2,3.083954e-001,0,,0,
1717107517.199,,1.000000e+003,2.072363e+002,7.959837e-005,1.136710e-006,-1.094076e-001,2.513216e-004,3,9.880499e-001,1.799000e+000,,,,,,,,,,,,,,,,,,0,4.000000e+000,1.000000e+000,1,2,3.278046e-001,0,,0,
1717107553.694,,1.000000e+003,2.084435e+002,6.728746e-005,1.260603e-006,-1.109151e-001,6.691020e-007,3,9.870483e-001,1.799000e+000,,,,,,,,,,,,,,,,,,0,4.000000e+000,1.000000e+000,1,2,3.318024e-001,0,,0,
1717107589.204,,1.000000e+003,2.096295e+002,5.446092e-005,1.210518e-006,-1.131509e-001,1.087494e-004,3,9.836185e-001,1.799000e+000,,,,,,,,,,,,,,,,,,0,4.000000e+000,1.000000e+000,1,2,3.038025e-001,0,,0,
1717107623.509,,1.000000e+003,2.107770e+002,4.194721e-005,1.218788e-006,-1.180339e-001,6.584602e-004,3,9.807748e-001,1.799000e+000,,,,,,,,,,,,,,,,,,0,4.000000e+000,1.000000e+000,1,2,2.828979e-001,0,,0,
1717107660.864,,1.000000e+003,2.119869e+002,2.909175e-005,1.135554e-006,-1.232670e-001,1.903299e-003,3,9.739098e-001,1.799000e+000,,,,,,,,,,,,,,,,,,0,4.000000e+000,1.000000e+000,1,2,3.355103e-001,0,,0,
1717107697.634,,1.000000e+003,2.131597e+002,1.774358e-005,9.419180e-007,-1.405146e-001,5.896439e-003,3,9.561626e-001,1.799000e+000,,,,,,,,,,,,,,,,,,0,4.000000e+000,1.000000e+000,1,2,3.146057e-001,0,,0,
1717107735.634,,1.000000e+003,2.143334e+002,7.975625e-006,8.625011e-007,-1.975573e-001,5.298133e-003,3,8.988353e-001,1.799000e+000,,,,,,,,,,,,,,,,,,0,4.000000e+000,1.000000e+000,1,2,3.348999e-001,0,,0,
1717107771.254,,1.000000e+003,2.154890e+002,-2.141584e-006,4.140502e-008,8.104351e-001,1.753393e-001,3,7.965682e-001,1.799000e+000,,,,,,,,,,,,,,,,,,0,4.000000e+000,1.000000e+000,1,2,3.132935e-001,0,,0,
1717107808.504,,1.000000e+003,2.166384e+002,-7.523593e-006,5.293090e-007,4.002325e-002,9.620880e-003,3,9.095754e-001,1.799000e+000,,,,,,,,,,,,,,,,,,0,4.000000e+000,1.000000e+000,1,2,2.996979e-001,0,,0,
1717107847.544,,1.000000e+003,2.178526e+002,-1.387867e-005,5.268240e-007,-2.140164e-002,1.971989e-003,3,9.514925e-001,1.799000e+000,,,,,,,,,,,,,,,,,,0,4.000000e+000,1.000000e+000,1,2,3.722992e-001,0,,0,
1717107886.324,,1.000000e+003,2.191030e+002,-1.971877e-005,5.274504e-007,-4.174652e-002,1.498057e-003,3,9.616497e-001,1.799000e+000,,,,,,,,,,,,,,,,,,0,4.000000e+000,1.000000e+000,1,2,2.891998e-001,0,,0,
1717107928.554,,1.000000e+003,2.205126e+002,-2.514816e-005,4.289569e-007,-5.012449e-002,1.216885e-003,3,9.721550e-001,1.799000e+000,,,,,,,,,,,,,,,,,,0,4.000000e+000,1.000000e+000,1,2,2.931976e-001,0,,0,
1717107964.799,,1.000000e+003,2.216896e+002,-2.894237e-005,3.760006e-007,-5.355256e-002,2.491211e-003,3,9.750108e-001,1.799000e+000,,,,,,,,,,,,,,,,,,0,4.000000e+000,1.000000e+000,1,2,3.502960e-001,0,,0,
1717108002.139,,1.000000e+003,2.229433e+002,-3.210365e-005,2.667362e-007,-5.635862e-002,2.015784e-003,3,9.744756e-001,1.799000e+000,,,,,,,,,,,,,,,,,,0,4.000000e+000,1.000000e+000,1,2,2.908020e-001,0,,0,
1717108038.209,,1.000000e+003,2.241336e+002,-3.438331e-005,2.231385e-007,-5.583768e-002,3.158727e-003,3,9.752535e-001,1.799000e+000,,,,,,,,,,,,,,,,,,0,4.000000e+000,1.000000e+000,1,2,3.217010e-001,0,,0,
1717108076.979,,1.000000e+003,2.254093e+002,-3.626337e-005,1.192146e-007,-5.689753e-002,9.773617e-004,3,9.791846e-001,1.799000e+000,,,,,,,,,,,,,,,,,,0,4.000000e+000,1.000000e+000,1,2,3.999023e-001,0,,0,
1717108114.219,,1.000000e+003,2.267214e+002,-3.766722e-005,1.328974e-007,-5.858911e-002,1.421165e-004,3,9.779913e-001,1.799000e+000,,,,,,,,,,,,,,,,,,0,4.000000e+000,1.000000e+000,1,2,3.200073e-001,0,,0,
1717108151.164,,1.000000e+003,2.279162e+002,-3.869342e-005,1.068952e-007,-5.905611e-002,2.002299e-003,3,9.782177e-001,1.799000e+000,,,,,,,,,,,,,,,,,,0,4.000000e+000,1.000000e+000,1,2,3.139038e-001,0,,0,
1717108187.784,,1.000000e+003,2.291241e+002,-3.953290e-005,9.935019e-008,-5.808583e-002,3.779361e-004,3,9.791793e-001,1.799000e+000,,,,,,,,,,,,,,,,,,0,4.000000e+000,1.000000e+000,1,2,3.463898e-001,0,,0,
1717108223.364,,1.000000e+003,2.302628e+002,-4.013821e-005,8.815235e-008,-5.740834e-002,9.894394e-004,3,9.784352e-001,1.799000e+000,,,,,,,,,,,,,,,,,,0,4.000000e+000,1.000000e+000,1,2,3.013000e-001,0,,0,
1717108260.429,,1.000000e+003,2.314526e+002,-4.070886e-005,4.852135e-008,-5.620556e-002,1.269007e-003,3,9.808376e-001,1.799000e+000,,,,,,,,,,,,,,,,,,0,4.000000e+000,1.000000e+000,1,2,3.143921e-001,0,,0,
1717108305.714,,1.000000e+003,2.328839e+002,-4.127155e-005,6.877160e-008,-5.576501e-002,8.240499e-005,3,9.808087e-001,1.799000e+000,,,,,,,,,,,,,,,,,,0,4.000000e+000,1.000000e+000,1,2,2.288055e-001,0,,0,
1717108343.974,,1.000000e+003,2.340913e+002,-4.165264e-005,6.075845e-008,-5.579315e-002,9.504957e-004,3,9.798034e-001,1.799000e+000,,,,,,,,,,,,,,,,,,0,4.000000e+000,1.000000e+000,1,2,3.119965e-001,0,,0,
1717108379.594,,1.000000e+003,2.352701e+002,-4.201457e-005,5.256008e-008,-5.498411e-002,2.383891e-003,3,9.795237e-001,1.799000e+000,,,,,,,,,,,,,,,,,,0,4.000000e+000,1.000000e+000,1,2,3.051910e-001,0,,0,
1717108417.614,,1.000000e+003,2.364720e+002,-4.231192e-005,3.927858e-008,-5.465264e-002,6.518721e-004,3,9.807727e-001,1.799000e+000,,,,,,,,,,,,,,,,,,0,4.000000e+000,1.000000e+000,1,2,3.393097e-001,0,,0,
1717108452.404,,1.000000e+003,2.375858e+002,-4.251101e-005,6.202409e-008,-5.446192e-002,2.414461e-004,3,9.798421e-001,1.799000e+000,,,,,,,,,,,,,,,,,,0,4.000000e+000,1.000000e+000,1,2,2.908936e-001,0,,0,
1717108490.969,,1.000000e+003,2.387686e+002,-4.273036e-005,8.126337e-009,-5.210102e-002,7.795244e-004,3,9.803209e-001,1.799000e+000,,,,,,,,,,,,,,,,,,0,4.000000e+000,1.000000e+000,1,2,3.044891e-001,0,,0,
1717108529.459,,1.000000e+003,2.400356e+002,-4.293052e-005,1.005309e-008,-5.174387e-002,7.904325e-004,3,9.794617e-001,1.799000e+000,,,,,,,,,,,,,,,,,,0,4.000000e+000,1.000000e+000,1,2,3.078918e-001,0,,0,
1717108564.019,,1.000000e+003,2.411562e+002,-4.310991e-005,7.231128e-009,-5.057282e-002,7.725333e-004,3,9.797400e-001,1.799000e+000,,,,,,,,,,,,,,,,,,0,4.000000e+000,1.000000e+000,1,2,3.109894e-001,0,,0,
1717108612.119,,1.000000e+003,2.425784e+002,-4.326312e-005,7.454930e-009,-5.158020e-002,4.555389e-004,3,9.805181e-001,1.799000e+000,,,,,,,,,,,,,,,,,,0,4.000000e+000,1.000000e+000,1,2,6.625061e-001,0,,0,
1717108648.364,,1.000000e+003,2.439246e+002,-4.338261e-005,6.068385e-009,-5.006012e-002,2.963635e-004,3,9.793296e-001,1.799000e+000,,,,,,,,,,,,,,,,,,0,4.000000e+000,1.000000e+000,1,2,3.186951e-001,0,,0,
1717108684.749,,1.000000e+003,2.451427e+002,-4.351686e-005,3.807725e-008,-4.893082e-002,1.392592e-003,3,9.787492e-001,1.799000e+000,,,,,,,,,,,,,,,,,,0,4.000000e+000,1.000000e+000,1,2,3.109894e-001,0,,0,
1717108722.024,,1.000000e+003,2.463513e+002,-4.363330e-005,1.396837e-009,-4.733017e-002,2.129817e-003,3,9.793907e-001,1.799000e+000,,,,,,,,,,,,,,,,,,0,4.000000e+000,1.000000e+000,1,2,3.479919e-001,0,,0,
1717108759.044,,1.000000e+003,2.475727e+002,-4.376666e-005,4.265877e-008,-4.726754e-002,3.748830e-004,3,9.819376e-001,1.799000e+000,,,,,,,,,,,,,,,,,,0,4.000000e+000,1.000000e+000,1,2,3.063049e-001,0,,0,
1717108795.174,,1.000000e+003,2.487326e+002,-4.382550e-005,1.475037e-008,-4.640461e-002,3.270069e-005,3,9.794379e-001,1.799000e+000,,,,,,,,,,,,,,,,,,0,4.000000e+000,1.000000e+000,1,2,3.437042e-001,0,,0,
1717108832.469,,1.000000e+003,2.499620e+002,-4.393170e-005,1.478124e-008,-4.537240e-002,5.502061e-004,3,9.803793e-001,1.799000e+000,,,,,,,,,,,,,,,,,,0,4.000000e+000,1.000000e+000,1,2,3.472900e-001,0,,0,
1717108868.499,,1.000000e+003,2.511167e+002,-4.400045e-005,2.182200e-008,-4.437257e-002,4.576884e-005,3,9.820536e-001,1.799000e+000,,,,,,,,,,,,,,,,,,0,4.000000e+000,1.000000e+000,1,2,3.390961e-001,0,,0,
1717108914.904,,1.000000e+003,2.526108e+002,-4.410978e-005,3.827790e-009,-4.296768e-002,2.532604e-004,3,9.807382e-001,1.799000e+000,,,,,,,,,,,,,,,,,,0,4.000000e+000,1.000000e+000,1,2,3.197021e-001,0,,0,
1717108951.954,,1.000000e+003,2.537678e+002,-4.417081e-005,6.377078e-009,-4.330578e-002,4.926967e-005,3,9.802364e-001,1.799000e+000,,,,,,,,,,,,,,,,,,0,4.000000e+000,1.000000e+000,1,2,2.870026e-001,0,,0,
1717108995.694,,1.000000e+003,2.551113e+002,-4.419143e-005,5.106292e-008,-4.155642e-002,1.240874e-003,3,9.793167e-001,1.799000e+000,,,,,,,,,,,,,,,,,,0,4.000000e+000,1.000000e+000,1,2,2.781067e-001,0,,0,
1717109030.959,,1.000000e+003,2.562257e+002,-4.425702e-005,2.031713e-008,-4.050685e-002,1.341750e-003,3,9.809015e-001,1.799000e+000,,,,,,,,,,,,,,,,,,0,4.000000e+000,1.000000e+000,1,2,3.172913e-001,0,,0,
1717109067.034,,1.000000e+003,2.573781e+002,-4.428405e-005,1.438508e-008,-4.016145e-002,5.127217e-004,3,9.805964e-001,1.799000e+000,,,,,,,,,,,,,,,,,,0,4.000000e+000,1.000000e+000,1,2,2.832947e-001,0,,0,
1717109108.414,,1.000000e+003,2.586382e+002,-4.434524e-005,6.840117e-009,-3.931351e-002,9.586907e-004,3,9.805863e-001,1.799000e+000,,,,,,,,,,,,,,,,,,0,4.000000e+000,1.000000e+000,1,2,5.227051e-001,0,,0,
1717109144.674,,1.000000e+003,2.598798e+002,-4.442553e-005,4.658430e-008,-3.689249e-002,1.221574e-003,3,9.805536e-001,1.799000e+000,,,,,,,,,,,,,,,,,,0,4.000000e+000,1.000000e+000,1,2,2.892151e-001,0,,0,
1717109181.654,,1.000000e+003,2.610390e+002,-4.447802e-005,3.144035e-008,-3.823889e-002,5.532432e-004,3,9.808389e-001,1.799000e+000,,,,,,,,,,,,,,,,,,0,4.000000e+000,1.000000e+000,1,2,2.919006e-001,0,,0,
1717109216.469,,1.000000e+003,2.621611e+002,-4.446918e-005,7.984852e-009,-3.598914e-002,7.886018e-004,3,9.799238e-001,1.799000e+000,,,,,,,,,,,,,,,,,,0,4.000000e+000,1.000000e+000,1,2,3.203125e-001,0,,0,
1717109252.544,,1.000000e+003,2.632935e+002,-4.450091e-005,7.069064e-009,-3.598620e-002,3.332841e-004,3,9.795446e-001,1.799000e+000,,,,,,,,,,,,,,,,,,0,4.000000e+000,1.000000e+000,1,2,2.629089e-001,0,,0,
1717109289.859,,1.000000e+003,2.644836e+002,-4.454723e-005,3.211691e-008,-3.505417e-002,7.992096e-006,3,9.796038e-001,1.799000e+000,,,,,,,,,,,,,,,,,,0,4.000000e+000,1.000000e+000,1,2,3.133850e-001,0,,0,
1717109327.859,,1.000000e+003,2.657339e+002,-4.459177e-005,1.310915e-008,-3.318408e-002,8.178938e-004,3,9.805876e-001,1.799000e+000,,,,,,,,,,,,,,,,,,0,4.000000e+000,1.000000e+000,1,2,3.034058e-001,0,,0,
1717109364.464,,1.000000e+003,2.669405e+002,-4.460452e-005,3.755504e-008,-3.222308e-002,5.763134e-004,3,9.804207e-001,1.799000e+000,,,,,,,,,,,,,,,,,,0,4.000000e+000,1.000000e+000,1,2,3.198853e-001,0,,0,
1717109401.139,,1.000000e+003,2.680987e+002,-4.466930e-005,4.062911e-008,-3.245912e-002,4.656252e-004,3,9.803343e-001,1.799000e+000,,,,,,,,,,,,,,,,,,0,4.000000e+000,1.000000e+000,1,2,3.363037e-001,0,,0,
1717109448.374,,1.000000e+003,2.696010e+002,-4.464484e-005,1.066019e-008,-2.976288e-002,8.908935e-004,3,9.802797e-001,1.799000e+000,,,,,,,,,,,,,,,,,,0,4.000000e+000,1.000000e+000,1,2,3.268738e-001,0,,0,
1717109485.134,,1.000000e+003,2.708189e+002,-4.473474e-005,1.061131e-008,-2.884842e-002,1.570849e-003,3,9.810925e-001,1.799000e+000,,,,,,,,,,,,,,,,,,0,4.000000e+000,1.000000e+000,1,2,3.713989e-001,0,,0,
1717109521.119,,1.000000e+003,2.720072e+002,-4.472257e-005,2.252942e-008,-2.796862e-002,9.676166e-004,3,9.808043e-001,1.799000e+000,,,,,,,,,,,,,,,,,,0,4.000000e+000,1.000000e+000,1,2,3.471069e-001,0,,0,
1717109559.184,,1.000000e+003,2.732629e+002,-4.475656e-005,5.404696e-009,-2.699445e-002,7.298122e-004,3,9.807792e-001,1.799000e+000,,,,,,,,,,,,,,,,,,0,4.000000e+000,1.000000e+000,1,2,3.366089e-001,0,,0,
1717109596.169,,1.000000e+003,2.744677e+002,-4.476140e-005,1.107178e-008,-2.487000e-002,4.174975e-004,3,9.810168e-001,1.799000e+000,,,,,,,,,,,,,,,,,,0,4.000000e+000,1.000000e+000,1,2,2.973022e-001,0,,0,
1717109630.619,,1.000000e+003,2.756019e+002,-4.477931e-005,1.089685e-008,-2.425390e-002,4.050655e-004,3,9.801527e-001,1.799000e+000,,,,,,,,,,,,,,,,,,0,4.000000e+000,1.000000e+000,1,2,3.286133e-001,0,,0,
1717109668.424,,1.000000e+003,2.768671e+002,-4.479659e-005,2.877274e-008,-2.349775e-002,4.708949e-004,3,9.793006e-001,1.799000e+000,,,,,,,,,,,,,,,,,,0,4.000000e+000,1.000000e+000,1,2,3.680115e-001,0,,0,
1717109706.719,,1.000000e+003,2.781248e+002,-4.486100e-005,3.306356e-008,-2.228230e-002,5.936660e-004,3,9.807084e-001,1.799000e+000,,,,,,,,,,,,,,,,,,0,4.000000e+000,1.000000e+000,1,2,3.277893e-001,0,,0,
1717109741.974,,1.000000e+003,2.792205e+002,-4.482198e-005,3.521670e-008,-2.091670e-002,3.661666e-004,3,9.800775e-001,1.799000e+000,,,,,,,,,,,,,,,,,,0,4.000000e+000,1.000000e+000,1,2,2.792969e-001,0,,0,
1717109782.824,,1.000000e+003,2.804758e+002,-4.485741e-005,3.716146e-008,-2.006020e-002,2.140414e-004,3,9.792062e-001,1.799000e+000,,,,,,,,,,,,,,,,,,0,4.000000e+000,1.000000e+000,1,2,3.116150e-001,0,,0,
1717109817.879,,1.000000e+003,2.816048e+002,-4.490052e-005,1.913638e-008,-1.853319e-002,9.612195e-004,3,9.800864e-001,1.799000e+000,,,,,,,,,,,,,,,,,,0,4.000000e+000,1.000000e+000,1,2,3.292847e-001,0,,0,
1717109853.024,,1.000000e+003,2.827210e+002,-4.496103e-005,8.378436e-009,-1.779662e-002,8.156324e-004,3,9.825939e-001,1.799000e+000,,,,,,,,,,,,,,,,,,0,4.000000e+000,1.000000e+000,1,2,3.472900e-001,0,,0,
1717109888.384,,1.000000e+003,2.838716e+002,-4.492178e-005,3.443982e-008,-1.594478e-002,2.798287e-004,3,9.795389e-001,1.799000e+000,,,,,,,,,,,,,,,,,,0,4.000000e+000,1.000000e+000,1,2,2.817078e-001,0,,0,
1717109924.684,,1.000000e+003,2.850401e+002,-4.494047e-005,3.194970e-009,-1.569100e-002,4.823312e-005,3,9.803807e-001,1.799000e+000,,,,,,,,,,,,,,,,,,0,4.000000e+000,1.000000e+000,1,2,2.843018e-001,0,,0,
1717109960.719,,1.000000e+003,2.861667e+002,-4.498178e-005,5.904520e-008,-1.430878e-002,4.280559e-004,3,9.811565e-001,1.799000e+000,,,,,,,,,,,,,,,,,,0,4.000000e+000,1.000000e+000,1,2,3.099976e-001,0,,0,
1717109996.709,,1.000000e+003,2.873206e+002,-4.498140e-005,1.304999e-008,-1.287877e-002,1.809801e-003,3,9.812541e-001,1.799000e+000,,,,,,,,,,,,,,,,,,0,4.000000e+000,1.000000e+000,1,2,3.204956e-001,0,,0,
1717110031.279,,1.000000e+003,2.884056e+002,-4.498582e-005,3.711516e-008,-1.219913e-002,1.972894e-003,3,9.803490e-001,1.799000e+000,,,,,,,,,,,,,,,,,,0,4.000000e+000,1.000000e+000,1,2,2.837219e-001,0,,0,
1717110067.874,,1.000000e+003,2.895652e+002,-4.495528e-005,4.206968e-008,-1.196271e-002,1.806569e-003,3,9.799397e-001,1.799000e+000,,,,,,,,,,,,,,,,,,0,4.000000e+000,1.000000e+000,1,2,2.861023e-001,0,,0,
1717110102.664,,1.000000e+003,2.906868e+002,-4.496896e-005,3.452985e-008,-9.738339e-003,1.009200e-004,3,9.801139e-001,1.799000e+000,,,,,,,,,,,,,,,,,,0,4.000000e+000,1.000000e+000,1,2,2.885132e-001,0,,0,
1717110140.929,,1.000000e+003,2.919472e+002,-4.496059e-005,2.388510e-008,-9.426106e-003,5.022679e-004,3,9.799372e-001,1.799000e+000,,,,,,,,,,,,,,,,,,0,4.000000e+000,1.000000e+000,1,2,3.398743e-001,0,,0,
1717110175.869,,1.000000e+003,2.931071e+002,-4.498538e-005,1.685720e-008,-7.675203e-003,1.003042e-004,3,9.816327e-001,1.799000e+000,,,,,,,,,,,,,,,,,,0,4.000000e+000,1.000000e+000,1,2,3.345947e-001,0,,0,
1717110213.139,,1.000000e+003,2.942976e+002,-4.491942e-005,1.847012e-008,-5.576539e-003,1.238810e-003,3,9.796220e-001,1.799000e+000,,,,,,,,,,,,,,,,,,0,4.000000e+000,1.000000e+000,1,2,3.128052e-001,0,,0,
1717110248.394,,1.000000e+003,2.954073e+002,-4.495303e-005,1.773182e-008,-5.793277e-003,4.922752e-005,3,9.792138e-001,1.799000e+000,,,,,,,,,,,,,,,,,,0,4.000000e+000,1.000000e+000,1,2,2.904968e-001,0,,0,
1717110285.674,,1.000000e+003,2.965888e+002,-4.500648e-005,2.035571e-008,-4.265809e-003,1.142096e-003,3,9.814110e-001,1.799000e+000,,,,,,,,,,,,,,,,,,0,4.000000e+000,1.000000e+000,1,2,3.181152e-001,0,,0,
1717110321.704,,1.000000e+003,2.977268e+002,-4.495611e-005,4.450320e-009,-2.368277e-003,3.313761e-004,3,9.795021e-001,1.799000e+000,,,,,,,,,,,,,,,,,,0,4.000000e+000,1.000000e+000,1,2,3.040161e-001,0,,0,
1717110358.334,,1.000000e+003,2.989485e+002,-4.481585e-005,1.103808e-007,-2.159824e-003,2.307880e-003,3,9.800585e-001,1.799000e+000,,,,,,,,,,,,,,,,,,0,4.000000e+000,1.000000e+000,1,2,3.239136e-001,0,,0,
1717110628.854,,1.000000e+003,3.000097e+002,-4.464428e-005,6.429298e-008,-2.236809e-004,4.026981e-004,3,9.800196e-001,1.799000e+000,,,,,,,,,,,,,,,,,,0,4.000000e+000,1.000000e+000,1,2,1.289978e-001,0,,0,
1717110651.439,,1.000000e+003,3.000140e+002,-4.457994e-005,3.870235e-008,1.071802e-003,7.727353e-004,3,9.810440e-001,1.799000e+000,,,,,,,,,,,,,,,,,,0,4.000000e+000,1.000000e+000,1,2,1.721191e-002,0,,0,