File: squid/SIO1/MdeT_1000G_FC.rso.dat
[Header]
TITLE,MPMS RSO Measurement
BYAPP,MPMS Measurement,1.1,Summary
FILEOPENTIME, 1717111006.244000 5/30/2024, 8:16:46 PM

INFO, APPNAME, MPMS MultiVu Application, Revision 1.61,  Build 082

INFO, NAME, SIO1
INFO, WEIGHT, 0.000
INFO, AREA, 1.000
INFO, LENGTH, 1.000
INFO, SHAPE, 0
INFO, COMMENT,
INFO, SEQUENCE FILE: MdeT1000GZFC_FCC_SIO.seq


INFO, BACKGROUND DATA FILE:, None


STARTUPAXIS,X,4,LINEAR,AUTO,0.000000,0.000000
STARTUPAXIS,Y1,5,LINEAR,AUTO,0.000000,0.000000


STARTUPGROUP,Longitudinal
FIELDGROUP,Longitudinal,1,2,3,4,5,6,7,8,9,10,11,19,20,21,22,23,35
FIELDGROUP,Transverse,1,2,3,4,12,13,14,15,16,17,18,24,25,26,27,28,35

PLOT_APPEARANCE,ALL,HORZ_GRID_ON,VERT_GRID_ON,MARKERS_AND_LINES

[Data]
Time,Comment,Field (Oe),Temperature (K),Long Moment (emu),Long Scan Std Dev,Long Offset (cm),Long Offset Std Dev,Long Algorithm,Long Reg Fit,Long Reg Factor,Trans Moment (emu),Trans Scan Std Dev,Trans Offset (cm),Trans Offset Std Dev,Trans Algorithm,Trans Reg Fit,Trans Reg Factor,Long Moment [w/o ABS] (emu),Long Scan Std Dev [w/o ABS],Long Offset [w/o ABS] (cm),Long Offset Std Dev [w/o ABS],Long Reg Fit [w/o ABS],Trans Moment [w/o ABS] (emu),Trans Scan Std Dev [w/o ABS],Trans Offset [w/o ABS] (cm),Trans Offset Std Dev [w/o ABS],Trans Reg Fit [w/o ABS],RSO Position (deg),Amplitude (cm),Frequency,Cycles to Average,Scans per Measurement,Delta Temp (K),Error,EC Comp. Running,Using ABS,
1717111006.244,,1.000000e+003,2.892793e+002,-4.433913e-005,1.479667e-008,-1.011358e-002,8.019294e-005,3,9.812615e-001,1.799000e+000,,,,,,,,,,,,,,,,,,0,4.000000e+000,1.000000e+000,4,2,1.269226e-001,0,,0,
1717111061.744,,1.000000e+003,2.872719e+002,-4.433888e-005,1.663854e-008,-1.010267e-002,1.820638e-004,3,9.816082e-001,1.799000e+000,,,,,,,,,,,,,,,,,,0,4.000000e+000,1.000000e+000,4,2,7.579956e-001,0,,0,
1717111116.364,,1.000000e+003,2.850459e+002,-4.429901e-005,1.605717e-008,-1.042852e-002,1.646467e-004,3,9.815239e-001,1.799000e+000,,,,,,,,,,,,,,,,,,0,4.000000e+000,1.000000e+000,4,2,5.302734e-001,0,,0,
1717111171.449,,1.000000e+003,2.833036e+002,-4.428206e-005,1.735625e-008,-1.083331e-002,1.130563e-004,3,9.813700e-001,1.799000e+000,,,,,,,,,,,,,,,,,,0,4.000000e+000,1.000000e+000,4,2,4.548950e-001,0,,0,
1717111225.829,,1.000000e+003,2.818127e+002,-4.427464e-005,1.114638e-008,-1.139089e-002,1.813737e-004,3,9.814554e-001,1.799000e+000,,,,,,,,,,,,,,,,,,0,4.000000e+000,1.000000e+000,4,2,4.349060e-001,0,,0,
1717111280.634,,1.000000e+003,2.802720e+002,-4.424044e-005,9.595199e-009,-1.160990e-002,3.170892e-005,3,9.813615e-001,1.799000e+000,,,,,,,,,,,,,,,,,,0,4.000000e+000,1.000000e+000,4,2,4.593201e-001,0,,0,
1717111335.519,,1.000000e+003,2.786725e+002,-4.422468e-005,8.483905e-009,-1.187711e-002,2.891886e-004,3,9.815558e-001,1.799000e+000,,,,,,,,,,,,,,,,,,0,4.000000e+000,1.000000e+000,4,2,4.902039e-001,0,,0,
1717111391.264,,1.000000e+003,2.769392e+002,-4.421420e-005,2.232877e-009,-1.203406e-002,1.945992e-004,3,9.817286e-001,1.799000e+000,,,,,,,,,,,,,,,,,,0,4.000000e+000,1.000000e+000,4,2,5.124817e-001,0,,0,
1717111448.814,,1.000000e+003,2.751030e+002,-4.418017e-005,1.114124e-008,-1.238786e-002,1.296207e-004,3,9.816955e-001,1.799000e+000,,,,,,,,,,,,,,,,,,0,4.000000e+000,1.000000e+000,4,2,5.123901e-001,0,,0,
1717111503.839,,1.000000e+003,2.733595e+002,-4.414653e-005,4.694703e-009,-1.264877e-002,1.106394e-004,3,9.811686e-001,1.799000e+000,,,,,,,,,,,,,,,,,,0,4.000000e+000,1.000000e+000,4,2,5.263062e-001,0,,0,
1717111560.349,,1.000000e+003,2.715949e+002,-4.411912e-005,9.739256e-009,-1.291493e-002,2.571992e-004,3,9.813875e-001,1.799000e+000,,,,,,,,,,,,,,,,,,0,4.000000e+000,1.000000e+000,4,2,4.566956e-001,0,,0,
1717111614.479,,1.000000e+003,2.698925e+002,-4.408705e-005,2.222330e-008,-1.328920e-002,5.196074e-004,3,9.813371e-001,1.799000e+000,,,,,,,,,,,,,,,,,,0,4.000000e+000,1.000000e+000,4,2,4.981995e-001,0,,0,
1717111670.179,,1.000000e+003,2.681711e+002,-4.403848e-005,1.311172e-008,-1.342486e-002,1.154626e-005,3,9.811735e-001,1.799000e+000,,,,,,,,,,,,,,,,,,0,4.000000e+000,1.000000e+000,4,2,5.046997e-001,0,,0,
1717111723.484,,1.000000e+003,2.664950e+002,-4.399748e-005,1.046726e-008,-1.332952e-002,2.120922e-004,3,9.815893e-001,1.799000e+000,,,,,,,,,,,,,,,,,,0,4.000000e+000,1.000000e+000,4,2,4.779968e-001,0,,0,
1717111778.839,,1.000000e+003,2.647664e+002,-4.397010e-005,2.107085e-008,-1.363623e-002,6.139610e-005,3,9.810386e-001,1.799000e+000,,,,,,,,,,,,,,,,,,0,4.000000e+000,1.000000e+000,4,2,5.039063e-001,0,,0,
1717111833.424,,1.000000e+003,2.630476e+002,-4.395208e-005,7.303156e-009,-1.371024e-002,6.821863e-005,3,9.814498e-001,1.799000e+000,,,,,,,,,,,,,,,,,,0,4.000000e+000,1.000000e+000,4,2,4.491882e-001,0,,0,
1717111888.859,,1.000000e+003,2.613011e+002,-4.386699e-005,2.574755e-008,-1.386119e-002,4.847809e-005,3,9.812663e-001,1.799000e+000,,,,,,,,,,,,,,,,,,0,4.000000e+000,1.000000e+000,4,2,5.151978e-001,0,,0,
1717111942.169,,1.000000e+003,2.595864e+002,-4.380964e-005,1.754918e-008,-1.380670e-002,5.204412e-004,3,9.811172e-001,1.799000e+000,,,,,,,,,,,,,,,,,,0,4.000000e+000,1.000000e+000,4,2,5.456848e-001,0,,0,
1717111998.294,,1.000000e+003,2.577701e+002,-4.375278e-005,2.521248e-008,-1.398780e-002,1.384261e-006,3,9.814800e-001,1.799000e+000,,,,,,,,,,,,,,,,,,0,4.000000e+000,1.000000e+000,4,2,5.190125e-001,0,,0,
1717112053.124,,1.000000e+003,2.560231e+002,-4.369870e-005,7.174534e-009,-1.404557e-002,5.676390e-005,3,9.811372e-001,1.799000e+000,,,,,,,,,,,,,,,,,,0,4.000000e+000,1.000000e+000,4,2,5.056152e-001,0,,0,
1717112109.439,,1.000000e+003,2.542830e+002,-4.361449e-005,2.759199e-008,-1.404098e-002,1.919921e-005,3,9.810598e-001,1.799000e+000,,,,,,,,,,,,,,,,,,0,4.000000e+000,1.000000e+000,4,2,5.163116e-001,0,,0,
1717112163.994,,1.000000e+003,2.525487e+002,-4.354108e-005,4.771876e-009,-1.374452e-002,2.205235e-004,3,9.812919e-001,1.799000e+000,,,,,,,,,,,,,,,,,,0,4.000000e+000,1.000000e+000,4,2,4.851074e-001,0,,0,
1717112219.819,,1.000000e+003,2.508132e+002,-4.343346e-005,1.314774e-008,-1.360437e-002,8.364174e-006,3,9.810101e-001,1.799000e+000,,,,,,,,,,,,,,,,,,0,4.000000e+000,1.000000e+000,4,2,5.247955e-001,0,,0,
1717112275.654,,1.000000e+003,2.490468e+002,-4.336384e-005,3.161529e-009,-1.325384e-002,1.330872e-004,3,9.816289e-001,1.799000e+000,,,,,,,,,,,,,,,,,,0,4.000000e+000,1.000000e+000,4,2,5.225983e-001,0,,0,
1717112330.194,,1.000000e+003,2.472995e+002,-4.321133e-005,2.715982e-008,-1.345535e-002,2.999473e-005,3,9.812149e-001,1.799000e+000,,,,,,,,,,,,,,,,,,0,4.000000e+000,1.000000e+000,4,2,5.261993e-001,0,,0,
1717112386.229,,1.000000e+003,2.455252e+002,-4.308258e-005,3.959241e-008,-1.296599e-002,3.290352e-005,3,9.810522e-001,1.799000e+000,,,,,,,,,,,,,,,,,,0,4.000000e+000,1.000000e+000,4,2,4.848022e-001,0,,0,
1717112440.519,,1.000000e+003,2.438300e+002,-4.293071e-005,2.269663e-008,-1.309920e-002,1.649430e-004,3,9.808947e-001,1.799000e+000,,,,,,,,,,,,,,,,,,0,4.000000e+000,1.000000e+000,4,2,5.546112e-001,0,,0,
1717112495.594,,1.000000e+003,2.420865e+002,-4.274953e-005,1.869906e-008,-1.292804e-002,1.694896e-005,3,9.808036e-001,1.799000e+000,,,,,,,,,,,,,,,,,,0,4.000000e+000,1.000000e+000,4,2,4.920959e-001,0,,0,
1717112550.664,,1.000000e+003,2.403588e+002,-4.253579e-005,5.090600e-008,-1.271514e-002,2.203352e-004,3,9.808896e-001,1.799000e+000,,,,,,,,,,,,,,,,,,0,4.000000e+000,1.000000e+000,4,2,5.325012e-001,0,,0,
1717112605.724,,1.000000e+003,2.386073e+002,-4.229839e-005,3.004609e-009,-1.243035e-002,8.781230e-005,3,9.812117e-001,1.799000e+000,,,,,,,,,,,,,,,,,,0,4.000000e+000,1.000000e+000,4,2,5.453033e-001,0,,0,
1717112660.654,,1.000000e+003,2.368314e+002,-4.197480e-005,3.902905e-008,-1.240532e-002,9.163713e-005,3,9.808653e-001,1.799000e+000,,,,,,,,,,,,,,,,,,0,4.000000e+000,1.000000e+000,4,2,5.417023e-001,0,,0,
1717112716.049,,1.000000e+003,2.350149e+002,-4.158287e-005,3.370667e-008,-1.199511e-002,1.620678e-006,3,9.808451e-001,1.799000e+000,,,,,,,,,,,,,,,,,,0,4.000000e+000,1.000000e+000,4,2,5.531006e-001,0,,0,
1717112771.464,,1.000000e+003,2.332077e+002,-4.110927e-005,9.497446e-008,-1.174894e-002,2.209009e-004,3,9.805188e-001,1.799000e+000,,,,,,,,,,,,,,,,,,0,4.000000e+000,1.000000e+000,4,2,5.155029e-001,0,,0,
1717112826.004,,1.000000e+003,2.314355e+002,-4.052627e-005,9.359564e-008,-1.151850e-002,6.225221e-005,3,9.805541e-001,1.799000e+000,,,,,,,,,,,,,,,,,,0,4.000000e+000,1.000000e+000,4,2,5.108032e-001,0,,0,
1717112882.264,,1.000000e+003,2.296196e+002,-3.970679e-005,1.138433e-007,-1.098662e-002,1.346454e-004,3,9.798278e-001,1.799000e+000,,,,,,,,,,,,,,,,,,0,4.000000e+000,1.000000e+000,4,2,5.169983e-001,0,,0,
1717112938.869,,1.000000e+003,2.277808e+002,-3.863611e-005,1.039651e-007,-1.036014e-002,1.003635e-004,3,9.795867e-001,1.799000e+000,,,,,,,,,,,,,,,,,,0,4.000000e+000,1.000000e+000,4,2,5.511932e-001,0,,0,
1717112993.734,,1.000000e+003,2.260003e+002,-3.724263e-005,1.843976e-007,-9.694809e-003,2.278044e-004,3,9.792441e-001,1.799000e+000,,,,,,,,,,,,,,,,,,0,4.000000e+000,1.000000e+000,4,2,5.048065e-001,0,,0,
1717113046.719,,1.000000e+003,2.242740e+002,-3.528436e-005,2.544915e-007,-8.514710e-003,2.137267e-004,3,9.778341e-001,1.799000e+000,,,,,,,,,,,,,,,,,,0,4.000000e+000,1.000000e+000,4,2,5.614014e-001,0,,0,
1717113102.754,,1.000000e+003,2.224684e+002,-3.229159e-005,4.187391e-007,-6.512051e-003,8.769573e-005,3,9.764295e-001,1.799000e+000,,,,,,,,,,,,,,,,,,0,4.000000e+000,1.000000e+000,4,2,5.563965e-001,0,,0,
1717113157.354,,1.000000e+003,2.206784e+002,-2.782177e-005,5.769557e-007,-2.960712e-003,5.893381e-004,3,9.735427e-001,1.799000e+000,,,,,,,,,,,,,,,,,,0,4.000000e+000,1.000000e+000,4,2,6.006012e-001,0,,0,
1717113214.099,,1.000000e+003,2.188000e+002,-2.123447e-005,8.065305e-007,3.799378e-003,1.536350e-003,3,9.666741e-001,1.799000e+000,,,,,,,,,,,,,,,,,,0,4.000000e+000,1.000000e+000,4,2,5.287933e-001,0,,0,
1717113294.229,,1.000000e+003,2.161836e+002,-8.528162e-006,1.023450e-006,5.311713e-002,1.083609e-002,3,9.181972e-001,1.799000e+000,,,,,,,,,,,,,,,,,,0,4.000000e+000,1.000000e+000,4,2,4.943085e-001,0,,0,
1717113348.484,,1.000000e+003,2.144120e+002,2.552862e-006,1.202717e-006,-2.945054e-001,1.365385e-001,3,6.554848e-001,1.799000e+000,,,,,,,,,,,,,,,,,,0,4.000000e+000,1.000000e+000,4,2,5.236969e-001,0,,0,
1717113404.799,,1.000000e+003,2.126077e+002,1.641818e-005,1.626114e-006,-6.559415e-002,3.043182e-003,3,9.555542e-001,1.799000e+000,,,,,,,,,,,,,,,,,,0,4.000000e+000,1.000000e+000,4,2,5.599060e-001,0,,0,
1717113460.879,,1.000000e+003,2.107943e+002,3.378497e-005,1.923956e-006,-4.714308e-002,1.035069e-003,3,9.770882e-001,1.799000e+000,,,,,,,,,,,,,,,,,,0,4.000000e+000,1.000000e+000,4,2,5.052948e-001,0,,0,
1717113516.869,,1.000000e+003,2.090150e+002,5.317137e-005,2.101454e-006,-4.086247e-002,2.449259e-004,3,9.832090e-001,1.799000e+000,,,,,,,,,,,,,,,,,,0,4.000000e+000,1.000000e+000,4,2,5.204010e-001,0,,0,
1717113571.404,,1.000000e+003,2.072921e+002,7.204496e-005,2.063668e-006,-3.794783e-002,2.859427e-004,3,9.860625e-001,1.799000e+000,,,,,,,,,,,,,,,,,,0,4.000000e+000,1.000000e+000,4,2,5.193939e-001,0,,0,
1717113626.929,,1.000000e+003,2.055285e+002,8.997566e-005,1.791900e-006,-3.639963e-002,1.101113e-004,3,9.873919e-001,1.799000e+000,,,,,,,,,,,,,,,,,,0,4.000000e+000,1.000000e+000,4,2,4.869995e-001,0,,0,
1717113683.004,,1.000000e+003,2.037796e+002,1.058611e-004,1.530195e-006,-3.531775e-002,5.743562e-005,3,9.880984e-001,1.799000e+000,,,,,,,,,,,,,,,,,,0,4.000000e+000,1.000000e+000,4,2,5.164948e-001,0,,0,
1717113738.049,,1.000000e+003,2.020432e+002,1.191705e-004,1.289085e-006,-3.446489e-002,1.229661e-004,3,9.885346e-001,1.799000e+000,,,,,,,,,,,,,,,,,,0,4.000000e+000,1.000000e+000,4,2,4.629974e-001,0,,0,
1717113791.589,,1.000000e+003,2.003513e+002,1.301257e-004,1.070979e-006,-3.390222e-002,9.488309e-006,3,9.887542e-001,1.799000e+000,,,,,,,,,,,,,,,,,,0,4.000000e+000,1.000000e+000,4,2,5.133057e-001,0,,0,
1717113847.084,,1.000000e+003,1.986093e+002,1.398234e-004,9.274571e-007,-3.345498e-002,7.740532e-005,3,9.889666e-001,1.799000e+000,,,,,,,,,,,,,,,,,,0,4.000000e+000,1.000000e+000,4,2,5.292053e-001,0,,0,
1717113902.409,,1.000000e+003,1.968409e+002,1.483069e-004,8.091557e-007,-3.272517e-002,8.574250e-005,3,9.889715e-001,1.799000e+000,,,,,,,,,,,,,,,,,,0,4.000000e+000,1.000000e+000,4,2,4.987030e-001,0,,0,
1717113957.709,,1.000000e+003,1.950474e+002,1.557827e-004,7.595590e-007,-3.228872e-002,1.535278e-004,3,9.893013e-001,1.799000e+000,,,,,,,,,,,,,,,,,,0,4.000000e+000,1.000000e+000,4,2,5.308075e-001,0,,0,
1717114012.244,,1.000000e+003,1.932776e+002,1.623248e-004,6.931593e-007,-3.175188e-002,2.340204e-005,3,9.893247e-001,1.799000e+000,,,,,,,,,,,,,,,,,,0,4.000000e+000,1.000000e+000,4,2,5.379944e-001,0,,0,
1717114068.119,,1.000000e+003,1.914879e+002,1.681695e-004,5.815463e-007,-3.125654e-002,3.251761e-005,3,9.895277e-001,1.799000e+000,,,,,,,,,,,,,,,,,,0,4.000000e+000,1.000000e+000,4,2,4.481964e-001,0,,0,
1717114122.184,,1.000000e+003,1.897839e+002,1.731294e-004,5.097855e-007,-3.085137e-002,5.434309e-006,3,9.895388e-001,1.799000e+000,,,,,,,,,,,,,,,,,,0,4.000000e+000,1.000000e+000,4,2,5.378876e-001,0,,0,
1717114178.229,,1.000000e+003,1.880009e+002,1.774981e-004,4.270250e-007,-3.022538e-002,1.918024e-004,3,9.893796e-001,1.799000e+000,,,,,,,,,,,,,,,,,,0,4.000000e+000,1.000000e+000,4,2,4.924011e-001,0,,0,
1717114233.014,,1.000000e+003,1.862802e+002,1.812029e-004,3.601004e-007,-2.983160e-002,3.854461e-005,3,9.893246e-001,1.799000e+000,,,,,,,,,,,,,,,,,,0,4.000000e+000,1.000000e+000,4,2,5.302887e-001,0,,0,
1717114289.709,,1.000000e+003,1.845081e+002,1.842078e-004,2.696740e-007,-2.941148e-002,5.062495e-005,3,9.895331e-001,1.799000e+000,,,,,,,,,,,,,,,,,,0,4.000000e+000,1.000000e+000,4,2,4.924011e-001,0,,0,
1717114346.789,,1.000000e+003,1.826755e+002,1.866798e-004,2.547847e-007,-2.874683e-002,6.555020e-005,3,9.895972e-001,1.799000e+000,,,,,,,,,,,,,,,,,,0,4.000000e+000,1.000000e+000,4,2,4.889069e-001,0,,0,
1717114402.589,,1.000000e+003,1.809265e+002,1.886772e-004,2.170316e-007,-2.828463e-002,3.896081e-005,3,9.895624e-001,1.799000e+000,,,,,,,,,,,,,,,,,,0,4.000000e+000,1.000000e+000,4,2,5.352020e-001,0,,0,
1717114457.649,,1.000000e+003,1.791639e+002,1.902011e-004,1.578758e-007,-2.770704e-002,9.711424e-005,3,9.898126e-001,1.799000e+000,,,,,,,,,,,,,,,,,,0,4.000000e+000,1.000000e+000,4,2,5.478973e-001,0,,0,
1717114513.139,,1.000000e+003,1.773723e+002,1.914937e-004,1.186100e-007,-2.722185e-002,1.685084e-005,3,9.895554e-001,1.799000e+000,,,,,,,,,,,,,,,,,,0,4.000000e+000,1.000000e+000,4,2,4.886932e-001,0,,0,
1717114570.709,,1.000000e+003,1.755089e+002,1.925252e-004,8.196821e-008,-2.670768e-002,1.111887e-005,3,9.894140e-001,1.799000e+000,,,,,,,,,,,,,,,,,,0,4.000000e+000,1.000000e+000,4,2,5.672913e-001,0,,0,
1717114627.969,,1.000000e+003,1.736558e+002,1.932633e-004,5.977320e-008,-2.621677e-002,5.669278e-005,3,9.897014e-001,1.799000e+000,,,,,,,,,,,,,,,,,,0,4.000000e+000,1.000000e+000,4,2,4.955139e-001,0,,0,
1717114683.039,,1.000000e+003,1.719046e+002,1.938129e-004,2.456165e-008,-2.568715e-002,3.992755e-005,3,9.895102e-001,1.799000e+000,,,,,,,,,,,,,,,,,,0,4.000000e+000,1.000000e+000,4,2,5.279999e-001,0,,0,
1717114738.634,,1.000000e+003,1.701650e+002,1.940931e-004,2.966537e-008,-2.532286e-002,1.297978e-004,3,9.896837e-001,1.799000e+000,,,,,,,,,,,,,,,,,,0,4.000000e+000,1.000000e+000,4,2,5.276947e-001,0,,0,
1717114793.704,,1.000000e+003,1.683852e+002,1.942574e-004,2.133067e-008,-2.493072e-002,7.786103e-005,3,9.897858e-001,1.799000e+000,,,,,,,,,,,,,,,,,,0,4.000000e+000,1.000000e+000,4,2,4.806976e-001,0,,0,
1717114849.504,,1.000000e+003,1.666427e+002,1.942738e-004,4.023308e-009,-2.450200e-002,1.853276e-005,3,9.895804e-001,1.799000e+000,,,,,,,,,,,,,,,,,,0,4.000000e+000,1.000000e+000,4,2,5.361023e-001,0,,0,
1717114904.269,,1.000000e+003,1.648650e+002,1.940484e-004,3.333881e-008,-2.396249e-002,8.706222e-005,3,9.896318e-001,1.799000e+000,,,,,,,,,,,,,,,,,,0,4.000000e+000,1.000000e+000,4,2,5.391998e-001,0,,0,
1717114958.894,,1.000000e+003,1.630941e+002,1.937444e-004,3.111623e-008,-2.359562e-002,4.993216e-005,3,9.894923e-001,1.799000e+000,,,,,,,,,,,,,,,,,,0,4.000000e+000,1.000000e+000,4,2,5.034943e-001,0,,0,
1717115014.249,,1.000000e+003,1.613281e+002,1.933519e-004,2.679453e-008,-2.308265e-002,2.358459e-004,3,9.894003e-001,1.799000e+000,,,,,,,,,,,,,,,,,,0,4.000000e+000,1.000000e+000,4,2,5.066986e-001,0,,0,
1717115069.509,,1.000000e+003,1.595579e+002,1.928146e-004,6.949703e-008,-2.271208e-002,1.352255e-004,3,9.895152e-001,1.799000e+000,,,,,,,,,,,,,,,,,,0,4.000000e+000,1.000000e+000,4,2,5.370941e-001,0,,0,
1717115131.864,,1.000000e+003,1.575592e+002,1.921309e-004,8.297661e-008,-2.221372e-002,4.522752e-005,3,9.896502e-001,1.799000e+000,,,,,,,,,,,,,,,,,,0,4.000000e+000,1.000000e+000,4,2,4.698944e-001,0,,0,
1717115186.729,,1.000000e+003,1.557945e+002,1.914428e-004,4.006832e-008,-2.183992e-002,7.430358e-005,3,9.895737e-001,1.799000e+000,,,,,,,,,,,,,,,,,,0,4.000000e+000,1.000000e+000,4,2,5.120087e-001,0,,0,
1717115242.259,,1.000000e+003,1.540175e+002,1.907232e-004,7.057745e-008,-2.133842e-002,6.462956e-006,3,9.894688e-001,1.799000e+000,,,,,,,,,,,,,,,,,,0,4.000000e+000,1.000000e+000,4,2,5.431976e-001,0,,0,
1717115297.384,,1.000000e+003,1.522604e+002,1.899645e-004,9.821574e-008,-2.088334e-002,1.070859e-004,3,9.894874e-001,1.799000e+000,,,,,,,,,,,,,,,,,,0,4.000000e+000,1.000000e+000,4,2,4.723969e-001,0,,0,
1717115352.414,,1.000000e+003,1.505092e+002,1.891715e-004,1.046571e-007,-2.039290e-002,1.549608e-004,3,9.895361e-001,1.799000e+000,,,,,,,,,,,,,,,,,,0,4.000000e+000,1.000000e+000,4,2,4.738922e-001,0,,0,
1717115406.639,,1.000000e+003,1.487948e+002,1.883879e-004,1.052539e-007,-2.012792e-002,5.169048e-005,3,9.895971e-001,1.799000e+000,,,,,,,,,,,,,,,,,,0,4.000000e+000,1.000000e+000,4,2,4.791870e-001,0,,0,
1717115461.789,,1.000000e+003,1.470349e+002,1.875086e-004,1.016628e-007,-1.946333e-002,1.217688e-004,3,9.894778e-001,1.799000e+000,,,,,,,,,,,,,,,,,,0,4.000000e+000,1.000000e+000,4,2,5.226135e-001,0,,0,
1717115516.439,,1.000000e+003,1.452656e+002,1.866322e-004,5.966002e-008,-1.906727e-002,5.286268e-005,3,9.895219e-001,1.799000e+000,,,,,,,,,,,,,,,,,,0,4.000000e+000,1.000000e+000,4,2,4.987030e-001,0,,0,
1717115573.509,,1.000000e+003,1.434479e+002,1.856985e-004,1.248765e-007,-1.857164e-002,7.694829e-005,3,9.895528e-001,1.799000e+000,,,,,,,,,,,,,,,,,,0,4.000000e+000,1.000000e+000,4,2,5.393982e-001,0,,0,
1717115628.529,,1.000000e+003,1.416418e+002,1.846834e-004,1.249485e-007,-1.808406e-002,1.369298e-004,3,9.894812e-001,1.799000e+000,,,,,,,,,,,,,,,,,,0,4.000000e+000,1.000000e+000,4,2,5.068054e-001,0,,0,
1717115683.859,,1.000000e+003,1.398607e+002,1.836267e-004,1.138356e-007,-1.766529e-002,1.205374e-004,3,9.896025e-001,1.799000e+000,,,,,,,,,,,,,,,,,,0,4.000000e+000,1.000000e+000,4,2,5.049133e-001,0,,0,
1717115741.354,,1.000000e+003,1.379935e+002,1.824405e-004,1.290336e-007,-1.724781e-002,1.305815e-004,3,9.897649e-001,1.799000e+000,,,,,,,,,,,,,,,,,,0,4.000000e+000,1.000000e+000,4,2,4.947968e-001,0,,0,
1717115798.444,,1.000000e+003,1.361644e+002,1.812630e-004,1.090406e-007,-1.671883e-002,5.969838e-005,3,9.895398e-001,1.799000e+000,,,,,,,,,,,,,,,,,,0,4.000000e+000,1.000000e+000,4,2,5.390015e-001,0,,0,
1717115851.789,,1.000000e+003,1.344422e+002,1.801251e-004,1.408874e-007,-1.627159e-002,2.211129e-005,3,9.894580e-001,1.799000e+000,,,,,,,,,,,,,,,,,,0,4.000000e+000,1.000000e+000,4,2,5.059052e-001,0,,0,
1717115907.274,,1.000000e+003,1.326418e+002,1.789473e-004,1.183940e-007,-1.590760e-002,1.382970e-004,3,9.897730e-001,1.799000e+000,,,,,,,,,,,,,,,,,,0,4.000000e+000,1.000000e+000,4,2,5.433960e-001,0,,0,
1717115963.369,,1.000000e+003,1.308081e+002,1.778302e-004,1.232301e-007,-1.537579e-002,6.726044e-005,3,9.894887e-001,1.799000e+000,,,,,,,,,,,,,,,,,,0,4.000000e+000,1.000000e+000,4,2,4.915009e-001,0,,0,
1717116018.169,,1.000000e+003,1.290248e+002,1.767603e-004,1.273975e-007,-1.491637e-002,7.782943e-005,3,9.895745e-001,1.799000e+000,,,,,,,,,,,,,,,,,,0,4.000000e+000,1.000000e+000,4,2,5.175018e-001,0,,0,
1717116073.959,,1.000000e+003,1.272154e+002,1.757450e-004,9.178464e-008,-1.439238e-002,9.853801e-006,3,9.894413e-001,1.799000e+000,,,,,,,,,,,,,,,,,,0,4.000000e+000,1.000000e+000,4,2,5.074997e-001,0,,0,
1717116129.279,,1.000000e+003,1.254421e+002,1.748640e-004,8.767903e-008,-1.397903e-002,4.133882e-005,3,9.895520e-001,1.799000e+000,,,,,,,,,,,,,,,,,,0,4.000000e+000,1.000000e+000,4,2,5.121994e-001,0,,0,
1717116184.629,,1.000000e+003,1.236432e+002,1.741827e-004,8.705135e-008,-1.348899e-002,6.243595e-005,3,9.895580e-001,1.799000e+000,,,,,,,,,,,,,,,,,,0,4.000000e+000,1.000000e+000,4,2,5.288010e-001,0,,0,
1717116241.124,,1.000000e+003,1.218113e+002,1.737189e-004,3.211434e-008,-1.299658e-002,1.961804e-004,3,9.894413e-001,1.799000e+000,,,,,,,,,,,,,,,,,,0,4.000000e+000,1.000000e+000,4,2,5.381012e-001,0,,0,
1717116296.149,,1.000000e+003,1.200059e+002,1.735240e-004,1.270786e-008,-1.245943e-002,9.365095e-005,3,9.894325e-001,1.799000e+000,,,,,,,,,,,,,,,,,,0,4.000000e+000,1.000000e+000,4,2,5.307007e-001,0,,0,
1717116352.704,,1.000000e+003,1.181561e+002,1.736692e-004,3.344171e-008,-1.182687e-002,1.647922e-004,3,9.894301e-001,1.799000e+000,,,,,,,,,,,,,,,,,,0,4.000000e+000,1.000000e+000,4,2,5.327988e-001,0,,0,
1717116407.529,,1.000000e+003,1.163615e+002,1.740315e-004,5.585281e-008,-1.138732e-002,1.324340e-004,3,9.893486e-001,1.799000e+000,,,,,,,,,,,,,,,,,,0,4.000000e+000,1.000000e+000,4,2,5.395966e-001,0,,0,
1717116462.664,,1.000000e+003,1.145543e+002,1.745235e-004,7.141092e-008,-1.071241e-002,1.670398e-005,3,9.895995e-001,1.799000e+000,,,,,,,,,,,,,,,,,,0,4.000000e+000,1.000000e+000,4,2,5.380020e-001,0,,0,
1717116516.134,,1.000000e+003,1.128049e+002,1.748627e-004,1.192583e-008,-1.024866e-002,1.043530e-005,3,9.894823e-001,1.799000e+000,,,,,,,,,,,,,,,,,,0,4.000000e+000,1.000000e+000,4,2,5.037994e-001,0,,0,
1717116586.239,,1.000000e+003,1.105109e+002,1.753879e-004,3.933775e-008,-9.601590e-003,4.592821e-005,3,9.897385e-001,1.799000e+000,,,,,,,,,,,,,,,,,,0,4.000000e+000,1.000000e+000,4,2,5.083008e-001,0,,0,
1717116640.389,,1.000000e+003,1.087626e+002,1.758903e-004,4.375205e-008,-9.296432e-003,1.120033e-004,3,9.896584e-001,1.799000e+000,,,,,,,,,,,,,,,,,,0,4.000000e+000,1.000000e+000,4,2,5.439987e-001,0,,0,
1717116696.124,,1.000000e+003,1.069625e+002,1.760794e-004,5.211762e-008,-9.221682e-003,1.372341e-005,3,9.896021e-001,1.799000e+000,,,,,,,,,,,,,,,,,,0,4.000000e+000,1.000000e+000,4,2,5.133972e-001,0,,0,
1717116751.449,,1.000000e+003,1.051628e+002,1.765251e-004,9.939906e-009,-9.073835e-003,1.075515e-004,3,9.896209e-001,1.799000e+000,,,,,,,,,,,,,,,,,,0,4.000000e+000,1.000000e+000,4,2,5.164032e-001,0,,0,
1717116805.234,,1.000000e+003,1.033983e+002,1.770108e-004,6.560749e-008,-8.571716e-003,2.289167e-005,3,9.895638e-001,1.799000e+000,,,,,,,,,,,,,,,,,,0,4.000000e+000,1.000000e+000,4,2,5.557022e-001,0,,0,
1717116861.269,,1.000000e+003,1.015553e+002,1.775999e-004,8.843018e-008,-8.119246e-003,1.486862e-005,3,9.896562e-001,1.799000e+000,,,,,,,,,,,,,,,,,,0,4.000000e+000,1.000000e+000,4,2,5.585022e-001,0,,0,
1717116917.764,,1.000000e+003,9.971645e+001,1.782153e-004,5.091372e-008,-7.676367e-003,1.399400e-004,3,9.896520e-001,1.799000e+000,,,,,,,,,,,,,,,,,,0,4.000000e+000,1.000000e+000,4,2,5.713654e-001,0,,0,
1717116973.314,,1.000000e+003,9.788023e+001,1.786585e-004,6.315853e-008,-7.240212e-003,7.450345e-005,3,9.894593e-001,1.799000e+000,,,,,,,,,,,,,,,,,,0,4.000000e+000,1.000000e+000,4,2,5.348129e-001,0,,0,
1717117026.384,,1.000000e+003,9.612261e+001,1.788777e-004,3.272143e-009,-6.882288e-003,1.112957e-004,3,9.896789e-001,1.799000e+000,,,,,,,,,,,,,,,,,,0,4.000000e+000,1.000000e+000,4,2,5.413895e-001,0,,0,
1717117081.654,,1.000000e+003,9.428805e+001,1.788093e-004,2.606396e-008,-6.364418e-003,9.136646e-006,3,9.894744e-001,1.799000e+000,,,,,,,,,,,,,,,,,,0,4.000000e+000,1.000000e+000,4,2,5.068436e-001,0,,0,
1717117136.269,,1.000000e+003,9.246478e+001,1.784624e-004,6.582358e-008,-5.952690e-003,8.971681e-005,3,9.895694e-001,1.799000e+000,,,,,,,,,,,,,,,,,,0,4.000000e+000,1.000000e+000,4,2,5.566254e-001,0,,0,
1717117191.964,,1.000000e+003,9.061183e+001,1.780448e-004,6.606025e-008,-5.569233e-003,7.036186e-005,3,9.896447e-001,1.799000e+000,,,,,,,,,,,,,,,,,,0,4.000000e+000,1.000000e+000,4,2,5.111237e-001,0,,0,
1717117246.069,,1.000000e+003,8.881667e+001,1.775333e-004,2.612570e-008,-5.187073e-003,7.595883e-005,3,9.893704e-001,1.799000e+000,,,,,,,,,,,,,,,,,,0,4.000000e+000,1.000000e+000,4,2,5.507507e-001,0,,0,
1717117299.704,,1.000000e+003,8.704858e+001,1.770734e-004,3.897760e-008,-4.775055e-003,1.080481e-004,3,9.895235e-001,1.799000e+000,,,,,,,,,,,,,,,,,,0,4.000000e+000,1.000000e+000,4,2,5.085831e-001,0,,0,
1717117353.699,,1.000000e+003,8.523050e+001,1.765463e-004,6.813877e-008,-4.518850e-003,4.184524e-005,3,9.896656e-001,1.799000e+000,,,,,,,,,,,,,,,,,,0,4.000000e+000,1.000000e+000,4,2,5.489655e-001,0,,0,
1717117410.309,,1.000000e+003,8.331980e+001,1.757153e-004,8.585774e-008,-4.104548e-003,7.340466e-005,3,9.894694e-001,1.799000e+000,,,,,,,,,,,,,,,,,,0,4.000000e+000,1.000000e+000,4,2,5.527344e-001,0,,0,
1717117464.864,,1.000000e+003,8.147230e+001,1.749650e-004,1.163154e-007,-3.847066e-003,2.666792e-005,3,9.895422e-001,1.799000e+000,,,,,,,,,,,,,,,,,,0,4.000000e+000,1.000000e+000,4,2,5.312119e-001,0,,0,
1717117520.689,,1.000000e+003,7.960376e+001,1.742359e-004,7.225468e-008,-3.402712e-003,5.635462e-005,3,9.894530e-001,1.799000e+000,,,,,,,,,,,,,,,,,,0,4.000000e+000,1.000000e+000,4,2,5.235291e-001,0,,0,
1717117575.724,,1.000000e+003,7.776251e+001,1.736198e-004,6.801530e-008,-3.165918e-003,4.025354e-007,3,9.895214e-001,1.799000e+000,,,,,,,,,,,,,,,,,,0,4.000000e+000,1.000000e+000,4,2,5.242691e-001,0,,0,
1717117631.759,,1.000000e+003,7.584536e+001,1.730884e-004,3.748559e-008,-2.821390e-003,1.296931e-004,3,9.894620e-001,1.799000e+000,,,,,,,,,,,,,,,,,,0,4.000000e+000,1.000000e+000,4,2,5.687485e-001,0,,0,
1717117686.334,,1.000000e+003,7.395683e+001,1.725704e-004,2.815278e-008,-2.661518e-003,4.764882e-005,3,9.894123e-001,1.799000e+000,,,,,,,,,,,,,,,,,,0,4.000000e+000,1.000000e+000,4,2,5.472412e-001,0,,0,
1717117742.464,,1.000000e+003,7.202953e+001,1.720849e-004,5.513252e-008,-2.169828e-003,1.216498e-004,3,9.896325e-001,1.799000e+000,,,,,,,,,,,,,,,,,,0,4.000000e+000,1.000000e+000,4,2,6.264496e-001,0,,0,
1717117796.869,,1.000000e+003,7.014552e+001,1.715923e-004,1.199786e-008,-1.932031e-003,2.050395e-005,3,9.896584e-001,1.799000e+000,,,,,,,,,,,,,,,,,,0,4.000000e+000,1.000000e+000,4,2,5.561676e-001,0,,0,
1717117851.899,,1.000000e+003,6.822715e+001,1.711668e-004,4.001687e-008,-1.589667e-003,4.137388e-005,3,9.895506e-001,1.799000e+000,,,,,,,,,,,,,,,,,,0,4.000000e+000,1.000000e+000,4,2,5.572739e-001,0,,0,
1717117907.199,,1.000000e+003,6.629884e+001,1.707573e-004,3.376070e-008,-1.341503e-003,6.730555e-005,3,9.897170e-001,1.799000e+000,,,,,,,,,,,,,,,,,,0,4.000000e+000,1.000000e+000,4,2,5.230713e-001,0,,0,
1717117963.194,,1.000000e+003,6.437851e+001,1.703956e-004,3.738269e-008,-1.103060e-003,1.444372e-004,3,9.894048e-001,1.799000e+000,,,,,,,,,,,,,,,,,,0,4.000000e+000,1.000000e+000,4,2,5.664520e-001,0,,0,
1717118018.819,,1.000000e+003,6.243455e+001,1.700663e-004,1.274901e-008,-7.927478e-004,2.907663e-005,3,9.895406e-001,1.799000e+000,,,,,,,,,,,,,,,,,,0,4.000000e+000,1.000000e+000,4,2,5.468178e-001,0,,0,
1717118074.224,,1.000000e+003,6.047245e+001,1.698025e-004,3.868949e-008,-4.471655e-004,8.179511e-005,3,9.896002e-001,1.799000e+000,,,,,,,,,,,,,,,,,,0,4.000000e+000,1.000000e+000,4,2,5.605125e-001,0,,0,
1717118130.959,,1.000000e+003,5.850314e+001,1.695802e-004,2.228762e-008,-3.854555e-006,2.656596e-005,3,9.894204e-001,1.799000e+000,,,,,,,,,,,,,,,,,,0,4.000000e+000,1.000000e+000,4,2,6.068802e-001,0,,0,
1717118186.534,,1.000000e+003,5.648870e+001,1.693234e-004,5.604831e-008,3.557369e-004,6.283387e-005,3,9.895627e-001,1.799000e+000,,,,,,,,,,,,,,,,,,0,4.000000e+000,1.000000e+000,4,2,5.686684e-001,0,,0,
1717118241.449,,1.000000e+003,5.453806e+001,1.691364e-004,3.808601e-010,7.374376e-004,1.100514e-004,3,9.894699e-001,1.799000e+000,,,,,,,,,,,,,,,,,,0,4.000000e+000,1.000000e+000,4,2,6.316605e-001,0,,0,
1717118297.614,,1.000000e+003,5.251016e+001,1.689806e-004,9.065283e-009,1.188424e-003,1.839850e-005,3,9.893780e-001,1.799000e+000,,,,,,,,,,,,,,,,,,0,4.000000e+000,1.000000e+000,4,2,5.345993e-001,0,,0,
1717118354.254,,1.000000e+003,5.058588e+001,1.689986e-004,4.548073e-009,1.679245e-003,1.472454e-004,3,9.894865e-001,1.799000e+000,,,,,,,,,,,,,,,,,,0,4.000000e+000,1.000000e+000,4,2,5.494995e-001,0,,0,
1717118409.784,,1.000000e+003,4.876490e+001,1.690086e-004,7.233707e-009,2.154033e-003,5.838294e-005,3,9.895263e-001,1.799000e+000,,,,,,,,,,,,,,,,,,0,4.000000e+000,1.000000e+000,4,2,5.363922e-001,0,,0,
1717118464.264,,1.000000e+003,4.699491e+001,1.690869e-004,5.144879e-009,2.462089e-003,3.393826e-005,3,9.895093e-001,1.799000e+000,,,,,,,,,,,,,,,,,,0,4.000000e+000,1.000000e+000,4,2,5.612411e-001,0,,0,
1717118518.614,,1.000000e+003,4.518574e+001,1.691794e-004,2.635207e-008,2.776046e-003,9.421961e-005,3,9.895072e-001,1.799000e+000,,,,,,,,,,,,,,,,,,0,4.000000e+000,1.000000e+000,4,2,5.398865e-001,0,,0,
1717118573.514,,1.000000e+003,4.336679e+001,1.693625e-004,9.723827e-009,3.215836e-003,1.672747e-004,3,9.896305e-001,1.799000e+000,,,,,,,,,,,,,,,,,,0,4.000000e+000,1.000000e+000,4,2,5.445290e-001,0,,0,
1717118630.664,,1.000000e+003,4.144292e+001,1.695411e-004,2.396485e-008,3.701088e-003,6.436532e-005,3,9.896575e-001,1.799000e+000,,,,,,,,,,,,,,,,,,0,4.000000e+000,1.000000e+000,4,2,5.813713e-001,0,,0,
1717118685.929,,1.000000e+003,3.955233e+001,1.697790e-004,2.036343e-008,4.230439e-003,1.198024e-005,3,9.894208e-001,1.799000e+000,,,,,,,,,,,,,,,,,,0,4.000000e+000,1.000000e+000,4,2,5.552101e-001,0,,0,
1717118740.759,,1.000000e+003,3.771679e+001,1.699506e-004,2.737076e-009,4.293591e-003,1.445835e-006,3,9.896928e-001,1.799000e+000,,,,,,,,,,,,,,,,,,0,4.000000e+000,1.000000e+000,4,2,5.516624e-001,0,,0,
1717118796.419,,1.000000e+003,3.585162e+001,1.702252e-004,4.882490e-008,4.730350e-003,1.111689e-005,3,9.897540e-001,1.799000e+000,,,,,,,,,,,,,,,,,,0,4.000000e+000,1.000000e+000,4,2,5.611801e-001,0,,0,
1717118851.039,,1.000000e+003,3.398752e+001,1.704894e-004,2.144385e-008,5.019446e-003,5.377708e-005,3,9.897262e-001,1.799000e+000,,,,,,,,,,,,,,,,,,0,4.000000e+000,1.000000e+000,4,2,5.343094e-001,0,,0,
1717118905.344,,1.000000e+003,3.216374e+001,1.707112e-004,3.443982e-008,5.332183e-003,2.029219e-004,3,9.896165e-001,1.799000e+000,,,,,,,,,,,,,,,,,,0,4.000000e+000,1.000000e+000,4,2,5.458088e-001,0,,0,
1717118962.414,,1.000000e+003,3.025821e+001,1.709589e-004,1.977691e-008,5.635636e-003,1.384768e-004,3,9.896937e-001,1.799000e+000,,,,,,,,,,,,,,,,,,0,4.000000e+000,1.000000e+000,4,2,5.536003e-001,0,,0,
1717119017.964,,1.000000e+003,2.832018e+001,1.711943e-004,3.619937e-008,5.982994e-003,8.141915e-005,3,9.895977e-001,1.799000e+000,,,,,,,,,,,,,,,,,,0,4.000000e+000,1.000000e+000,4,2,5.771503e-001,0,,0,
1717119074.149,,1.000000e+003,2.638026e+001,1.714772e-004,1.244032e-008,6.280321e-003,1.516635e-004,3,9.896501e-001,1.799000e+000,,,,,,,,,,,,,,,,,,0,4.000000e+000,1.000000e+000,4,2,5.517101e-001,0,,0,
1717119129.319,,1.000000e+003,2.418142e+001,1.717787e-004,2.335775e-008,6.346591e-003,1.307764e-004,3,9.898688e-001,1.799000e+000,,,,,,,,,,,,,,,,,,0,4.000000e+000,1.000000e+000,4,2,1.116680e+000,0,,0,
1717119184.394,,1.000000e+003,2.277258e+001,1.719903e-004,8.478761e-009,6.540522e-003,1.696095e-004,3,9.897091e-001,1.799000e+000,,,,,,,,,,,,,,,,,,0,4.000000e+000,1.000000e+000,4,2,6.679001e-001,0,,0,
1717119240.899,,1.000000e+003,2.095131e+001,1.722581e-004,3.591140e-009,6.941644e-003,3.402502e-005,3,9.897776e-001,1.799000e+000,,,,,,,,,,,,,,,,,,0,4.000000e+000,1.000000e+000,4,2,5.410595e-001,0,,0,
1717119294.959,,1.000000e+003,1.919360e+001,1.724531e-004,1.891257e-008,7.320184e-003,4.600460e-005,3,9.896904e-001,1.799000e+000,,,,,,,,,,,,,,,,,,0,4.000000e+000,1.000000e+000,4,2,4.867496e-001,0,,0,
1717119350.264,,1.000000e+003,1.736994e+001,1.726479e-004,2.512759e-008,7.733396e-003,5.304049e-005,3,9.898670e-001,1.799000e+000,,,,,,,,,,,,,,,,,,0,4.000000e+000,1.000000e+000,4,2,4.437885e-001,0,,0,
1717119407.384,,1.000000e+003,1.550282e+001,1.727557e-004,4.578954e-009,8.360066e-003,1.421686e-004,3,9.897507e-001,1.799000e+000,,,,,,,,,,,,,,,,,,0,4.000000e+000,1.000000e+000,4,2,5.256100e-001,0,,0,
1717119461.879,,1.000000e+003,1.370684e+001,1.727722e-004,2.027108e-009,9.145310e-003,1.295825e-004,3,9.896455e-001,1.799000e+000,,,,,,,,,,,,,,,,,,0,4.000000e+000,1.000000e+000,4,2,6.042900e-001,0,,0,
1717119517.799,,1.000000e+003,1.192534e+001,1.726288e-004,4.105627e-009,1.012190e-002,8.068224e-005,3,9.897652e-001,1.799000e+000,,,,,,,,,,,,,,,,,,0,4.000000e+000,1.000000e+000,4,2,4.932404e-001,0,,0,
1717119574.144,,1.000000e+003,1.023015e+001,1.724114e-004,3.257737e-008,1.162793e-002,2.982219e-004,3,9.895084e-001,1.799000e+000,,,,,,,,,,,,,,,,,,0,4.000000e+000,1.000000e+000,4,2,4.998922e-001,0,,0,
1717120040.009,,1.000000e+003,1.000594e+001,1.724148e-004,1.328408e-008,1.159120e-002,6.477312e-005,3,9.896762e-001,1.799000e+000,,,,,,,,,,,,,,,,,,0,4.000000e+000,1.000000e+000,4,2,2.310753e-003,0,,0,
1717120092.884,,1.000000e+003,1.000253e+001,1.724178e-004,6.009218e-009,1.154734e-002,5.467961e-005,3,9.897337e-001,1.799000e+000,,,,,,,,,,,,,,,,,,0,4.000000e+000,1.000000e+000,4,2,4.205704e-004,0,,0,
1717120144.819,,1.000000e+003,1.000039e+001,1.724235e-004,6.719220e-009,1.165624e-002,1.254396e-004,3,9.896496e-001,1.799000e+000,,,,,,,,,,,,,,,,,,0,4.000000e+000,1.000000e+000,4,2,2.010345e-003,0,,0,
1717120197.219,,1.000000e+003,1.000142e+001,1.724038e-004,9.476873e-009,1.167301e-002,1.453981e-004,3,9.895968e-001,1.799000e+000,,,,,,,,,,,,,,,,,,0,4.000000e+000,1.000000e+000,4,2,4.205704e-004,0,,0,
1717120250.404,,1.000000e+003,1.000037e+001,1.724010e-004,4.620113e-009,1.157568e-002,7.955481e-005,3,9.895879e-001,1.799000e+000,,,,,,,,,,,,,,,,,,0,4.000000e+000,1.000000e+000,4,2,2.664566e-003,0,,0,
1717120303.344,,1.000000e+003,1.000105e+001,1.724163e-004,1.256380e-008,1.177542e-002,2.504043e-004,3,9.895568e-001,1.799000e+000,,,,,,,,,,,,,,,,,,0,4.000000e+000,1.000000e+000,4,2,6.303787e-004,0,,0,
1717120354.744,,1.000000e+003,1.000163e+001,1.724488e-004,2.088846e-009,1.172424e-002,2.317570e-004,3,9.895239e-001,1.799000e+000,,,,,,,,,,,,,,,,,,0,4.000000e+000,1.000000e+000,4,2,4.091263e-004,0,,0,
1717120407.369,,1.000000e+003,1.000041e+001,1.724101e-004,1.876852e-008,1.159829e-002,3.655383e-005,3,9.897361e-001,1.799000e+000,,,,,,,,,,,,,,,,,,0,4.000000e+000,1.000000e+000,4,2,1.729965e-003,0,,0,
1717120459.779,,1.000000e+003,1.000100e+001,1.724356e-004,1.602116e-008,1.160046e-002,4.095884e-005,3,9.897900e-001,1.799000e+000,,,,,,,,,,,,,,,,,,0,4.000000e+000,1.000000e+000,4,2,1.039505e-003,0,,0,
1717120512.244,,1.000000e+003,1.000146e+001,1.724307e-004,2.594048e-008,1.159981e-002,1.106473e-004,3,9.895275e-001,1.799000e+000,,,,,,,,,,,,,,,,,,0,4.000000e+000,1.000000e+000,4,2,2.098083e-004,0,,0,
1717120578.414,,1.000000e+003,1.000105e+001,1.723888e-004,1.205960e-008,1.168547e-002,1.183536e-004,3,9.896842e-001,1.799000e+000,,,,,,,,,,,,,,,,,,0,4.000000e+000,1.000000e+000,4,2,4.196167e-004,0,,0,
1717120631.559,,1.000000e+003,1.000026e+001,1.723918e-004,2.946987e-008,1.162855e-002,9.408691e-005,3,9.896634e-001,1.799000e+000,,,,,,,,,,,,,,,,,,0,4.000000e+000,1.000000e+000,4,2,2.420425e-003,0,,0,
1717120683.434,,1.000000e+003,1.000100e+001,1.724060e-004,4.719912e-008,1.151098e-002,7.818438e-005,3,9.895978e-001,1.799000e+000,,,,,,,,,,,,,,,,,,0,4.000000e+000,1.000000e+000,4,2,6.294250e-004,0,,0,
1717120758.659,,1.000000e+003,1.000163e+001,1.723976e-004,3.236129e-008,1.160097e-002,2.091735e-005,3,9.898659e-001,1.799000e+000,,,,,,,,,,,,,,,,,,0,4.000000e+000,1.000000e+000,4,2,8.306503e-004,0,,0,
1717120866.099,,1.000000e+003,1.000095e+001,1.724046e-004,2.863640e-008,1.155841e-002,9.297990e-005,3,9.896562e-001,1.799000e+000,,,,,,,,,,,,,,,,,,0,4.000000e+000,1.000000e+000,4,2,1.039505e-003,0,,0,
1717120956.664,,1.000000e+003,1.000044e+001,1.723824e-004,2.494237e-008,1.153795e-002,4.523476e-005,3,9.897600e-001,1.799000e+000,,,,,,,,,,,,,,,,,,0,4.000000e+000,1.000000e+000,4,2,2.630234e-003,0,,0,
1717121008.079,,1.000000e+003,1.000126e+001,1.723963e-004,8.818328e-009,1.148416e-002,2.813566e-005,3,9.896410e-001,1.799000e+000,,,,,,,,,,,,,,,,,,0,4.000000e+000,1.000000e+000,4,2,8.296967e-004,0,,0,
1717121059.564,,1.000000e+003,1.000089e+001,1.724365e-004,2.928465e-008,1.166610e-002,1.768310e-004,3,9.894617e-001,1.799000e+000,,,,,,,,,,,,,,,,,,0,4.000000e+000,1.000000e+000,4,2,1.039505e-003,0,,0,
1717121110.544,,1.000000e+003,1.000068e+001,1.723846e-004,9.672373e-010,1.155236e-002,1.910754e-004,3,9.897783e-001,1.799000e+000,,,,,,,,,,,,,,,,,,0,4.000000e+000,1.000000e+000,4,2,6.198883e-004,0,,0,
1717121161.479,,1.000000e+003,1.000037e+001,1.724011e-004,8.890351e-009,1.155175e-002,4.687520e-006,3,9.896901e-001,1.799000e+000,,,,,,,,,,,,,,,,,,0,4.000000e+000,1.000000e+000,4,2,8.306503e-004,0,,0,
1717121213.389,,1.000000e+003,1.000157e+001,1.724212e-004,5.535890e-009,1.156451e-002,5.081988e-006,3,9.898647e-001,1.799000e+000,,,,,,,,,,,,,,,,,,0,4.000000e+000,1.000000e+000,4,2,6.294250e-004,0,,0,
1717121265.329,,1.000000e+003,1.000115e+001,1.724251e-004,2.255515e-008,1.156886e-002,1.595456e-005,3,9.895509e-001,1.799000e+000,,,,,,,,,,,,,,,,,,0,4.000000e+000,1.000000e+000,4,2,1.249313e-003,0,,0,
1717121330.244,,1.000000e+003,1.000141e+001,1.724207e-004,1.075280e-008,1.155476e-002,7.519985e-005,3,9.896818e-001,1.799000e+000,,,,,,,,,,,,,,,,,,0,4.000000e+000,1.000000e+000,4,2,1.660347e-003,0,,0,
1717121411.239,,1.000000e+003,1.000121e+001,1.724142e-004,2.574497e-008,1.163934e-002,1.679288e-005,3,9.895165e-001,1.799000e+000,,,,,,,,,,,,,,,,,,0,4.000000e+000,1.000000e+000,4,2,6.198883e-004,0,,0,
1717121445.414,,1.000000e+003,1.000152e+001,1.724343e-004,2.490121e-009,1.154584e-002,1.340415e-004,3,9.896576e-001,1.799000e+000,,,,,,,,,,,,,,,,,,0,4.000000e+000,1.000000e+000,4,2,4.196167e-004,0,,0,