File: squid/SIO1/MdeT1000G.csv
Time,Comment,Field (Oe),Temperature (K),Long Moment (emu),Long Scan Std Dev,Long Offset (cm),Long Offset Std Dev,Long Algorithm,Long Reg Fit,Long Reg Factor,Trans Moment (emu),Trans Scan Std Dev,Trans Offset (cm),Trans Offset Std Dev,Trans Algorithm,Trans Reg Fit,Trans Reg Factor,Long Moment [w/o ABS] (emu),Long Scan Std Dev [w/o ABS],Long Offset [w/o ABS] (cm),Long Offset Std Dev [w/o ABS],Long Reg Fit [w/o ABS],Trans Moment [w/o ABS] (emu),Trans Scan Std Dev [w/o ABS],Trans Offset [w/o ABS] (cm),Trans Offset Std Dev [w/o ABS],Trans Reg Fit [w/o ABS],RSO Position (deg),Amplitude (cm),Frequency,Cycles to Average,Scans per Measurement,Delta Temp (K),Error,EC Comp. Running,Using ABS
1717111006,,1.00E+03,2.89E+02,-4.43E-05,1.48E-08,-1.01E-02,8.02E-05,3,9.81E-01,1.80E+00,,,,,,,,,,,,,,,,,,0,4.00E+00,1.00E+00,4,2,1.27E-01,0,,0
1717111043,,1.00E+03,2.88E+02,-4.43E-05,1.72E-08,-9.87E-03,8.86E-05,3,9.81E-01,1.80E+00,,,,,,,,,,,,,,,,,,0,4.00E+00,1.00E+00,4,2,7.16E-01,0,,0
1717111081,,1.00E+03,2.86E+02,-4.43E-05,2.87E-08,-1.00E-02,1.50E-04,3,9.81E-01,1.80E+00,,,,,,,,,,,,,,,,,,0,4.00E+00,1.00E+00,4,2,6.99E-01,0,,0
1717111116,,1.00E+03,2.85E+02,-4.43E-05,1.61E-08,-1.04E-02,1.65E-04,3,9.82E-01,1.80E+00,,,,,,,,,,,,,,,,,,0,4.00E+00,1.00E+00,4,2,5.30E-01,0,,0
1717111153,,1.00E+03,2.84E+02,-4.43E-05,2.18E-08,-1.08E-02,4.89E-06,3,9.81E-01,1.80E+00,,,,,,,,,,,,,,,,,,0,4.00E+00,1.00E+00,4,2,4.57E-01,0,,0
1717111190,,1.00E+03,2.83E+02,-4.43E-05,8.11E-09,-1.10E-02,3.27E-05,3,9.81E-01,1.80E+00,,,,,,,,,,,,,,,,,,0,4.00E+00,1.00E+00,4,2,4.46E-01,0,,0
1717111226,,1.00E+03,2.82E+02,-4.43E-05,1.11E-08,-1.14E-02,1.81E-04,3,9.81E-01,1.80E+00,,,,,,,,,,,,,,,,,,0,4.00E+00,1.00E+00,4,2,4.35E-01,0,,0
1717111263,,1.00E+03,2.81E+02,-4.43E-05,9.13E-09,-1.17E-02,4.04E-04,3,9.82E-01,1.80E+00,,,,,,,,,,,,,,,,,,0,4.00E+00,1.00E+00,4,2,4.84E-01,0,,0
1717111300,,1.00E+03,2.80E+02,-4.42E-05,1.32E-08,-1.17E-02,1.59E-04,3,9.82E-01,1.80E+00,,,,,,,,,,,,,,,,,,0,4.00E+00,1.00E+00,4,2,4.50E-01,0,,0
1717111336,,1.00E+03,2.79E+02,-4.42E-05,8.48E-09,-1.19E-02,2.89E-04,3,9.82E-01,1.80E+00,,,,,,,,,,,,,,,,,,0,4.00E+00,1.00E+00,4,2,4.90E-01,0,,0
1717111373,,1.00E+03,2.78E+02,-4.42E-05,2.73E-08,-1.22E-02,6.73E-05,3,9.81E-01,1.80E+00,,,,,,,,,,,,,,,,,,0,4.00E+00,1.00E+00,4,2,5.37E-01,0,,0
1717111411,,1.00E+03,2.76E+02,-4.42E-05,4.32E-08,-1.23E-02,1.67E-04,3,9.82E-01,1.80E+00,,,,,,,,,,,,,,,,,,0,4.00E+00,1.00E+00,4,2,5.10E-01,0,,0
1717111449,,1.00E+03,2.75E+02,-4.42E-05,1.11E-08,-1.24E-02,1.30E-04,3,9.82E-01,1.80E+00,,,,,,,,,,,,,,,,,,0,4.00E+00,1.00E+00,4,2,5.12E-01,0,,0
1717111485,,1.00E+03,2.74E+02,-4.41E-05,3.73E-09,-1.24E-02,6.00E-05,3,9.81E-01,1.80E+00,,,,,,,,,,,,,,,,,,0,4.00E+00,1.00E+00,4,2,5.08E-01,0,,0
1717111524,,1.00E+03,2.73E+02,-4.41E-05,1.56E-08,-1.28E-02,6.94E-05,3,9.81E-01,1.80E+00,,,,,,,,,,,,,,,,,,0,4.00E+00,1.00E+00,4,2,5.03E-01,0,,0
1717111560,,1.00E+03,2.72E+02,-4.41E-05,9.74E-09,-1.29E-02,2.57E-04,3,9.81E-01,1.80E+00,,,,,,,,,,,,,,,,,,0,4.00E+00,1.00E+00,4,2,4.57E-01,0,,0
1717111597,,1.00E+03,2.70E+02,-4.41E-05,2.67E-08,-1.31E-02,3.83E-05,3,9.82E-01,1.80E+00,,,,,,,,,,,,,,,,,,0,4.00E+00,1.00E+00,4,2,5.07E-01,0,,0
1717111633,,1.00E+03,2.69E+02,-4.41E-05,4.20E-09,-1.32E-02,1.46E-04,3,9.81E-01,1.80E+00,,,,,,,,,,,,,,,,,,0,4.00E+00,1.00E+00,4,2,4.96E-01,0,,0
1717111670,,1.00E+03,2.68E+02,-4.40E-05,1.31E-08,-1.34E-02,1.15E-05,3,9.81E-01,1.80E+00,,,,,,,,,,,,,,,,,,0,4.00E+00,1.00E+00,4,2,5.05E-01,0,,0
1717111705,,1.00E+03,2.67E+02,-4.40E-05,2.41E-08,-1.35E-02,6.65E-05,3,9.82E-01,1.80E+00,,,,,,,,,,,,,,,,,,0,4.00E+00,1.00E+00,4,2,5.27E-01,0,,0
1717111743,,1.00E+03,2.66E+02,-4.40E-05,1.48E-08,-1.34E-02,2.69E-04,3,9.82E-01,1.80E+00,,,,,,,,,,,,,,,,,,0,4.00E+00,1.00E+00,4,2,5.09E-01,0,,0
1717111779,,1.00E+03,2.65E+02,-4.40E-05,2.11E-08,-1.36E-02,6.14E-05,3,9.81E-01,1.80E+00,,,,,,,,,,,,,,,,,,0,4.00E+00,1.00E+00,4,2,5.04E-01,0,,0
1717111816,,1.00E+03,2.64E+02,-4.39E-05,1.37E-08,-1.38E-02,1.46E-04,3,9.81E-01,1.80E+00,,,,,,,,,,,,,,,,,,0,4.00E+00,1.00E+00,4,2,5.51E-01,0,,0
1717111852,,1.00E+03,2.63E+02,-4.39E-05,1.80E-08,-1.38E-02,3.37E-04,3,9.81E-01,1.80E+00,,,,,,,,,,,,,,,,,,0,4.00E+00,1.00E+00,4,2,5.14E-01,0,,0
1717111889,,1.00E+03,2.61E+02,-4.39E-05,2.57E-08,-1.39E-02,4.85E-05,3,9.81E-01,1.80E+00,,,,,,,,,,,,,,,,,,0,4.00E+00,1.00E+00,4,2,5.15E-01,0,,0
1717111924,,1.00E+03,2.60E+02,-4.38E-05,2.32E-08,-1.37E-02,4.51E-04,3,9.81E-01,1.80E+00,,,,,,,,,,,,,,,,,,0,4.00E+00,1.00E+00,4,2,5.36E-01,0,,0
1717111962,,1.00E+03,2.59E+02,-4.38E-05,1.28E-08,-1.39E-02,6.12E-05,3,9.81E-01,1.80E+00,,,,,,,,,,,,,,,,,,0,4.00E+00,1.00E+00,4,2,4.87E-01,0,,0
1717111998,,1.00E+03,2.58E+02,-4.38E-05,2.52E-08,-1.40E-02,1.38E-06,3,9.81E-01,1.80E+00,,,,,,,,,,,,,,,,,,0,4.00E+00,1.00E+00,4,2,5.19E-01,0,,0
1717112035,,1.00E+03,2.57E+02,-4.37E-05,1.08E-08,-1.39E-02,2.00E-04,3,9.81E-01,1.80E+00,,,,,,,,,,,,,,,,,,0,4.00E+00,1.00E+00,4,2,5.14E-01,0,,0
1717112072,,1.00E+03,2.55E+02,-4.37E-05,1.17E-08,-1.40E-02,1.31E-04,3,9.81E-01,1.80E+00,,,,,,,,,,,,,,,,,,0,4.00E+00,1.00E+00,4,2,5.15E-01,0,,0
1717112109,,1.00E+03,2.54E+02,-4.36E-05,2.76E-08,-1.40E-02,1.92E-05,3,9.81E-01,1.80E+00,,,,,,,,,,,,,,,,,,0,4.00E+00,1.00E+00,4,2,5.16E-01,0,,0
1717112147,,1.00E+03,2.53E+02,-4.36E-05,8.39E-10,-1.38E-02,1.57E-05,3,9.81E-01,1.80E+00,,,,,,,,,,,,,,,,,,0,4.00E+00,1.00E+00,4,2,5.17E-01,0,,0
1717112183,,1.00E+03,2.52E+02,-4.35E-05,1.07E-08,-1.37E-02,5.42E-06,3,9.81E-01,1.80E+00,,,,,,,,,,,,,,,,,,0,4.00E+00,1.00E+00,4,2,4.89E-01,0,,0
1717112220,,1.00E+03,2.51E+02,-4.34E-05,1.31E-08,-1.36E-02,8.36E-06,3,9.81E-01,1.80E+00,,,,,,,,,,,,,,,,,,0,4.00E+00,1.00E+00,4,2,5.25E-01,0,,0
1717112257,,1.00E+03,2.50E+02,-4.34E-05,2.87E-08,-1.35E-02,2.55E-04,3,9.81E-01,1.80E+00,,,,,,,,,,,,,,,,,,0,4.00E+00,1.00E+00,4,2,5.54E-01,0,,0
1717112293,,1.00E+03,2.48E+02,-4.33E-05,2.49E-08,-1.34E-02,3.51E-04,3,9.81E-01,1.80E+00,,,,,,,,,,,,,,,,,,0,4.00E+00,1.00E+00,4,2,5.43E-01,0,,0
1717112330,,1.00E+03,2.47E+02,-4.32E-05,2.72E-08,-1.35E-02,3.00E-05,3,9.81E-01,1.80E+00,,,,,,,,,,,,,,,,,,0,4.00E+00,1.00E+00,4,2,5.26E-01,0,,0
1717112367,,1.00E+03,2.46E+02,-4.31E-05,2.50E-08,-1.33E-02,7.97E-05,3,9.81E-01,1.80E+00,,,,,,,,,,,,,,,,,,0,4.00E+00,1.00E+00,4,2,5.21E-01,0,,0
1717112405,,1.00E+03,2.45E+02,-4.30E-05,2.69E-08,-1.31E-02,1.65E-04,3,9.81E-01,1.80E+00,,,,,,,,,,,,,,,,,,0,4.00E+00,1.00E+00,4,2,4.93E-01,0,,0
1717112441,,1.00E+03,2.44E+02,-4.29E-05,2.27E-08,-1.31E-02,1.65E-04,3,9.81E-01,1.80E+00,,,,,,,,,,,,,,,,,,0,4.00E+00,1.00E+00,4,2,5.55E-01,0,,0
1717112478,,1.00E+03,2.43E+02,-4.28E-05,2.86E-08,-1.31E-02,9.77E-05,3,9.80E-01,1.80E+00,,,,,,,,,,,,,,,,,,0,4.00E+00,1.00E+00,4,2,5.27E-01,0,,0
1717112514,,1.00E+03,2.42E+02,-4.27E-05,2.56E-08,-1.28E-02,2.28E-04,3,9.81E-01,1.80E+00,,,,,,,,,,,,,,,,,,0,4.00E+00,1.00E+00,4,2,5.33E-01,0,,0
1717112551,,1.00E+03,2.40E+02,-4.25E-05,5.09E-08,-1.27E-02,2.20E-04,3,9.81E-01,1.80E+00,,,,,,,,,,,,,,,,,,0,4.00E+00,1.00E+00,4,2,5.33E-01,0,,0
1717112588,,1.00E+03,2.39E+02,-4.24E-05,1.10E-08,-1.28E-02,2.32E-05,3,9.81E-01,1.80E+00,,,,,,,,,,,,,,,,,,0,4.00E+00,1.00E+00,4,2,5.32E-01,0,,0
1717112625,,1.00E+03,2.38E+02,-4.22E-05,3.96E-08,-1.24E-02,4.36E-04,3,9.81E-01,1.80E+00,,,,,,,,,,,,,,,,,,0,4.00E+00,1.00E+00,4,2,5.00E-01,0,,0
1717112661,,1.00E+03,2.37E+02,-4.20E-05,3.90E-08,-1.24E-02,9.16E-05,3,9.81E-01,1.80E+00,,,,,,,,,,,,,,,,,,0,4.00E+00,1.00E+00,4,2,5.42E-01,0,,0
1717112698,,1.00E+03,2.36E+02,-4.17E-05,2.29E-08,-1.21E-02,1.74E-04,3,9.81E-01,1.80E+00,,,,,,,,,,,,,,,,,,0,4.00E+00,1.00E+00,4,2,5.51E-01,0,,0
1717112734,,1.00E+03,2.34E+02,-4.14E-05,2.81E-08,-1.17E-02,6.92E-05,3,9.81E-01,1.80E+00,,,,,,,,,,,,,,,,,,0,4.00E+00,1.00E+00,4,2,5.10E-01,0,,0
1717112771,,1.00E+03,2.33E+02,-4.11E-05,9.50E-08,-1.17E-02,2.21E-04,3,9.81E-01,1.80E+00,,,,,,,,,,,,,,,,,,0,4.00E+00,1.00E+00,4,2,5.16E-01,0,,0
1717112808,,1.00E+03,2.32E+02,-4.07E-05,7.56E-08,-1.15E-02,2.12E-04,3,9.81E-01,1.80E+00,,,,,,,,,,,,,,,,,,0,4.00E+00,1.00E+00,4,2,4.99E-01,0,,0
1717112846,,1.00E+03,2.31E+02,-4.03E-05,9.65E-08,-1.13E-02,2.98E-04,3,9.80E-01,1.80E+00,,,,,,,,,,,,,,,,,,0,4.00E+00,1.00E+00,4,2,5.08E-01,0,,0
1717112882,,1.00E+03,2.30E+02,-3.97E-05,1.14E-07,-1.10E-02,1.35E-04,3,9.80E-01,1.80E+00,,,,,,,,,,,,,,,,,,0,4.00E+00,1.00E+00,4,2,5.17E-01,0,,0
1717112920,,1.00E+03,2.28E+02,-3.90E-05,1.36E-07,-1.08E-02,4.45E-06,3,9.80E-01,1.80E+00,,,,,,,,,,,,,,,,,,0,4.00E+00,1.00E+00,4,2,5.21E-01,0,,0
1717112956,,1.00E+03,2.27E+02,-3.82E-05,1.23E-07,-1.01E-02,4.13E-05,3,9.79E-01,1.80E+00,,,,,,,,,,,,,,,,,,0,4.00E+00,1.00E+00,4,2,5.11E-01,0,,0
1717112994,,1.00E+03,2.26E+02,-3.72E-05,1.84E-07,-9.69E-03,2.28E-04,3,9.79E-01,1.80E+00,,,,,,,,,,,,,,,,,,0,4.00E+00,1.00E+00,4,2,5.05E-01,0,,0
1717113029,,1.00E+03,2.25E+02,-3.60E-05,2.17E-07,-8.84E-03,5.26E-04,3,9.79E-01,1.80E+00,,,,,,,,,,,,,,,,,,0,4.00E+00,1.00E+00,4,2,5.46E-01,0,,0
1717113066,,1.00E+03,2.24E+02,-3.44E-05,3.11E-07,-7.96E-03,4.63E-04,3,9.77E-01,1.80E+00,,,,,,,,,,,,,,,,,,0,4.00E+00,1.00E+00,4,2,5.58E-01,0,,0
1717113103,,1.00E+03,2.22E+02,-3.23E-05,4.19E-07,-6.51E-03,8.77E-05,3,9.76E-01,1.80E+00,,,,,,,,,,,,,,,,,,0,4.00E+00,1.00E+00,4,2,5.56E-01,0,,0
1717113139,,1.00E+03,2.21E+02,-2.95E-05,4.98E-07,-4.66E-03,2.97E-05,3,9.75E-01,1.80E+00,,,,,,,,,,,,,,,,,,0,4.00E+00,1.00E+00,4,2,4.74E-01,0,,0
1717113176,,1.00E+03,2.20E+02,-2.59E-05,6.86E-07,-1.60E-03,7.26E-04,3,9.71E-01,1.80E+00,,,,,,,,,,,,,,,,,,0,4.00E+00,1.00E+00,4,2,5.35E-01,0,,0
1717113214,,1.00E+03,2.19E+02,-2.12E-05,8.07E-07,3.80E-03,1.54E-03,3,9.67E-01,1.80E+00,,,,,,,,,,,,,,,,,,0,4.00E+00,1.00E+00,4,2,5.29E-01,0,,0
1717113276,,1.00E+03,2.17E+02,-1.15E-05,8.74E-07,3.06E-02,5.14E-03,3,9.41E-01,1.80E+00,,,,,,,,,,,,,,,,,,0,4.00E+00,1.00E+00,4,2,5.23E-01,0,,0
1717113313,,1.00E+03,2.16E+02,-5.19E-06,1.13E-06,1.14E-01,3.27E-02,3,8.73E-01,1.80E+00,,,,,,,,,,,,,,,,,,0,4.00E+00,1.00E+00,4,2,4.75E-01,0,,0
1717113348,,1.00E+03,2.14E+02,2.55E-06,1.20E-06,-2.95E-01,1.37E-01,3,6.55E-01,1.80E+00,,,,,,,,,,,,,,,,,,0,4.00E+00,1.00E+00,4,2,5.24E-01,0,,0
1717113387,,1.00E+03,2.13E+02,1.16E-05,1.57E-06,-8.03E-02,7.77E-03,3,9.36E-01,1.80E+00,,,,,,,,,,,,,,,,,,0,4.00E+00,1.00E+00,4,2,4.84E-01,0,,0
1717113424,,1.00E+03,2.12E+02,2.18E-05,1.73E-06,-5.67E-02,1.65E-03,3,9.65E-01,1.80E+00,,,,,,,,,,,,,,,,,,0,4.00E+00,1.00E+00,4,2,5.24E-01,0,,0
1717113461,,1.00E+03,2.11E+02,3.38E-05,1.92E-06,-4.71E-02,1.04E-03,3,9.77E-01,1.80E+00,,,,,,,,,,,,,,,,,,0,4.00E+00,1.00E+00,4,2,5.05E-01,0,,0
1717113497,,1.00E+03,2.10E+02,4.62E-05,2.05E-06,-4.27E-02,3.14E-04,3,9.82E-01,1.80E+00,,,,,,,,,,,,,,,,,,0,4.00E+00,1.00E+00,4,2,5.24E-01,0,,0
1717113535,,1.00E+03,2.08E+02,5.94E-05,2.06E-06,-3.98E-02,3.66E-04,3,9.85E-01,1.80E+00,,,,,,,,,,,,,,,,,,0,4.00E+00,1.00E+00,4,2,5.53E-01,0,,0
1717113571,,1.00E+03,2.07E+02,7.20E-05,2.06E-06,-3.79E-02,2.86E-04,3,9.86E-01,1.80E+00,,,,,,,,,,,,,,,,,,0,4.00E+00,1.00E+00,4,2,5.19E-01,0,,0
1717113609,,1.00E+03,2.06E+02,8.44E-05,1.89E-06,-3.67E-02,1.77E-05,3,9.87E-01,1.80E+00,,,,,,,,,,,,,,,,,,0,4.00E+00,1.00E+00,4,2,5.04E-01,0,,0
1717113646,,1.00E+03,2.05E+02,9.56E-05,1.74E-06,-3.60E-02,5.07E-05,3,9.88E-01,1.80E+00,,,,,,,,,,,,,,,,,,0,4.00E+00,1.00E+00,4,2,4.69E-01,0,,0
1717113683,,1.00E+03,2.04E+02,1.06E-04,1.53E-06,-3.53E-02,5.74E-05,3,9.88E-01,1.80E+00,,,,,,,,,,,,,,,,,,0,4.00E+00,1.00E+00,4,2,5.16E-01,0,,0
1717113719,,1.00E+03,2.03E+02,1.15E-04,1.36E-06,-3.46E-02,1.48E-04,3,9.89E-01,1.80E+00,,,,,,,,,,,,,,,,,,0,4.00E+00,1.00E+00,4,2,4.73E-01,0,,0
1717113757,,1.00E+03,2.01E+02,1.23E-04,1.29E-06,-3.42E-02,1.04E-04,3,9.89E-01,1.80E+00,,,,,,,,,,,,,,,,,,0,4.00E+00,1.00E+00,4,2,5.15E-01,0,,0
1717113792,,1.00E+03,2.00E+02,1.30E-04,1.07E-06,-3.39E-02,9.49E-06,3,9.89E-01,1.80E+00,,,,,,,,,,,,,,,,,,0,4.00E+00,1.00E+00,4,2,5.13E-01,0,,0
1717113828,,1.00E+03,1.99E+02,1.37E-04,9.87E-07,-3.34E-02,1.39E-04,3,9.89E-01,1.80E+00,,,,,,,,,,,,,,,,,,0,4.00E+00,1.00E+00,4,2,5.29E-01,0,,0
1717113865,,1.00E+03,1.98E+02,1.43E-04,9.30E-07,-3.31E-02,5.37E-05,3,9.89E-01,1.80E+00,,,,,,,,,,,,,,,,,,0,4.00E+00,1.00E+00,4,2,4.91E-01,0,,0
1717113902,,1.00E+03,1.97E+02,1.48E-04,8.09E-07,-3.27E-02,8.57E-05,3,9.89E-01,1.80E+00,,,,,,,,,,,,,,,,,,0,4.00E+00,1.00E+00,4,2,4.99E-01,0,,0
1717113939,,1.00E+03,1.96E+02,1.53E-04,7.45E-07,-3.25E-02,6.64E-05,3,9.89E-01,1.80E+00,,,,,,,,,,,,,,,,,,0,4.00E+00,1.00E+00,4,2,5.48E-01,0,,0
1717113976,,1.00E+03,1.94E+02,1.58E-04,7.12E-07,-3.21E-02,7.58E-05,3,9.89E-01,1.80E+00,,,,,,,,,,,,,,,,,,0,4.00E+00,1.00E+00,4,2,5.04E-01,0,,0
1717114012,,1.00E+03,1.93E+02,1.62E-04,6.93E-07,-3.18E-02,2.34E-05,3,9.89E-01,1.80E+00,,,,,,,,,,,,,,,,,,0,4.00E+00,1.00E+00,4,2,5.38E-01,0,,0
1717114049,,1.00E+03,1.92E+02,1.66E-04,6.00E-07,-3.15E-02,1.92E-05,3,9.90E-01,1.80E+00,,,,,,,,,,,,,,,,,,0,4.00E+00,1.00E+00,4,2,5.41E-01,0,,0
1717114086,,1.00E+03,1.91E+02,1.70E-04,5.05E-07,-3.10E-02,3.74E-05,3,9.89E-01,1.80E+00,,,,,,,,,,,,,,,,,,0,4.00E+00,1.00E+00,4,2,5.64E-01,0,,0
1717114122,,1.00E+03,1.90E+02,1.73E-04,5.10E-07,-3.09E-02,5.43E-06,3,9.90E-01,1.80E+00,,,,,,,,,,,,,,,,,,0,4.00E+00,1.00E+00,4,2,5.38E-01,0,,0
1717114159,,1.00E+03,1.89E+02,1.76E-04,4.41E-07,-3.05E-02,6.26E-05,3,9.90E-01,1.80E+00,,,,,,,,,,,,,,,,,,0,4.00E+00,1.00E+00,4,2,4.89E-01,0,,0
1717114196,,1.00E+03,1.87E+02,1.79E-04,3.96E-07,-3.02E-02,6.55E-05,3,9.89E-01,1.80E+00,,,,,,,,,,,,,,,,,,0,4.00E+00,1.00E+00,4,2,4.96E-01,0,,0
1717114233,,1.00E+03,1.86E+02,1.81E-04,3.60E-07,-2.98E-02,3.85E-05,3,9.89E-01,1.80E+00,,,,,,,,,,,,,,,,,,0,4.00E+00,1.00E+00,4,2,5.30E-01,0,,0
1717114272,,1.00E+03,1.85E+02,1.83E-04,2.98E-07,-2.94E-02,2.52E-04,3,9.89E-01,1.80E+00,,,,,,,,,,,,,,,,,,0,4.00E+00,1.00E+00,4,2,5.45E-01,0,,0
1717114309,,1.00E+03,1.84E+02,1.85E-04,2.66E-07,-2.91E-02,1.39E-05,3,9.90E-01,1.80E+00,,,,,,,,,,,,,,,,,,0,4.00E+00,1.00E+00,4,2,5.01E-01,0,,0
1717114347,,1.00E+03,1.83E+02,1.87E-04,2.55E-07,-2.87E-02,6.56E-05,3,9.90E-01,1.80E+00,,,,,,,,,,,,,,,,,,0,4.00E+00,1.00E+00,4,2,4.89E-01,0,,0
1717114383,,1.00E+03,1.82E+02,1.88E-04,2.15E-07,-2.85E-02,7.37E-05,3,9.90E-01,1.80E+00,,,,,,,,,,,,,,,,,,0,4.00E+00,1.00E+00,4,2,5.09E-01,0,,0
1717114420,,1.00E+03,1.80E+02,1.89E-04,1.21E-07,-2.81E-02,6.84E-05,3,9.90E-01,1.80E+00,,,,,,,,,,,,,,,,,,0,4.00E+00,1.00E+00,4,2,5.14E-01,0,,0
1717114458,,1.00E+03,1.79E+02,1.90E-04,1.58E-07,-2.77E-02,9.71E-05,3,9.90E-01,1.80E+00,,,,,,,,,,,,,,,,,,0,4.00E+00,1.00E+00,4,2,5.48E-01,0,,0
1717114494,,1.00E+03,1.78E+02,1.91E-04,1.30E-07,-2.74E-02,3.53E-05,3,9.89E-01,1.80E+00,,,,,,,,,,,,,,,,,,0,4.00E+00,1.00E+00,4,2,5.12E-01,0,,0
1717114533,,1.00E+03,1.77E+02,1.92E-04,1.14E-07,-2.70E-02,2.37E-04,3,9.90E-01,1.80E+00,,,,,,,,,,,,,,,,,,0,4.00E+00,1.00E+00,4,2,5.70E-01,0,,0
1717114571,,1.00E+03,1.76E+02,1.93E-04,8.20E-08,-2.67E-02,1.11E-05,3,9.89E-01,1.80E+00,,,,,,,,,,,,,,,,,,0,4.00E+00,1.00E+00,4,2,5.67E-01,0,,0
1717114608,,1.00E+03,1.74E+02,1.93E-04,6.81E-08,-2.64E-02,6.73E-05,3,9.90E-01,1.80E+00,,,,,,,,,,,,,,,,,,0,4.00E+00,1.00E+00,4,2,5.05E-01,0,,0
1717114646,,1.00E+03,1.73E+02,1.93E-04,6.30E-08,-2.61E-02,5.23E-07,3,9.89E-01,1.80E+00,,,,,,,,,,,,,,,,,,0,4.00E+00,1.00E+00,4,2,4.87E-01,0,,0
1717114683,,1.00E+03,1.72E+02,1.94E-04,2.46E-08,-2.57E-02,3.99E-05,3,9.90E-01,1.80E+00,,,,,,,,,,,,,,,,,,0,4.00E+00,1.00E+00,4,2,5.28E-01,0,,0
1717114721,,1.00E+03,1.71E+02,1.94E-04,4.10E-08,-2.55E-02,3.08E-05,3,9.90E-01,1.80E+00,,,,,,,,,,,,,,,,,,0,4.00E+00,1.00E+00,4,2,4.89E-01,0,,0
1717114757,,1.00E+03,1.70E+02,1.94E-04,9.21E-09,-2.52E-02,2.37E-04,3,9.89E-01,1.80E+00,,,,,,,,,,,,,,,,,,0,4.00E+00,1.00E+00,4,2,5.03E-01,0,,0
1717114794,,1.00E+03,1.68E+02,1.94E-04,2.13E-08,-2.49E-02,7.79E-05,3,9.90E-01,1.80E+00,,,,,,,,,,,,,,,,,,0,4.00E+00,1.00E+00,4,2,4.81E-01,0,,0
1717114830,,1.00E+03,1.67E+02,1.94E-04,9.26E-10,-2.47E-02,2.82E-05,3,9.90E-01,1.80E+00,,,,,,,,,,,,,,,,,,0,4.00E+00,1.00E+00,4,2,5.40E-01,0,,0
1717114868,,1.00E+03,1.66E+02,1.94E-04,1.37E-09,-2.44E-02,9.89E-06,3,9.89E-01,1.80E+00,,,,,,,,,,,,,,,,,,0,4.00E+00,1.00E+00,4,2,5.07E-01,0,,0
1717114904,,1.00E+03,1.65E+02,1.94E-04,3.33E-08,-2.40E-02,8.71E-05,3,9.90E-01,1.80E+00,,,,,,,,,,,,,,,,,,0,4.00E+00,1.00E+00,4,2,5.39E-01,0,,0
1717114942,,1.00E+03,1.64E+02,1.94E-04,5.89E-08,-2.38E-02,7.47E-05,3,9.90E-01,1.80E+00,,,,,,,,,,,,,,,,,,0,4.00E+00,1.00E+00,4,2,5.07E-01,0,,0
1717114976,,1.00E+03,1.63E+02,1.94E-04,4.60E-08,-2.35E-02,5.65E-05,3,9.90E-01,1.80E+00,,,,,,,,,,,,,,,,,,0,4.00E+00,1.00E+00,4,2,5.14E-01,0,,0
1717115014,,1.00E+03,1.61E+02,1.93E-04,2.68E-08,-2.31E-02,2.36E-04,3,9.89E-01,1.80E+00,,,,,,,,,,,,,,,,,,0,4.00E+00,1.00E+00,4,2,5.07E-01,0,,0
1717115050,,1.00E+03,1.60E+02,1.93E-04,5.78E-08,-2.29E-02,1.12E-04,3,9.90E-01,1.80E+00,,,,,,,,,,,,,,,,,,0,4.00E+00,1.00E+00,4,2,5.51E-01,0,,0
1717115095,,1.00E+03,1.59E+02,1.93E-04,3.23E-08,-2.24E-02,6.55E-05,3,9.90E-01,1.80E+00,,,,,,,,,,,,,,,,,,0,4.00E+00,1.00E+00,4,2,5.09E-01,0,,0
1717115132,,1.00E+03,1.58E+02,1.92E-04,8.30E-08,-2.22E-02,4.52E-05,3,9.90E-01,1.80E+00,,,,,,,,,,,,,,,,,,0,4.00E+00,1.00E+00,4,2,4.70E-01,0,,0
1717115168,,1.00E+03,1.56E+02,1.92E-04,7.07E-08,-2.20E-02,1.35E-05,3,9.90E-01,1.80E+00,,,,,,,,,,,,,,,,,,0,4.00E+00,1.00E+00,4,2,5.07E-01,0,,0
1717115206,,1.00E+03,1.55E+02,1.91E-04,8.52E-08,-2.15E-02,1.83E-04,3,9.89E-01,1.80E+00,,,,,,,,,,,,,,,,,,0,4.00E+00,1.00E+00,4,2,5.08E-01,0,,0
1717115242,,1.00E+03,1.54E+02,1.91E-04,7.06E-08,-2.13E-02,6.46E-06,3,9.89E-01,1.80E+00,,,,,,,,,,,,,,,,,,0,4.00E+00,1.00E+00,4,2,5.43E-01,0,,0
1717115279,,1.00E+03,1.53E+02,1.90E-04,6.58E-08,-2.09E-02,2.00E-04,3,9.89E-01,1.80E+00,,,,,,,,,,,,,,,,,,0,4.00E+00,1.00E+00,4,2,5.01E-01,0,,0
1717115315,,1.00E+03,1.52E+02,1.90E-04,8.97E-08,-2.07E-02,8.85E-07,3,9.90E-01,1.80E+00,,,,,,,,,,,,,,,,,,0,4.00E+00,1.00E+00,4,2,5.19E-01,0,,0
1717115352,,1.00E+03,1.51E+02,1.89E-04,1.05E-07,-2.04E-02,1.55E-04,3,9.90E-01,1.80E+00,,,,,,,,,,,,,,,,,,0,4.00E+00,1.00E+00,4,2,4.74E-01,0,,0
1717115389,,1.00E+03,1.49E+02,1.89E-04,1.03E-07,-2.01E-02,7.04E-05,3,9.89E-01,1.80E+00,,,,,,,,,,,,,,,,,,0,4.00E+00,1.00E+00,4,2,5.23E-01,0,,0
1717115426,,1.00E+03,1.48E+02,1.88E-04,1.02E-07,-1.98E-02,6.96E-05,3,9.89E-01,1.80E+00,,,,,,,,,,,,,,,,,,0,4.00E+00,1.00E+00,4,2,5.19E-01,0,,0
1717115462,,1.00E+03,1.47E+02,1.88E-04,1.02E-07,-1.95E-02,1.22E-04,3,9.89E-01,1.80E+00,,,,,,,,,,,,,,,,,,0,4.00E+00,1.00E+00,4,2,5.23E-01,0,,0
1717115499,,1.00E+03,1.46E+02,1.87E-04,8.64E-08,-1.91E-02,1.90E-04,3,9.89E-01,1.80E+00,,,,,,,,,,,,,,,,,,0,4.00E+00,1.00E+00,4,2,5.29E-01,0,,0
1717115535,,1.00E+03,1.45E+02,1.86E-04,1.01E-07,-1.90E-02,3.95E-05,3,9.90E-01,1.80E+00,,,,,,,,,,,,,,,,,,0,4.00E+00,1.00E+00,4,2,5.02E-01,0,,0
1717115574,,1.00E+03,1.43E+02,1.86E-04,1.25E-07,-1.86E-02,7.69E-05,3,9.90E-01,1.80E+00,,,,,,,,,,,,,,,,,,0,4.00E+00,1.00E+00,4,2,5.39E-01,0,,0
1717115610,,1.00E+03,1.42E+02,1.85E-04,1.17E-07,-1.84E-02,4.23E-06,3,9.90E-01,1.80E+00,,,,,,,,,,,,,,,,,,0,4.00E+00,1.00E+00,4,2,5.04E-01,0,,0
1717115648,,1.00E+03,1.41E+02,1.84E-04,1.10E-07,-1.80E-02,8.65E-05,3,9.90E-01,1.80E+00,,,,,,,,,,,,,,,,,,0,4.00E+00,1.00E+00,4,2,4.99E-01,0,,0
1717115684,,1.00E+03,1.40E+02,1.84E-04,1.14E-07,-1.77E-02,1.21E-04,3,9.90E-01,1.80E+00,,,,,,,,,,,,,,,,,,0,4.00E+00,1.00E+00,4,2,5.05E-01,0,,0
1717115722,,1.00E+03,1.39E+02,1.83E-04,1.37E-07,-1.75E-02,1.47E-05,3,9.90E-01,1.80E+00,,,,,,,,,,,,,,,,,,0,4.00E+00,1.00E+00,4,2,4.99E-01,0,,0
1717115760,,1.00E+03,1.37E+02,1.82E-04,1.13E-07,-1.71E-02,2.72E-06,3,9.90E-01,1.80E+00,,,,,,,,,,,,,,,,,,0,4.00E+00,1.00E+00,4,2,5.32E-01,0,,0
1717115798,,1.00E+03,1.36E+02,1.81E-04,1.09E-07,-1.67E-02,5.97E-05,3,9.90E-01,1.80E+00,,,,,,,,,,,,,,,,,,0,4.00E+00,1.00E+00,4,2,5.39E-01,0,,0
1717115834,,1.00E+03,1.35E+02,1.80E-04,1.30E-07,-1.65E-02,6.67E-05,3,9.90E-01,1.80E+00,,,,,,,,,,,,,,,,,,0,4.00E+00,1.00E+00,4,2,5.40E-01,0,,0
1717115870,,1.00E+03,1.34E+02,1.80E-04,1.15E-07,-1.62E-02,1.92E-05,3,9.90E-01,1.80E+00,,,,,,,,,,,,,,,,,,0,4.00E+00,1.00E+00,4,2,5.14E-01,0,,0
1717115907,,1.00E+03,1.33E+02,1.79E-04,1.18E-07,-1.59E-02,1.38E-04,3,9.90E-01,1.80E+00,,,,,,,,,,,,,,,,,,0,4.00E+00,1.00E+00,4,2,5.43E-01,0,,0
1717115945,,1.00E+03,1.31E+02,1.78E-04,1.35E-07,-1.55E-02,4.49E-05,3,9.89E-01,1.80E+00,,,,,,,,,,,,,,,,,,0,4.00E+00,1.00E+00,4,2,5.21E-01,0,,0
1717115982,,1.00E+03,1.30E+02,1.77E-04,1.24E-07,-1.51E-02,1.33E-04,3,9.89E-01,1.80E+00,,,,,,,,,,,,,,,,,,0,4.00E+00,1.00E+00,4,2,5.27E-01,0,,0
1717116018,,1.00E+03,1.29E+02,1.77E-04,1.27E-07,-1.49E-02,7.78E-05,3,9.90E-01,1.80E+00,,,,,,,,,,,,,,,,,,0,4.00E+00,1.00E+00,4,2,5.18E-01,0,,0
1717116055,,1.00E+03,1.28E+02,1.76E-04,1.26E-07,-1.46E-02,1.90E-04,3,9.90E-01,1.80E+00,,,,,,,,,,,,,,,,,,0,4.00E+00,1.00E+00,4,2,5.67E-01,0,,0
1717116094,,1.00E+03,1.27E+02,1.75E-04,8.74E-08,-1.42E-02,1.12E-04,3,9.89E-01,1.80E+00,,,,,,,,,,,,,,,,,,0,4.00E+00,1.00E+00,4,2,4.81E-01,0,,0
1717116129,,1.00E+03,1.25E+02,1.75E-04,8.77E-08,-1.40E-02,4.13E-05,3,9.90E-01,1.80E+00,,,,,,,,,,,,,,,,,,0,4.00E+00,1.00E+00,4,2,5.12E-01,0,,0
1717116167,,1.00E+03,1.24E+02,1.74E-04,5.81E-08,-1.36E-02,7.06E-05,3,9.90E-01,1.80E+00,,,,,,,,,,,,,,,,,,0,4.00E+00,1.00E+00,4,2,4.89E-01,0,,0
1717116203,,1.00E+03,1.23E+02,1.74E-04,5.91E-08,-1.33E-02,3.16E-06,3,9.89E-01,1.80E+00,,,,,,,,,,,,,,,,,,0,4.00E+00,1.00E+00,4,2,5.27E-01,0,,0
1717116241,,1.00E+03,1.22E+02,1.74E-04,3.21E-08,-1.30E-02,1.96E-04,3,9.89E-01,1.80E+00,,,,,,,,,,,,,,,,,,0,4.00E+00,1.00E+00,4,2,5.38E-01,0,,0
1717116278,,1.00E+03,1.21E+02,1.74E-04,4.07E-09,-1.26E-02,7.88E-05,3,9.89E-01,1.80E+00,,,,,,,,,,,,,,,,,,0,4.00E+00,1.00E+00,4,2,5.39E-01,0,,0
1717116315,,1.00E+03,1.19E+02,1.74E-04,2.27E-08,-1.22E-02,7.30E-05,3,9.90E-01,1.80E+00,,,,,,,,,,,,,,,,,,0,4.00E+00,1.00E+00,4,2,4.94E-01,0,,0
1717116353,,1.00E+03,1.18E+02,1.74E-04,3.34E-08,-1.18E-02,1.65E-04,3,9.89E-01,1.80E+00,,,,,,,,,,,,,,,,,,0,4.00E+00,1.00E+00,4,2,5.33E-01,0,,0
1717116390,,1.00E+03,1.17E+02,1.74E-04,4.06E-08,-1.15E-02,8.89E-05,3,9.90E-01,1.80E+00,,,,,,,,,,,,,,,,,,0,4.00E+00,1.00E+00,4,2,5.37E-01,0,,0
1717116425,,1.00E+03,1.16E+02,1.74E-04,5.88E-08,-1.10E-02,2.48E-05,3,9.90E-01,1.80E+00,,,,,,,,,,,,,,,,,,0,4.00E+00,1.00E+00,4,2,5.76E-01,0,,0
1717116463,,1.00E+03,1.15E+02,1.75E-04,7.14E-08,-1.07E-02,1.67E-05,3,9.90E-01,1.80E+00,,,,,,,,,,,,,,,,,,0,4.00E+00,1.00E+00,4,2,5.38E-01,0,,0
1717116498,,1.00E+03,1.13E+02,1.75E-04,4.14E-08,-1.04E-02,8.70E-05,3,9.89E-01,1.80E+00,,,,,,,,,,,,,,,,,,0,4.00E+00,1.00E+00,4,2,5.02E-01,0,,0
1717116535,,1.00E+03,1.12E+02,1.75E-04,3.53E-08,-1.01E-02,1.15E-04,3,9.90E-01,1.80E+00,,,,,,,,,,,,,,,,,,0,4.00E+00,1.00E+00,4,2,5.08E-01,0,,0
1717116586,,1.00E+03,1.11E+02,1.75E-04,3.93E-08,-9.60E-03,4.59E-05,3,9.90E-01,1.80E+00,,,,,,,,,,,,,,,,,,0,4.00E+00,1.00E+00,4,2,5.08E-01,0,,0
1717116623,,1.00E+03,1.09E+02,1.76E-04,4.96E-08,-9.32E-03,1.61E-05,3,9.89E-01,1.80E+00,,,,,,,,,,,,,,,,,,0,4.00E+00,1.00E+00,4,2,5.08E-01,0,,0
1717116659,,1.00E+03,1.08E+02,1.76E-04,3.01E-08,-9.24E-03,5.22E-05,3,9.90E-01,1.80E+00,,,,,,,,,,,,,,,,,,0,4.00E+00,1.00E+00,4,2,5.10E-01,0,,0
1717116696,,1.00E+03,1.07E+02,1.76E-04,5.21E-08,-9.22E-03,1.37E-05,3,9.90E-01,1.80E+00,,,,,,,,,,,,,,,,,,0,4.00E+00,1.00E+00,4,2,5.13E-01,0,,0
1717116733,,1.00E+03,1.06E+02,1.76E-04,7.66E-08,-9.18E-03,7.04E-05,3,9.90E-01,1.80E+00,,,,,,,,,,,,,,,,,,0,4.00E+00,1.00E+00,4,2,4.69E-01,0,,0
1717116770,,1.00E+03,1.05E+02,1.77E-04,4.46E-08,-8.88E-03,1.19E-04,3,9.90E-01,1.80E+00,,,,,,,,,,,,,,,,,,0,4.00E+00,1.00E+00,4,2,5.20E-01,0,,0
1717116805,,1.00E+03,1.03E+02,1.77E-04,6.56E-08,-8.57E-03,2.29E-05,3,9.90E-01,1.80E+00,,,,,,,,,,,,,,,,,,0,4.00E+00,1.00E+00,4,2,5.56E-01,0,,0
1717116842,,1.00E+03,1.02E+02,1.77E-04,6.13E-08,-8.28E-03,8.33E-05,3,9.90E-01,1.80E+00,,,,,,,,,,,,,,,,,,0,4.00E+00,1.00E+00,4,2,5.66E-01,0,,0
1717116881,,1.00E+03,1.01E+02,1.78E-04,5.29E-08,-7.88E-03,6.69E-06,3,9.89E-01,1.80E+00,,,,,,,,,,,,,,,,,,0,4.00E+00,1.00E+00,4,2,5.67E-01,0,,0
1717116918,,1.00E+03,9.97E+01,1.78E-04,5.09E-08,-7.68E-03,1.40E-04,3,9.90E-01,1.80E+00,,,,,,,,,,,,,,,,,,0,4.00E+00,1.00E+00,4,2,5.71E-01,0,,0
1717116954,,1.00E+03,9.85E+01,1.79E-04,3.14E-08,-7.41E-03,3.38E-06,3,9.90E-01,1.80E+00,,,,,,,,,,,,,,,,,,0,4.00E+00,1.00E+00,4,2,4.89E-01,0,,0
1717116992,,1.00E+03,9.73E+01,1.79E-04,5.42E-08,-7.13E-03,2.43E-05,3,9.90E-01,1.80E+00,,,,,,,,,,,,,,,,,,0,4.00E+00,1.00E+00,4,2,4.94E-01,0,,0
1717117026,,1.00E+03,9.61E+01,1.79E-04,3.27E-09,-6.88E-03,1.11E-04,3,9.90E-01,1.80E+00,,,,,,,,,,,,,,,,,,0,4.00E+00,1.00E+00,4,2,5.41E-01,0,,0
1717117063,,1.00E+03,9.49E+01,1.79E-04,3.35E-08,-6.53E-03,2.24E-05,3,9.89E-01,1.80E+00,,,,,,,,,,,,,,,,,,0,4.00E+00,1.00E+00,4,2,5.53E-01,0,,0
1717117099,,1.00E+03,9.37E+01,1.79E-04,5.41E-08,-6.24E-03,8.23E-06,3,9.90E-01,1.80E+00,,,,,,,,,,,,,,,,,,0,4.00E+00,1.00E+00,4,2,5.09E-01,0,,0
1717117136,,1.00E+03,9.25E+01,1.78E-04,6.58E-08,-5.95E-03,8.97E-05,3,9.90E-01,1.80E+00,,,,,,,,,,,,,,,,,,0,4.00E+00,1.00E+00,4,2,5.57E-01,0,,0
1717117173,,1.00E+03,9.12E+01,1.78E-04,3.62E-08,-5.74E-03,1.45E-05,3,9.89E-01,1.80E+00,,,,,,,,,,,,,,,,,,0,4.00E+00,1.00E+00,4,2,5.14E-01,0,,0
1717117210,,1.00E+03,9.00E+01,1.78E-04,7.46E-08,-5.47E-03,4.05E-05,3,9.89E-01,1.80E+00,,,,,,,,,,,,,,,,,,0,4.00E+00,1.00E+00,4,2,5.19E-01,0,,0
1717117246,,1.00E+03,8.88E+01,1.78E-04,2.61E-08,-5.19E-03,7.60E-05,3,9.89E-01,1.80E+00,,,,,,,,,,,,,,,,,,0,4.00E+00,1.00E+00,4,2,5.51E-01,0,,0
1717117283,,1.00E+03,8.76E+01,1.77E-04,8.02E-08,-4.95E-03,1.26E-04,3,9.90E-01,1.80E+00,,,,,,,,,,,,,,,,,,0,4.00E+00,1.00E+00,4,2,5.60E-01,0,,0
1717117318,,1.00E+03,8.64E+01,1.77E-04,3.99E-08,-4.79E-03,1.58E-05,3,9.89E-01,1.80E+00,,,,,,,,,,,,,,,,,,0,4.00E+00,1.00E+00,4,2,4.99E-01,0,,0
1717117354,,1.00E+03,8.52E+01,1.77E-04,6.81E-08,-4.52E-03,4.18E-05,3,9.90E-01,1.80E+00,,,,,,,,,,,,,,,,,,0,4.00E+00,1.00E+00,4,2,5.49E-01,0,,0
1717117390,,1.00E+03,8.40E+01,1.76E-04,9.05E-08,-4.26E-03,2.44E-05,3,9.89E-01,1.80E+00,,,,,,,,,,,,,,,,,,0,4.00E+00,1.00E+00,4,2,5.88E-01,0,,0
1717117428,,1.00E+03,8.27E+01,1.75E-04,9.63E-08,-3.96E-03,1.35E-04,3,9.90E-01,1.80E+00,,,,,,,,,,,,,,,,,,0,4.00E+00,1.00E+00,4,2,5.50E-01,0,,0
1717117465,,1.00E+03,8.15E+01,1.75E-04,1.16E-07,-3.85E-03,2.67E-05,3,9.90E-01,1.80E+00,,,,,,,,,,,,,,,,,,0,4.00E+00,1.00E+00,4,2,5.31E-01,0,,0
1717117502,,1.00E+03,8.02E+01,1.74E-04,8.74E-08,-3.59E-03,5.32E-05,3,9.90E-01,1.80E+00,,,,,,,,,,,,,,,,,,0,4.00E+00,1.00E+00,4,2,5.25E-01,0,,0
1717117539,,1.00E+03,7.90E+01,1.74E-04,2.07E-08,-3.43E-03,1.88E-04,3,9.90E-01,1.80E+00,,,,,,,,,,,,,,,,,,0,4.00E+00,1.00E+00,4,2,6.05E-01,0,,0
1717117576,,1.00E+03,7.78E+01,1.74E-04,6.80E-08,-3.17E-03,4.03E-07,3,9.90E-01,1.80E+00,,,,,,,,,,,,,,,,,,0,4.00E+00,1.00E+00,4,2,5.24E-01,0,,0
1717117612,,1.00E+03,7.65E+01,1.73E-04,5.72E-08,-2.94E-03,3.81E-05,3,9.90E-01,1.80E+00,,,,,,,,,,,,,,,,,,0,4.00E+00,1.00E+00,4,2,5.64E-01,0,,0
1717117649,,1.00E+03,7.53E+01,1.73E-04,5.46E-08,-2.67E-03,5.08E-05,3,9.89E-01,1.80E+00,,,,,,,,,,,,,,,,,,0,4.00E+00,1.00E+00,4,2,5.47E-01,0,,0
1717117686,,1.00E+03,7.40E+01,1.73E-04,2.82E-08,-2.66E-03,4.76E-05,3,9.89E-01,1.80E+00,,,,,,,,,,,,,,,,,,0,4.00E+00,1.00E+00,4,2,5.47E-01,0,,0
1717117723,,1.00E+03,7.27E+01,1.72E-04,1.37E-09,-2.30E-03,4.58E-06,3,9.90E-01,1.80E+00,,,,,,,,,,,,,,,,,,0,4.00E+00,1.00E+00,4,2,5.50E-01,0,,0
1717117760,,1.00E+03,7.14E+01,1.72E-04,7.39E-08,-2.10E-03,2.19E-05,3,9.89E-01,1.80E+00,,,,,,,,,,,,,,,,,,0,4.00E+00,1.00E+00,4,2,5.09E-01,0,,0
1717117797,,1.00E+03,7.01E+01,1.72E-04,1.20E-08,-1.93E-03,2.05E-05,3,9.90E-01,1.80E+00,,,,,,,,,,,,,,,,,,0,4.00E+00,1.00E+00,4,2,5.56E-01,0,,0
1717117833,,1.00E+03,6.89E+01,1.71E-04,3.74E-08,-1.68E-03,2.86E-05,3,9.90E-01,1.80E+00,,,,,,,,,,,,,,,,,,0,4.00E+00,1.00E+00,4,2,5.59E-01,0,,0
1717117870,,1.00E+03,6.76E+01,1.71E-04,4.56E-09,-1.43E-03,2.36E-04,3,9.90E-01,1.80E+00,,,,,,,,,,,,,,,,,,0,4.00E+00,1.00E+00,4,2,5.20E-01,0,,0
1717117907,,1.00E+03,6.63E+01,1.71E-04,3.38E-08,-1.34E-03,6.73E-05,3,9.90E-01,1.80E+00,,,,,,,,,,,,,,,,,,0,4.00E+00,1.00E+00,4,2,5.23E-01,0,,0
1717117945,,1.00E+03,6.50E+01,1.71E-04,1.49E-08,-9.31E-04,1.42E-04,3,9.90E-01,1.80E+00,,,,,,,,,,,,,,,,,,0,4.00E+00,1.00E+00,4,2,5.57E-01,0,,0
1717117981,,1.00E+03,6.37E+01,1.70E-04,6.22E-08,-8.06E-04,9.13E-05,3,9.89E-01,1.80E+00,,,,,,,,,,,,,,,,,,0,4.00E+00,1.00E+00,4,2,5.27E-01,0,,0
1717118019,,1.00E+03,6.24E+01,1.70E-04,1.27E-08,-7.93E-04,2.91E-05,3,9.90E-01,1.80E+00,,,,,,,,,,,,,,,,,,0,4.00E+00,1.00E+00,4,2,5.47E-01,0,,0
1717118057,,1.00E+03,6.11E+01,1.70E-04,1.39E-08,-4.95E-04,1.30E-04,3,9.90E-01,1.80E+00,,,,,,,,,,,,,,,,,,0,4.00E+00,1.00E+00,4,2,6.01E-01,0,,0
1717118093,,1.00E+03,5.98E+01,1.70E-04,2.22E-08,-3.69E-04,1.49E-04,3,9.90E-01,1.80E+00,,,,,,,,,,,,,,,,,,0,4.00E+00,1.00E+00,4,2,5.20E-01,0,,0
1717118131,,1.00E+03,5.85E+01,1.70E-04,2.23E-08,-3.85E-06,2.66E-05,3,9.89E-01,1.80E+00,,,,,,,,,,,,,,,,,,0,4.00E+00,1.00E+00,4,2,6.07E-01,0,,0
1717118166,,1.00E+03,5.72E+01,1.69E-04,4.95E-08,2.11E-04,1.61E-04,3,9.89E-01,1.80E+00,,,,,,,,,,,,,,,,,,0,4.00E+00,1.00E+00,4,2,5.71E-01,0,,0
1717118205,,1.00E+03,5.59E+01,1.69E-04,4.75E-09,5.38E-04,6.27E-05,3,9.90E-01,1.80E+00,,,,,,,,,,,,,,,,,,0,4.00E+00,1.00E+00,4,2,6.31E-01,0,,0
1717118241,,1.00E+03,5.45E+01,1.69E-04,3.81E-10,7.37E-04,1.10E-04,3,9.89E-01,1.80E+00,,,,,,,,,,,,,,,,,,0,4.00E+00,1.00E+00,4,2,6.32E-01,0,,0
1717118279,,1.00E+03,5.32E+01,1.69E-04,3.81E-08,1.08E-03,1.67E-04,3,9.89E-01,1.80E+00,,,,,,,,,,,,,,,,,,0,4.00E+00,1.00E+00,4,2,5.84E-01,0,,0
1717118316,,1.00E+03,5.19E+01,1.69E-04,2.56E-08,1.30E-03,7.66E-05,3,9.89E-01,1.80E+00,,,,,,,,,,,,,,,,,,0,4.00E+00,1.00E+00,4,2,5.35E-01,0,,0
1717118354,,1.00E+03,5.06E+01,1.69E-04,4.55E-09,1.68E-03,1.47E-04,3,9.89E-01,1.80E+00,,,,,,,,,,,,,,,,,,0,4.00E+00,1.00E+00,4,2,5.49E-01,0,,0
1717118390,,1.00E+03,4.94E+01,1.69E-04,1.54E-08,1.86E-03,5.95E-05,3,9.90E-01,1.80E+00,,,,,,,,,,,,,,,,,,0,4.00E+00,1.00E+00,4,2,5.43E-01,0,,0
1717118428,,1.00E+03,4.82E+01,1.69E-04,7.30E-09,2.13E-03,3.63E-05,3,9.89E-01,1.80E+00,,,,,,,,,,,,,,,,,,0,4.00E+00,1.00E+00,4,2,5.45E-01,0,,0
1717118464,,1.00E+03,4.70E+01,1.69E-04,5.14E-09,2.46E-03,3.39E-05,3,9.90E-01,1.80E+00,,,,,,,,,,,,,,,,,,0,4.00E+00,1.00E+00,4,2,5.61E-01,0,,0
1717118500,,1.00E+03,4.58E+01,1.69E-04,1.80E-08,2.79E-03,1.85E-04,3,9.89E-01,1.80E+00,,,,,,,,,,,,,,,,,,0,4.00E+00,1.00E+00,4,2,5.35E-01,0,,0
1717118537,,1.00E+03,4.46E+01,1.69E-04,2.19E-08,2.92E-03,6.51E-05,3,9.89E-01,1.80E+00,,,,,,,,,,,,,,,,,,0,4.00E+00,1.00E+00,4,2,4.93E-01,0,,0
1717118574,,1.00E+03,4.34E+01,1.69E-04,9.72E-09,3.22E-03,1.67E-04,3,9.90E-01,1.80E+00,,,,,,,,,,,,,,,,,,0,4.00E+00,1.00E+00,4,2,5.45E-01,0,,0
1717118610,,1.00E+03,4.21E+01,1.69E-04,2.10E-08,3.57E-03,1.24E-06,3,9.90E-01,1.80E+00,,,,,,,,,,,,,,,,,,0,4.00E+00,1.00E+00,4,2,5.38E-01,0,,0
1717118649,,1.00E+03,4.08E+01,1.70E-04,7.99E-08,3.86E-03,1.42E-04,3,9.89E-01,1.80E+00,,,,,,,,,,,,,,,,,,0,4.00E+00,1.00E+00,4,2,5.13E-01,0,,0
1717118686,,1.00E+03,3.96E+01,1.70E-04,2.04E-08,4.23E-03,1.20E-05,3,9.89E-01,1.80E+00,,,,,,,,,,,,,,,,,,0,4.00E+00,1.00E+00,4,2,5.55E-01,0,,0
1717118723,,1.00E+03,3.83E+01,1.70E-04,6.93E-08,4.21E-03,1.33E-05,3,9.90E-01,1.80E+00,,,,,,,,,,,,,,,,,,0,4.00E+00,1.00E+00,4,2,5.51E-01,0,,0
1717118759,,1.00E+03,3.71E+01,1.70E-04,2.78E-09,4.48E-03,3.82E-05,3,9.90E-01,1.80E+00,,,,,,,,,,,,,,,,,,0,4.00E+00,1.00E+00,4,2,5.18E-01,0,,0
1717118796,,1.00E+03,3.59E+01,1.70E-04,4.88E-08,4.73E-03,1.11E-05,3,9.90E-01,1.80E+00,,,,,,,,,,,,,,,,,,0,4.00E+00,1.00E+00,4,2,5.61E-01,0,,0
1717118832,,1.00E+03,3.47E+01,1.70E-04,3.11E-08,4.88E-03,3.45E-05,3,9.90E-01,1.80E+00,,,,,,,,,,,,,,,,,,0,4.00E+00,1.00E+00,4,2,5.40E-01,0,,0
1717118870,,1.00E+03,3.34E+01,1.71E-04,8.39E-09,5.12E-03,8.85E-05,3,9.90E-01,1.80E+00,,,,,,,,,,,,,,,,,,0,4.00E+00,1.00E+00,4,2,5.28E-01,0,,0
1717118905,,1.00E+03,3.22E+01,1.71E-04,3.44E-08,5.33E-03,2.03E-04,3,9.90E-01,1.80E+00,,,,,,,,,,,,,,,,,,0,4.00E+00,1.00E+00,4,2,5.46E-01,0,,0
1717118944,,1.00E+03,3.09E+01,1.71E-04,2.79E-08,5.60E-03,1.78E-04,3,9.90E-01,1.80E+00,,,,,,,,,,,,,,,,,,0,4.00E+00,1.00E+00,4,2,5.09E-01,0,,0
1717118980,,1.00E+03,2.96E+01,1.71E-04,6.59E-10,5.55E-03,2.71E-05,3,9.90E-01,1.80E+00,,,,,,,,,,,,,,,,,,0,4.00E+00,1.00E+00,4,2,5.68E-01,0,,0
1717119018,,1.00E+03,2.83E+01,1.71E-04,3.62E-08,5.98E-03,8.14E-05,3,9.90E-01,1.80E+00,,,,,,,,,,,,,,,,,,0,4.00E+00,1.00E+00,4,2,5.77E-01,0,,0
1717119055,,1.00E+03,2.70E+01,1.71E-04,2.59E-08,6.13E-03,1.70E-05,3,9.90E-01,1.80E+00,,,,,,,,,,,,,,,,,,0,4.00E+00,1.00E+00,4,2,5.08E-01,0,,0
1717119092,,1.00E+03,2.57E+01,1.72E-04,4.42E-08,6.24E-03,1.02E-04,3,9.89E-01,1.80E+00,,,,,,,,,,,,,,,,,,0,4.00E+00,1.00E+00,4,2,5.45E-01,0,,0
1717119129,,1.00E+03,2.42E+01,1.72E-04,2.34E-08,6.35E-03,1.31E-04,3,9.90E-01,1.80E+00,,,,,,,,,,,,,,,,,,0,4.00E+00,1.00E+00,4,2,1.12E+00,0,,0
1717119166,,1.00E+03,2.33E+01,1.72E-04,5.98E-08,6.56E-03,1.29E-04,3,9.90E-01,1.80E+00,,,,,,,,,,,,,,,,,,0,4.00E+00,1.00E+00,4,2,2.72E-01,0,,0
1717119203,,1.00E+03,2.21E+01,1.72E-04,5.67E-08,6.80E-03,8.65E-05,3,9.90E-01,1.80E+00,,,,,,,,,,,,,,,,,,0,4.00E+00,1.00E+00,4,2,5.04E-01,0,,0
1717119241,,1.00E+03,2.10E+01,1.72E-04,3.59E-09,6.94E-03,3.40E-05,3,9.90E-01,1.80E+00,,,,,,,,,,,,,,,,,,0,4.00E+00,1.00E+00,4,2,5.41E-01,0,,0
1717119277,,1.00E+03,1.98E+01,1.72E-04,2.64E-08,7.15E-03,6.14E-05,3,9.90E-01,1.80E+00,,,,,,,,,,,,,,,,,,0,4.00E+00,1.00E+00,4,2,5.10E-01,0,,0
1717119314,,1.00E+03,1.86E+01,1.72E-04,5.60E-08,7.46E-03,1.18E-04,3,9.90E-01,1.80E+00,,,,,,,,,,,,,,,,,,0,4.00E+00,1.00E+00,4,2,5.60E-01,0,,0
1717119350,,1.00E+03,1.74E+01,1.73E-04,2.51E-08,7.73E-03,5.30E-05,3,9.90E-01,1.80E+00,,,,,,,,,,,,,,,,,,0,4.00E+00,1.00E+00,4,2,4.44E-01,0,,0
1717119388,,1.00E+03,1.62E+01,1.73E-04,2.28E-08,8.11E-03,1.21E-04,3,9.90E-01,1.80E+00,,,,,,,,,,,,,,,,,,0,4.00E+00,1.00E+00,4,2,5.56E-01,0,,0
1717119426,,1.00E+03,1.49E+01,1.73E-04,7.40E-09,8.73E-03,1.11E-04,3,9.90E-01,1.80E+00,,,,,,,,,,,,,,,,,,0,4.00E+00,1.00E+00,4,2,5.12E-01,0,,0
1717119462,,1.00E+03,1.37E+01,1.73E-04,2.03E-09,9.15E-03,1.30E-04,3,9.90E-01,1.80E+00,,,,,,,,,,,,,,,,,,0,4.00E+00,1.00E+00,4,2,6.04E-01,0,,0
1717119499,,1.00E+03,1.25E+01,1.73E-04,5.03E-08,9.72E-03,9.15E-05,3,9.90E-01,1.80E+00,,,,,,,,,,,,,,,,,,0,4.00E+00,1.00E+00,4,2,4.87E-01,0,,0
1717119538,,1.00E+03,1.13E+01,1.73E-04,6.52E-08,1.05E-02,1.44E-04,3,9.90E-01,1.80E+00,,,,,,,,,,,,,,,,,,0,4.00E+00,1.00E+00,4,2,4.68E-01,0,,0
1717119574,,1.00E+03,1.02E+01,1.72E-04,3.26E-08,1.16E-02,2.98E-04,3,9.90E-01,1.80E+00,,,,,,,,,,,,,,,,,,0,4.00E+00,1.00E+00,4,2,5.00E-01,0,,0
1717120023,,1.00E+03,1.00E+01,1.72E-04,1.41E-08,1.16E-02,9.82E-05,3,9.90E-01,1.80E+00,,,,,,,,,,,,,,,,,,0,4.00E+00,1.00E+00,4,2,4.00E-03,0,,0
1717120058,,1.00E+03,1.00E+01,1.72E-04,3.81E-08,1.15E-02,7.51E-05,3,9.90E-01,1.80E+00,,,,,,,,,,,,,,,,,,0,4.00E+00,1.00E+00,4,2,2.73E-03,0,,0
1717120093,,1.00E+03,1.00E+01,1.72E-04,6.01E-09,1.15E-02,5.47E-05,3,9.90E-01,1.80E+00,,,,,,,,,,,,,,,,,,0,4.00E+00,1.00E+00,4,2,4.21E-04,0,,0
1717120127,,1.00E+03,1.00E+01,1.72E-04,9.86E-09,1.16E-02,2.06E-06,3,9.90E-01,1.80E+00,,,,,,,,,,,,,,,,,,0,4.00E+00,1.00E+00,4,2,6.29E-04,0,,0
1717120162,,1.00E+03,1.00E+01,1.72E-04,4.24E-09,1.16E-02,7.78E-05,3,9.90E-01,1.80E+00,,,,,,,,,,,,,,,,,,0,4.00E+00,1.00E+00,4,2,2.25E-03,0,,0
1717120197,,1.00E+03,1.00E+01,1.72E-04,9.48E-09,1.17E-02,1.45E-04,3,9.90E-01,1.80E+00,,,,,,,,,,,,,,,,,,0,4.00E+00,1.00E+00,4,2,4.21E-04,0,,0
1717120233,,1.00E+03,1.00E+01,1.72E-04,3.61E-08,1.16E-02,2.50E-05,3,9.90E-01,1.80E+00,,,,,,,,,,,,,,,,,,0,4.00E+00,1.00E+00,4,2,2.43E-03,0,,0
1717120268,,1.00E+03,1.00E+01,1.72E-04,3.18E-08,1.16E-02,2.95E-05,3,9.90E-01,1.80E+00,,,,,,,,,,,,,,,,,,0,4.00E+00,1.00E+00,4,2,1.80E-03,0,,0
1717120303,,1.00E+03,1.00E+01,1.72E-04,1.26E-08,1.18E-02,2.50E-04,3,9.90E-01,1.80E+00,,,,,,,,,,,,,,,,,,0,4.00E+00,1.00E+00,4,2,6.30E-04,0,,0
1717120337,,1.00E+03,1.00E+01,1.72E-04,4.80E-08,1.17E-02,1.56E-04,3,9.90E-01,1.80E+00,,,,,,,,,,,,,,,,,,0,4.00E+00,1.00E+00,4,2,4.21E-04,0,,0
1717120372,,1.00E+03,1.00E+01,1.72E-04,7.38E-09,1.16E-02,7.35E-05,3,9.90E-01,1.80E+00,,,,,,,,,,,,,,,,,,0,4.00E+00,1.00E+00,4,2,2.17E-03,0,,0
1717120407,,1.00E+03,1.00E+01,1.72E-04,1.88E-08,1.16E-02,3.66E-05,3,9.90E-01,1.80E+00,,,,,,,,,,,,,,,,,,0,4.00E+00,1.00E+00,4,2,1.73E-03,0,,0
1717120442,,1.00E+03,1.00E+01,1.72E-04,3.72E-08,1.16E-02,1.62E-04,3,9.90E-01,1.80E+00,,,,,,,,,,,,,,,,,,0,4.00E+00,1.00E+00,4,2,1.04E-03,0,,0
1717120478,,1.00E+03,1.00E+01,1.72E-04,1.07E-08,1.15E-02,3.81E-05,3,9.90E-01,1.80E+00,,,,,,,,,,,,,,,,,,0,4.00E+00,1.00E+00,4,2,2.66E-03,0,,0
1717120512,,1.00E+03,1.00E+01,1.72E-04,2.59E-08,1.16E-02,1.11E-04,3,9.90E-01,1.80E+00,,,,,,,,,,,,,,,,,,0,4.00E+00,1.00E+00,4,2,2.10E-04,0,,0
1717120561,,1.00E+03,1.00E+01,1.72E-04,4.60E-08,1.16E-02,7.91E-05,3,9.90E-01,1.80E+00,,,,,,,,,,,,,,,,,,0,4.00E+00,1.00E+00,4,2,8.39E-04,0,,0
1717120595,,1.00E+03,1.00E+01,1.72E-04,3.06E-08,1.16E-02,5.57E-05,3,9.90E-01,1.80E+00,,,,,,,,,,,,,,,,,,0,4.00E+00,1.00E+00,4,2,1.76E-03,0,,0
1717120632,,1.00E+03,1.00E+01,1.72E-04,2.95E-08,1.16E-02,9.41E-05,3,9.90E-01,1.80E+00,,,,,,,,,,,,,,,,,,0,4.00E+00,1.00E+00,4,2,2.42E-03,0,,0
1717120666,,1.00E+03,1.00E+01,1.73E-04,1.07E-06,1.73E-02,8.23E-03,3,9.26E-01,1.80E+00,,,,,,,,,,,,,,,,,,0,4.00E+00,1.00E+00,4,2,6.29E-04,0,,0
1717120712,,1.00E+03,1.00E+01,1.72E-04,2.25E-09,1.14E-02,4.01E-05,3,9.90E-01,1.80E+00,,,,,,,,,,,,,,,,,,0,4.00E+00,1.00E+00,4,2,1.48E-03,0,,0
1717120759,,1.00E+03,1.00E+01,1.72E-04,3.24E-08,1.16E-02,2.09E-05,3,9.90E-01,1.80E+00,,,,,,,,,,,,,,,,,,0,4.00E+00,1.00E+00,4,2,8.31E-04,0,,0
1717120838,,1.00E+03,1.00E+01,1.76E-04,4.43E-06,2.04E-02,1.24E-02,3,9.60E-01,1.80E+00,,,,,,,,,,,,,,,,,,0,4.00E+00,1.00E+00,4,2,2.17E-03,0,,0
1717120905,,1.00E+03,1.00E+01,1.72E-04,8.34E-10,1.16E-02,1.98E-05,3,9.90E-01,1.80E+00,,,,,,,,,,,,,,,,,,0,4.00E+00,1.00E+00,4,2,2.17E-03,0,,0
1717120957,,1.00E+03,1.00E+01,1.72E-04,2.49E-08,1.15E-02,4.52E-05,3,9.90E-01,1.80E+00,,,,,,,,,,,,,,,,,,0,4.00E+00,1.00E+00,4,2,2.63E-03,0,,0
1717120991,,1.00E+03,1.00E+01,1.72E-04,6.20E-09,1.14E-02,4.10E-05,3,9.90E-01,1.80E+00,,,,,,,,,,,,,,,,,,0,4.00E+00,1.00E+00,4,2,8.30E-04,0,,0
1717121025,,1.00E+03,1.00E+01,1.72E-04,3.37E-08,1.16E-02,9.65E-05,3,9.90E-01,1.80E+00,,,,,,,,,,,,,,,,,,0,4.00E+00,1.00E+00,4,2,1.93E-03,0,,0
1717121060,,1.00E+03,1.00E+01,1.72E-04,2.93E-08,1.17E-02,1.77E-04,3,9.89E-01,1.80E+00,,,,,,,,,,,,,,,,,,0,4.00E+00,1.00E+00,4,2,1.04E-03,0,,0
1717121094,,1.00E+03,1.00E+01,1.72E-04,1.36E-08,1.15E-02,1.18E-04,3,9.90E-01,1.80E+00,,,,,,,,,,,,,,,,,,0,4.00E+00,1.00E+00,4,2,2.21E-03,0,,0
1717121127,,1.00E+03,1.00E+01,1.71E-04,1.95E-06,2.83E-02,2.35E-02,3,9.36E-01,1.80E+00,,,,,,,,,,,,,,,,,,0,4.00E+00,1.00E+00,4,2,4.10E-04,0,,0
1717121161,,1.00E+03,1.00E+01,1.72E-04,8.89E-09,1.16E-02,4.69E-06,3,9.90E-01,1.80E+00,,,,,,,,,,,,,,,,,,0,4.00E+00,1.00E+00,4,2,8.31E-04,0,,0
1717121196,,1.00E+03,1.00E+01,1.72E-04,1.60E-08,1.16E-02,2.44E-04,3,9.89E-01,1.80E+00,,,,,,,,,,,,,,,,,,0,4.00E+00,1.00E+00,4,2,1.04E-03,0,,0
1717121231,,1.00E+03,1.00E+01,1.72E-04,2.75E-09,1.16E-02,2.11E-05,3,9.90E-01,1.80E+00,,,,,,,,,,,,,,,,,,0,4.00E+00,1.00E+00,4,2,4.20E-04,0,,0
1717121265,,1.00E+03,1.00E+01,1.72E-04,2.26E-08,1.16E-02,1.60E-05,3,9.90E-01,1.80E+00,,,,,,,,,,,,,,,,,,0,4.00E+00,1.00E+00,4,2,1.25E-03,0,,0
1717121300,,1.00E+03,1.00E+01,1.72E-04,1.42E-08,1.16E-02,8.64E-06,3,9.89E-01,1.80E+00,,,,,,,,,,,,,,,,,,0,4.00E+00,1.00E+00,4,2,4.20E-04,0,,0
1717121348,,1.00E+03,1.00E+01,1.74E-04,2.71E-06,1.28E-02,1.73E-03,3,9.68E-01,1.80E+00,,,,,,,,,,,,,,,,,,0,4.00E+00,1.00E+00,4,2,1.25E-03,0,,0
1717121411,,1.00E+03,1.00E+01,1.72E-04,2.57E-08,1.16E-02,1.68E-05,3,9.90E-01,1.80E+00,,,,,,,,,,,,,,,,,,0,4.00E+00,1.00E+00,4,2,6.20E-04,0,,0
1717121445,,1.00E+03,1.00E+01,1.72E-04,2.49E-09,1.15E-02,1.34E-04,3,9.90E-01,1.80E+00,,,,,,,,,,,,,,,,,,0,4.00E+00,1.00E+00,4,2,4.20E-04,0,,0